<robot name="onshape">
<link name="body_1">
<collision>
<origin xyz="-0.240134 0.0221827 -0.27623" rpy="-5.12956e-06 9.95073e-08 -1.534" />
<geometry>
<mesh filename="package://solenoid_body.stl"/>
</geometry>
<material name="solenoid_body_material">
<color rgba="0.647059 0.647059 0.647059 1.0"/>
</material>
</collision>
<collision>
<origin xyz="-0.0360299 0.0075899 -0.0981546" rpy="-1.5708 -9.70802e-08 -3.11644" />
<geometry>
<mesh filename="package://motor.stl"/>
</geometry>
<material name="motor_material">
<color rgba="0.768627 0.886275 0.952941 1.0"/>
</material>
</collision>
<collision>
<origin xyz="1.26396e-10 -1.21807e-10 -0.113737" rpy="3.14159 3.81895e-08 -2.05776" />
<geometry>
<mesh filename="package://body_1.stl"/>
</geometry>
<material name="body_1_material">
<color rgba="0.615686 0.811765 0.929412 1.0"/>
</material>
</collision>
<collision>
<origin xyz="-0.0761155 0.157779 -0.0759532" rpy="3.14159 9.72302e-08 -1.55745" />
<geometry>
<mesh filename="package://m3_l30mm.stl"/>
</geometry>
<material name="m3_l30mm_material">
<color rgba="0 0 0 1.0"/>
</material>
</collision>
<collision>
<origin xyz="0.36267 0.0528538 -0.0761966" rpy="3.14159 9.83834e-08 -1.54564" />
<geometry>
<mesh filename="package://part_14.stl"/>
</geometry>
<material name="part_14_material">
<color rgba="0.615686 0.811765 0.929412 1.0"/>
</material>
</collision>
<collision>
<origin xyz="0.217534 -0.0901843 -0.140211" rpy="-3.14159 -3.81895e-08 1.08383" />
<geometry>
<mesh filename="package://prt0002_1.stl"/>
</geometry>
<material name="prt0002_1_material">
<color rgba="0.615686 0.811765 0.929412 1.0"/>
</material>
</collision>
<collision>
<origin xyz="0.131774 -0.0402069 -0.146249" rpy="-9.59279e-08 9.95073e-08 -1.534" />
<geometry>
<mesh filename="package://solenoid_case_1.stl"/>
</geometry>
<material name="solenoid_case_1_material">
<color rgba="0.917647 0.917647 0.917647 1.0"/>
</material>
</collision>
<collision>
<origin xyz="0.110422 -0.0160755 -0.113737" rpy="3.14159 -1.32836e-07 2.65463" />
<geometry>
<mesh filename="package://m3_l35mm.stl"/>
</geometry>
<material name="m3_l35mm_material">
<color rgba="0 0 0 1.0"/>
</material>
</collision>
<collision>
<origin xyz="0.221494 -0.0900437 -0.140211" rpy="-3.14159 -3.81895e-08 1.08383" />
<geometry>
<mesh filename="package://prt0007_3.stl"/>
</geometry>
<material name="prt0007_3_material">
<color rgba="0.498039 0.498039 0.498039 1.0"/>
</material>
</collision>
<collision>
<origin xyz="0.0357787 0.22353 -0.0761966" rpy="3.14159 9.72302e-08 -1.55745" />
<geometry>
<mesh filename="package://m3_l30mm.stl"/>
</geometry>
<material name="m3_l30mm_material">
<color rgba="0 0 0 1.0"/>
</material>
</collision>
<collision>
<origin xyz="-0.0391491 0.222955 -0.0761966" rpy="3.14159 9.72302e-08 -1.55745" />
<geometry>
<mesh filename="package://m3_l30mm.stl"/>
</geometry>
<material name="m3_l30mm_material">
<color rgba="0 0 0 1.0"/>
</material>
</collision>
<collision>
<origin xyz="0.112236 0.250443 -0.0436566" rpy="3.14159 9.72302e-08 -1.55745" />
<geometry>
<mesh filename="package://body_3.stl"/>
</geometry>
<material name="body_3_material">
<color rgba="0.917647 0.917647 0.917647 1.0"/>
</material>
</collision>
<collision>
<origin xyz="0.0997414 -0.231721 -0.116277" rpy="-3.14159 3.3345e-08 0.56023" />
<geometry>
<mesh filename="package://suspention.stl"/>
</geometry>
<material name="suspention_material">
<color rgba="0.647059 0.647059 0.647059 1.0"/>
</material>
</collision>
<collision>
<origin xyz="0.225118 -0.0768069 -0.113737" rpy="3.14159 -1.32836e-07 2.65463" />
<geometry>
<mesh filename="package://m3_l35mm.stl"/>
</geometry>
<material name="m3_l35mm_material">
<color rgba="0 0 0 1.0"/>
</material>
</collision>
<collision>
<origin xyz="0.0737401 0.158928 -0.0761966" rpy="3.14159 9.72302e-08 -1.55745" />
<geometry>
<mesh filename="package://m3_l30mm.stl"/>
</geometry>
<material name="m3_l30mm_material">
<color rgba="0 0 0 1.0"/>
</material>
</collision>
<collision>
<origin xyz="0.217701 -0.0900827 -0.140211" rpy="-3.14159 -3.81895e-08 1.08383" />
<geometry>
<mesh filename="package://prt0001_2.stl"/>
</geometry>
<material name="prt0001_2_material">
<color rgba="0.917647 0.917647 0.917647 1.0"/>
</material>
</collision>
<collision>
<origin xyz="-0.0716856 0.0891647 -0.0761966" rpy="3.14159 1.15683e-07 -1.34599" />
<geometry>
<mesh filename="package://m3_l30mm.stl"/>
</geometry>
<material name="m3_l30mm_material">
<color rgba="0 0 0 1.0"/>
</material>
</collision>
<collision>
<origin xyz="0.254789 0.151879 -0.116277" rpy="3.14159 -1.32749e-07 2.65689" />
<geometry>
<mesh filename="package://suspention.stl"/>
</geometry>
<material name="suspention_material">
<color rgba="0.647059 0.647059 0.647059 1.0"/>
</material>
</collision>
<collision>
<origin xyz="0.00145422 -0.293436 -0.116277" rpy="-3.14159 3.3345e-08 0.56023" />
<geometry>
<mesh filename="package://suspention.stl"/>
</geometry>
<material name="suspention_material">
<color rgba="0.647059 0.647059 0.647059 1.0"/>
</material>
</collision>
<collision>
<origin xyz="-0.185463 -0.0558348 -0.116277" rpy="3.14159 9.95073e-08 -1.534" />
<geometry>
<mesh filename="package://solenoid_case_2.stl"/>
</geometry>
<material name="solenoid_case_2_material">
<color rgba="0.768627 0.886275 0.952941 1.0"/>
</material>
</collision>
<collision>
<origin xyz="0.380212 0.0572975 -0.0761966" rpy="3.14159 9.83834e-08 -1.54564" />
<geometry>
<mesh filename="package://part_15.stl"/>
</geometry>
<material name="part_15_material">
<color rgba="0.647059 0.647059 0.647059 1.0"/>
</material>
</collision>
<collision>
<origin xyz="0.0753588 -0.0822953 -0.113737" rpy="3.14159 -1.32836e-07 2.65463" />
<geometry>
<mesh filename="package://m3_l35mm.stl"/>
</geometry>
<material name="m3_l35mm_material">
<color rgba="0 0 0 1.0"/>
</material>
</collision>
<collision>
<origin xyz="0.218645 0.0121741 -0.0761966" rpy="3.14159 9.83834e-08 -1.54564" />
<geometry>
<mesh filename="package://body_2.stl"/>
</geometry>
<material name="body_2_material">
<color rgba="0.647059 0.647059 0.647059 1.0"/>
</material>
</collision>
<collision>
<origin xyz="-0.253371 -0.14793 -0.116277" rpy="-3.14159 1.32836e-07 -0.486967" />
<geometry>
<mesh filename="package://suspention.stl"/>
</geometry>
<material name="suspention_material">
<color rgba="0.647059 0.647059 0.647059 1.0"/>
</material>
</collision>
<collision>
<origin xyz="-0.0354061 -0.0172023 -0.0981546" rpy="-1.5708 -9.70802e-08 -3.11644" />
<geometry>
<mesh filename="package://gearbox.stl"/>
</geometry>
<material name="gearbox_material">
<color rgba="0.231373 0.380392 0.705882 1.0"/>
</material>
</collision>
<collision>
<origin xyz="0.0367738 0.093751 -0.0761966" rpy="3.14159 9.72302e-08 -1.55745" />
<geometry>
<mesh filename="package://m3_l30mm.stl"/>
</geometry>
<material name="m3_l30mm_material">
<color rgba="0 0 0 1.0"/>
</material>
</collision>
<collision>
<origin xyz="0.221603 -0.0896751 -0.140211" rpy="-3.14159 -3.84901e-08 1.08609" />
<geometry>
<mesh filename="package://prt0007.stl"/>
</geometry>
<material name="prt0007_material">
<color rgba="0.972549 0.529412 0.00392157 1.0"/>
</material>
</collision>
<collision>
<origin xyz="0.185302 -0.0133313 -0.113737" rpy="3.14159 -1.32836e-07 2.65463" />
<geometry>
<mesh filename="package://m3_l35mm.stl"/>
</geometry>
<material name="m3_l35mm_material">
<color rgba="0 0 0 1.0"/>
</material>
</collision>
<visual>
<origin xyz="0 0 0" rpy="0 -0 0" />
<geometry>
<mesh filename="package://body_1.stl"/>
</geometry>
<material name="body_1_material">
<color rgba="0.694351 0.700607 0.692106 1.0"/>
</material>
</visual>
<inertial>
<origin xyz="-0.000875129 0.00232211 -0.116828" rpy="0 0 0"/>
<mass value="0.793815" />
<inertia ixx="0.00152132" ixy="-4.69786e-05"  ixz="2.01706e-05" iyy="0.00182687" iyz="5.61521e-05" izz="0.00188173" />
</inertial>
</link>

<link name="roller_1">
<collision>
<origin xyz="-0.010626 0.128506 -0.0653485" rpy="-1.96053e-16 -1.52303e-16 3.34047e-16" />
<geometry>
<mesh filename="package://roller_core.stl"/>
</geometry>
<material name="roller_core_material">
<color rgba="0.972549 0.529412 0.00392157 1.0"/>
</material>
</collision>
<collision>
<origin xyz="-0.0106197 0.0432059 -0.0646269" rpy="-4.86015e-17 -4.08122e-17 7.91709e-16" />
<geometry>
<mesh filename="package://roller.stl"/>
</geometry>
<material name="roller_material">
<color rgba="0.768627 0.886275 0.952941 1.0"/>
</material>
</collision>
<collision>
<origin xyz="6.93889e-18 1.38778e-17 0" rpy="-2.92316e-20 3.45786e-21 1.08348e-18" />
<geometry>
<mesh filename="package://output_shaft.stl"/>
</geometry>
<material name="output_shaft_material">
<color rgba="0.917647 0.917647 0.917647 1.0"/>
</material>
</collision>
<visual>
<origin xyz="0 0 0" rpy="0 -0 0" />
<geometry>
<mesh filename="package://roller_1.stl"/>
</geometry>
<material name="roller_1_material">
<color rgba="0.805152 0.828341 0.796446 1.0"/>
</material>
</visual>
<inertial>
<origin xyz="-0.0348369 -8.01773e-05 -1.82817e-17" rpy="0 0 0"/>
<mass value="0.0499297" />
<inertia ixx="5.72787e-06" ixy="-2.57499e-09"  ixz="-3.70016e-21" iyy="1.43276e-05" iyz="2.34122e-20" izz="1.43282e-05" />
</inertial>
</link>

<joint name="roller" type="revolute">
<origin xyz="-0.0347647 -0.0426942 -0.0981546" rpy="-3.14056 -9.70802e-08 -3.11644" />
<parent link="body_1" />
<child link="roller_1" />
<axis xyz="-1 0 0"/>
<limit effort="1" velocity="20" />
<joint_properties friction="0.0"/>
</joint>

<link name="horn4_1">
<collision>
<origin xyz="0 -6.93889e-18 0.0012" rpy="-3.53365e-17 1.08315e-18 -6.12493e-18" />
<geometry>
<mesh filename="package://mx-12w_horn.stl"/>
</geometry>
<material name="mx-12w_horn_material">
<color rgba="0.980392 0.713725 0.00392157 1.0"/>
</material>
</collision>
<collision>
<origin xyz="0.171498 0.217932 0.00431" rpy="-3.14159 -4.59131e-14 -3.14159" />
<geometry>
<mesh filename="package://horn.stl"/>
</geometry>
<material name="horn_material">
<color rgba="0.231373 0.380392 0.705882 1.0"/>
</material>
</collision>
<collision>
<origin xyz="0.0678046 0.04517 0.0423198" rpy="2.07191e-14 -2.19889e-16 1.5708" />
<geometry>
<mesh filename="package://main_frame.stl"/>
</geometry>
<material name="main_frame_material">
<color rgba="0.980392 0.713725 0.00392157 1.0"/>
</material>
</collision>
<visual>
<origin xyz="0 0 0" rpy="0 -0 0" />
<geometry>
<mesh filename="package://horn4_1.stl"/>
</geometry>
<material name="horn4_1_material">
<color rgba="0.937052 0.694438 0.0445389 1.0"/>
</material>
</visual>
<inertial>
<origin xyz="-9.44942e-07 -1.4867e-07 0.012158" rpy="0 0 0"/>
<mass value="0.0125567" />
<inertia ixx="1.27588e-06" ixy="1.42523e-11"  ixz="-1.50868e-10" iyy="1.27557e-06" iyz="-4.04238e-12" izz="1.48771e-06" />
</inertial>
</link>

<link name="wheel2_sub2_1">
<collision>
<origin xyz="0.0534199 -0.0535157 0.032114" rpy="2.44425e-17 8.2835e-18 -1.92624e-17" />
<geometry>
<mesh filename="package://sub_wheel.stl"/>
</geometry>
<material name="sub_wheel_material">
<color rgba="0.768627 0.886275 0.952941 1.0"/>
</material>
</collision>
<visual>
<origin xyz="0 0 0" rpy="0 -0 0" />
<geometry>
<mesh filename="package://wheel2_sub2_1.stl"/>
</geometry>
<material name="wheel2_sub2_1_material">
<color rgba="0.768627 0.886275 0.952941 1.0"/>
</material>
</visual>
<inertial>
<origin xyz="3.67355e-05 -2.09868e-05 5.31199e-07" rpy="0 0 0"/>
<mass value="9.9564e-05" />
<inertia ixx="9.26988e-10" ixy="4.8503e-10"  ixz="2.09591e-13" iyy="1.48655e-09" iyz="-2.62533e-14" izz="1.76782e-09" />
</inertial>
</link>

<joint name="wheel2_sub1" type="revolute">
<origin xyz="-0.00825 0.0142894 0.0189056" rpy="3.13998 -0.000933133 -3.14159" />
<parent link="horn4_1" />
<child link="wheel2_sub2_1" />
<axis xyz="-0.866025 0.5 0"/>
<limit effort="1" velocity="20" />
<joint_properties friction="0.0"/>
</joint>

<link name="wheel2_sub7_1">
<collision>
<origin xyz="0.0534199 -0.0535157 0.032114" rpy="-2.27362e-17 -3.08617e-18 -1.99373e-18" />
<geometry>
<mesh filename="package://sub_wheel.stl"/>
</geometry>
<material name="sub_wheel_material">
<color rgba="0.768627 0.886275 0.952941 1.0"/>
</material>
</collision>
<visual>
<origin xyz="0 0 0" rpy="0 -0 0" />
<geometry>
<mesh filename="package://wheel2_sub7_1.stl"/>
</geometry>
<material name="wheel2_sub7_1_material">
<color rgba="0.768627 0.886275 0.952941 1.0"/>
</material>
</visual>
<inertial>
<origin xyz="3.67355e-05 -2.09868e-05 5.31199e-07" rpy="0 0 0"/>
<mass value="9.9564e-05" />
<inertia ixx="9.26988e-10" ixy="4.8503e-10"  ixz="2.09591e-13" iyy="1.48655e-09" iyz="-2.62533e-14" izz="1.76782e-09" />
</inertial>
</link>

<joint name="wheel2_sub2" type="revolute">
<origin xyz="0.00825 0.0142894 0.0189056" rpy="0.00183987 -0.00106225 -9.77202e-07" />
<parent link="horn4_1" />
<child link="wheel2_sub7_1" />
<axis xyz="-0.866025 0.5 0"/>
<limit effort="1" velocity="20" />
<joint_properties friction="0.0"/>
</joint>

<link name="wheel2_sub3_1">
<collision>
<origin xyz="0.0534199 -0.0535157 0.032114" rpy="1.46504e-17 -1.21021e-17 8.16211e-18" />
<geometry>
<mesh filename="package://sub_wheel.stl"/>
</geometry>
<material name="sub_wheel_material">
<color rgba="0.768627 0.886275 0.952941 1.0"/>
</material>
</collision>
<visual>
<origin xyz="0 0 0" rpy="0 -0 0" />
<geometry>
<mesh filename="package://wheel2_sub3_1.stl"/>
</geometry>
<material name="wheel2_sub3_1_material">
<color rgba="0.768627 0.886275 0.952941 1.0"/>
</material>
</visual>
<inertial>
<origin xyz="3.67355e-05 -2.09868e-05 5.31199e-07" rpy="0 0 0"/>
<mass value="9.9564e-05" />
<inertia ixx="9.26988e-10" ixy="4.8503e-10"  ixz="2.09591e-13" iyy="1.48655e-09" iyz="-2.62533e-14" izz="1.76782e-09" />
</inertial>
</link>

<joint name="wheel2_sub3" type="revolute">
<origin xyz="0.0165 1.11022e-16 0.0189056" rpy="1.57117 -0.523599 -1.57099" />
<parent link="horn4_1" />
<child link="wheel2_sub3_1" />
<axis xyz="-0.866025 0.5 0"/>
<limit effort="1" velocity="20" />
<joint_properties friction="0.0"/>
</joint>

<link name="wheel2_sub9_1">
<collision>
<origin xyz="0.0534199 -0.0535157 0.032114" rpy="1.01691e-17 -1.17466e-17 1.9771e-18" />
<geometry>
<mesh filename="package://sub_wheel.stl"/>
</geometry>
<material name="sub_wheel_material">
<color rgba="0.768627 0.886275 0.952941 1.0"/>
</material>
</collision>
<visual>
<origin xyz="0 0 0" rpy="0 -0 0" />
<geometry>
<mesh filename="package://wheel2_sub9_1.stl"/>
</geometry>
<material name="wheel2_sub9_1_material">
<color rgba="0.768627 0.886275 0.952941 1.0"/>
</material>
</visual>
<inertial>
<origin xyz="3.67355e-05 -2.09868e-05 5.31199e-07" rpy="0 0 0"/>
<mass value="9.9564e-05" />
<inertia ixx="9.26988e-10" ixy="4.8503e-10"  ixz="2.09591e-13" iyy="1.48655e-09" iyz="-2.62533e-14" izz="1.76782e-09" />
</inertial>
</link>

<joint name="wheel2_sub4" type="revolute">
<origin xyz="0.00825 -0.0142894 0.0189056" rpy="3.13998 -0.000933133 -3.14159" />
<parent link="horn4_1" />
<child link="wheel2_sub9_1" />
<axis xyz="-0.866025 0.5 0"/>
<limit effort="1" velocity="20" />
<joint_properties friction="0.0"/>
</joint>

<link name="wheel2_sub5_1">
<collision>
<origin xyz="0.0534199 -0.0535157 0.032114" rpy="-3.7442e-17 -4.23651e-18 2.64039e-18" />
<geometry>
<mesh filename="package://sub_wheel.stl"/>
</geometry>
<material name="sub_wheel_material">
<color rgba="0.768627 0.886275 0.952941 1.0"/>
</material>
</collision>
<visual>
<origin xyz="0 0 0" rpy="0 -0 0" />
<geometry>
<mesh filename="package://wheel2_sub5_1.stl"/>
</geometry>
<material name="wheel2_sub5_1_material">
<color rgba="0.768627 0.886275 0.952941 1.0"/>
</material>
</visual>
<inertial>
<origin xyz="3.67355e-05 -2.09868e-05 5.31199e-07" rpy="0 0 0"/>
<mass value="9.9564e-05" />
<inertia ixx="9.26988e-10" ixy="4.8503e-10"  ixz="2.09591e-13" iyy="1.48655e-09" iyz="-2.62533e-14" izz="1.76782e-09" />
</inertial>
</link>

<joint name="wheel2_sub5" type="revolute">
<origin xyz="-0.00825 -0.0142894 0.0189056" rpy="0.00183987 -0.00106225 -9.77199e-07" />
<parent link="horn4_1" />
<child link="wheel2_sub5_1" />
<axis xyz="-0.866025 0.5 0"/>
<limit effort="1" velocity="20" />
<joint_properties friction="0.0"/>
</joint>

<link name="wheel2_sub4_1">
<collision>
<origin xyz="0.0534199 -0.0535157 0.032114" rpy="-7.01868e-18 1.05629e-17 -8.21079e-19" />
<geometry>
<mesh filename="package://sub_wheel.stl"/>
</geometry>
<material name="sub_wheel_material">
<color rgba="0.768627 0.886275 0.952941 1.0"/>
</material>
</collision>
<visual>
<origin xyz="0 0 0" rpy="0 -0 0" />
<geometry>
<mesh filename="package://wheel2_sub4_1.stl"/>
</geometry>
<material name="wheel2_sub4_1_material">
<color rgba="0.768627 0.886275 0.952941 1.0"/>
</material>
</visual>
<inertial>
<origin xyz="3.67355e-05 -2.09868e-05 5.31199e-07" rpy="0 0 0"/>
<mass value="9.9564e-05" />
<inertia ixx="9.26988e-10" ixy="4.8503e-10"  ixz="2.09591e-13" iyy="1.48655e-09" iyz="-2.62533e-14" izz="1.76782e-09" />
</inertial>
</link>

<joint name="wheel2_sub6" type="revolute">
<origin xyz="-0.0165 -5.55112e-17 0.0189056" rpy="1.57117 -0.523599 -1.57099" />
<parent link="horn4_1" />
<child link="wheel2_sub4_1" />
<axis xyz="-0.866025 0.5 0"/>
<limit effort="1" velocity="20" />
<joint_properties friction="0.0"/>
</joint>

<link name="wheel2_sub1_1">
<collision>
<origin xyz="0.0534199 -0.0535157 0.032114" rpy="5.97579e-17 1.15166e-18 -2.50355e-17" />
<geometry>
<mesh filename="package://sub_wheel.stl"/>
</geometry>
<material name="sub_wheel_material">
<color rgba="0.768627 0.886275 0.952941 1.0"/>
</material>
</collision>
<visual>
<origin xyz="0 0 0" rpy="0 -0 0" />
<geometry>
<mesh filename="package://wheel2_sub1_1.stl"/>
</geometry>
<material name="wheel2_sub1_1_material">
<color rgba="0.768627 0.886275 0.952941 1.0"/>
</material>
</visual>
<inertial>
<origin xyz="3.67355e-05 -2.09868e-05 5.31199e-07" rpy="0 0 0"/>
<mass value="9.9564e-05" />
<inertia ixx="9.26988e-10" ixy="4.8503e-10"  ixz="2.09591e-13" iyy="1.48655e-09" iyz="-2.62533e-14" izz="1.76782e-09" />
</inertial>
</link>

<joint name="wheel2_sub7" type="revolute">
<origin xyz="2.77556e-16 -0.0165 0.0102056" rpy="3.13965 -0.00112434 2.61799" />
<parent link="horn4_1" />
<child link="wheel2_sub1_1" />
<axis xyz="-0.866025 0.5 0"/>
<limit effort="1" velocity="20" />
<joint_properties friction="0.0"/>
</joint>

<link name="wheel2_sub8_1">
<collision>
<origin xyz="0.0534199 -0.0535157 0.032114" rpy="-1.88112e-17 -2.51848e-17 -4.33871e-18" />
<geometry>
<mesh filename="package://sub_wheel.stl"/>
</geometry>
<material name="sub_wheel_material">
<color rgba="0.768627 0.886275 0.952941 1.0"/>
</material>
</collision>
<visual>
<origin xyz="0 0 0" rpy="0 -0 0" />
<geometry>
<mesh filename="package://wheel2_sub8_1.stl"/>
</geometry>
<material name="wheel2_sub8_1_material">
<color rgba="0.768627 0.886275 0.952941 1.0"/>
</material>
</visual>
<inertial>
<origin xyz="3.67355e-05 -2.09868e-05 5.31199e-07" rpy="0 0 0"/>
<mass value="9.9564e-05" />
<inertia ixx="9.26988e-10" ixy="4.8503e-10"  ixz="2.09591e-13" iyy="1.48655e-09" iyz="-2.62533e-14" izz="1.76782e-09" />
</inertial>
</link>

<joint name="wheel2_sub8" type="revolute">
<origin xyz="0.0142894 -0.00825 0.0102056" rpy="1.56971 -0.523599 -2.09385" />
<parent link="horn4_1" />
<child link="wheel2_sub8_1" />
<axis xyz="-0.866025 0.5 0"/>
<limit effort="1" velocity="20" />
<joint_properties friction="0.0"/>
</joint>

<link name="wheel2_sub10_1">
<collision>
<origin xyz="0.0534199 -0.0535157 0.032114" rpy="1.52351e-17 -4.78727e-17 -1.40387e-17" />
<geometry>
<mesh filename="package://sub_wheel.stl"/>
</geometry>
<material name="sub_wheel_material">
<color rgba="0.768627 0.886275 0.952941 1.0"/>
</material>
</collision>
<visual>
<origin xyz="0 0 0" rpy="0 -0 0" />
<geometry>
<mesh filename="package://wheel2_sub10_1.stl"/>
</geometry>
<material name="wheel2_sub10_1_material">
<color rgba="0.768627 0.886275 0.952941 1.0"/>
</material>
</visual>
<inertial>
<origin xyz="3.67355e-05 -2.09868e-05 5.31199e-07" rpy="0 0 0"/>
<mass value="9.9564e-05" />
<inertia ixx="9.26988e-10" ixy="4.8503e-10"  ixz="2.09591e-13" iyy="1.48655e-09" iyz="-2.62533e-14" izz="1.76782e-09" />
</inertial>
</link>

<joint name="wheel2_sub9" type="revolute">
<origin xyz="0.0142894 0.00825 0.0102056" rpy="1.5725 -0.523598 -1.04805" />
<parent link="horn4_1" />
<child link="wheel2_sub10_1" />
<axis xyz="-0.866025 0.5 0"/>
<limit effort="1" velocity="20" />
<joint_properties friction="0.0"/>
</joint>

<link name="wheel2_sub12_1">
<collision>
<origin xyz="0.0534199 -0.0535157 0.032114" rpy="-3.82994e-18 -2.82561e-17 -1.16832e-18" />
<geometry>
<mesh filename="package://sub_wheel.stl"/>
</geometry>
<material name="sub_wheel_material">
<color rgba="0.768627 0.886275 0.952941 1.0"/>
</material>
</collision>
<visual>
<origin xyz="0 0 0" rpy="0 -0 0" />
<geometry>
<mesh filename="package://wheel2_sub12_1.stl"/>
</geometry>
<material name="wheel2_sub12_1_material">
<color rgba="0.768627 0.886275 0.952941 1.0"/>
</material>
</visual>
<inertial>
<origin xyz="3.67355e-05 -2.09868e-05 5.31199e-07" rpy="0 0 0"/>
<mass value="9.9564e-05" />
<inertia ixx="9.26988e-10" ixy="4.8503e-10"  ixz="2.09591e-13" iyy="1.48655e-09" iyz="-2.62533e-14" izz="1.76782e-09" />
</inertial>
</link>

<joint name="wheel2_sub10" type="revolute">
<origin xyz="-0.0142894 0.00825 0.0102056" rpy="1.56971 -0.523599 -2.09385" />
<parent link="horn4_1" />
<child link="wheel2_sub12_1" />
<axis xyz="-0.866025 0.5 0"/>
<limit effort="1" velocity="20" />
<joint_properties friction="0.0"/>
</joint>

<link name="wheel2_sub6_1">
<collision>
<origin xyz="0.0534199 -0.0535157 0.032114" rpy="3.49698e-17 6.07824e-17 -2.85331e-17" />
<geometry>
<mesh filename="package://sub_wheel.stl"/>
</geometry>
<material name="sub_wheel_material">
<color rgba="0.768627 0.886275 0.952941 1.0"/>
</material>
</collision>
<visual>
<origin xyz="0 0 0" rpy="0 -0 0" />
<geometry>
<mesh filename="package://wheel2_sub6_1.stl"/>
</geometry>
<material name="wheel2_sub6_1_material">
<color rgba="0.768627 0.886275 0.952941 1.0"/>
</material>
</visual>
<inertial>
<origin xyz="3.67355e-05 -2.09868e-05 5.31199e-07" rpy="0 0 0"/>
<mass value="9.9564e-05" />
<inertia ixx="9.26988e-10" ixy="4.8503e-10"  ixz="2.09591e-13" iyy="1.48655e-09" iyz="-2.62533e-14" izz="1.76782e-09" />
</inertial>
</link>

<joint name="wheel2_sub11" type="revolute">
<origin xyz="-0.0142894 -0.00825 0.0102056" rpy="1.5725 -0.523598 -1.04805" />
<parent link="horn4_1" />
<child link="wheel2_sub6_1" />
<axis xyz="-0.866025 0.5 0"/>
<limit effort="1" velocity="20" />
<joint_properties friction="0.0"/>
</joint>

<link name="wheel2_sub11_1">
<collision>
<origin xyz="0.0534199 -0.0535157 0.032114" rpy="-1.92929e-18 -1.0851e-17 3.64284e-17" />
<geometry>
<mesh filename="package://sub_wheel.stl"/>
</geometry>
<material name="sub_wheel_material">
<color rgba="0.768627 0.886275 0.952941 1.0"/>
</material>
</collision>
<visual>
<origin xyz="0 0 0" rpy="0 -0 0" />
<geometry>
<mesh filename="package://wheel2_sub11_1.stl"/>
</geometry>
<material name="wheel2_sub11_1_material">
<color rgba="0.768627 0.886275 0.952941 1.0"/>
</material>
</visual>
<inertial>
<origin xyz="3.67355e-05 -2.09868e-05 5.31199e-07" rpy="0 0 0"/>
<mass value="9.9564e-05" />
<inertia ixx="9.26988e-10" ixy="4.8503e-10"  ixz="2.09591e-13" iyy="1.48655e-09" iyz="-2.62533e-14" izz="1.76782e-09" />
</inertial>
</link>

<joint name="wheel2_sub12" type="revolute">
<origin xyz="-3.05311e-16 0.0165 0.0102056" rpy="3.13965 -0.00112434 2.61799" />
<parent link="horn4_1" />
<child link="wheel2_sub11_1" />
<axis xyz="-0.866025 0.5 0"/>
<limit effort="1" velocity="20" />
<joint_properties friction="0.0"/>
</joint>

<joint name="wheel4" type="revolute">
<origin xyz="0.0595475 -0.0498349 -0.138971" rpy="1.5708 1.43948 1.08609" />
<parent link="body_1" />
<child link="horn4_1" />
<axis xyz="0 0 -1"/>
<limit effort="1" velocity="20" />
<joint_properties friction="0.0"/>
</joint>

<link name="horn2_1">
<collision>
<origin xyz="0.04517 -0.0678046 0.0423198" rpy="1.01629e-14 -3.38439e-16 3.44199e-16" />
<geometry>
<mesh filename="package://main_frame.stl"/>
</geometry>
<material name="main_frame_material">
<color rgba="0.980392 0.713725 0.00392157 1.0"/>
</material>
</collision>
<collision>
<origin xyz="0.217932 -0.171498 0.00431" rpy="3.14159 -9.32422e-15 1.5708" />
<geometry>
<mesh filename="package://horn.stl"/>
</geometry>
<material name="horn_material">
<color rgba="0.231373 0.380392 0.705882 1.0"/>
</material>
</collision>
<collision>
<origin xyz="-3.46945e-18 -2.77556e-17 0.0012" rpy="-2.22175e-17 -9.1306e-17 -7.69461e-18" />
<geometry>
<mesh filename="package://mx-12w_horn.stl"/>
</geometry>
<material name="mx-12w_horn_material">
<color rgba="0.980392 0.713725 0.00392157 1.0"/>
</material>
</collision>
<visual>
<origin xyz="0 0 0" rpy="0 -0 0" />
<geometry>
<mesh filename="package://horn2_1.stl"/>
</geometry>
<material name="horn2_1_material">
<color rgba="0.937052 0.694438 0.0445389 1.0"/>
</material>
</visual>
<inertial>
<origin xyz="-1.11491e-06 -2.12888e-08 0.012158" rpy="0 0 0"/>
<mass value="0.0125567" />
<inertia ixx="1.27584e-06" ixy="-1.42503e-11"  ixz="-1.22446e-10" iyy="1.27561e-06" iyz="-1.41565e-11" izz="1.48771e-06" />
</inertial>
</link>

<link name="wheel3_sub6_1">
<collision>
<origin xyz="0.0534199 -0.0535157 0.032114" rpy="-1.47786e-17 9.49758e-17 1.67439e-17" />
<geometry>
<mesh filename="package://sub_wheel.stl"/>
</geometry>
<material name="sub_wheel_material">
<color rgba="0.768627 0.886275 0.952941 1.0"/>
</material>
</collision>
<visual>
<origin xyz="0 0 0" rpy="0 -0 0" />
<geometry>
<mesh filename="package://wheel3_sub6_1.stl"/>
</geometry>
<material name="wheel3_sub6_1_material">
<color rgba="0.768627 0.886275 0.952941 1.0"/>
</material>
</visual>
<inertial>
<origin xyz="3.67355e-05 -2.09868e-05 5.31199e-07" rpy="0 0 0"/>
<mass value="9.9564e-05" />
<inertia ixx="9.26988e-10" ixy="4.8503e-10"  ixz="2.09591e-13" iyy="1.48655e-09" iyz="-2.62533e-14" izz="1.76782e-09" />
</inertial>
</link>

<joint name="wheel3_sub1" type="revolute">
<origin xyz="0.0142894 0.00825 0.0189056" rpy="2.1658 -0.445999 1.81033" />
<parent link="horn2_1" />
<child link="wheel3_sub6_1" />
<axis xyz="-0.866025 0.5 0"/>
<limit effort="1" velocity="20" />
<joint_properties friction="0.0"/>
</joint>

<link name="wheel3_sub2_1">
<collision>
<origin xyz="0.0534199 -0.0535157 0.032114" rpy="2.72373e-17 1.39476e-17 -6.77526e-17" />
<geometry>
<mesh filename="package://sub_wheel.stl"/>
</geometry>
<material name="sub_wheel_material">
<color rgba="0.768627 0.886275 0.952941 1.0"/>
</material>
</collision>
<visual>
<origin xyz="0 0 0" rpy="0 -0 0" />
<geometry>
<mesh filename="package://wheel3_sub2_1.stl"/>
</geometry>
<material name="wheel3_sub2_1_material">
<color rgba="0.768627 0.886275 0.952941 1.0"/>
</material>
</visual>
<inertial>
<origin xyz="3.67355e-05 -2.09868e-05 5.31199e-07" rpy="0 0 0"/>
<mass value="9.9564e-05" />
<inertia ixx="9.26988e-10" ixy="4.8503e-10"  ixz="2.09591e-13" iyy="1.48655e-09" iyz="-2.62533e-14" izz="1.76782e-09" />
</inertial>
</link>

<joint name="wheel3_sub2" type="revolute">
<origin xyz="-1.94289e-16 0.0165 0.0189056" rpy="1.78384 -0.513754 3.03568" />
<parent link="horn2_1" />
<child link="wheel3_sub2_1" />
<axis xyz="-0.866025 0.5 0"/>
<limit effort="1" velocity="20" />
<joint_properties friction="0.0"/>
</joint>

<link name="wheel3_sub3_1">
<collision>
<origin xyz="0.0534199 -0.0535157 0.032114" rpy="-7.06882e-17 1.04333e-17 1.27107e-17" />
<geometry>
<mesh filename="package://sub_wheel.stl"/>
</geometry>
<material name="sub_wheel_material">
<color rgba="0.768627 0.886275 0.952941 1.0"/>
</material>
</collision>
<visual>
<origin xyz="0 0 0" rpy="0 -0 0" />
<geometry>
<mesh filename="package://wheel3_sub3_1.stl"/>
</geometry>
<material name="wheel3_sub3_1_material">
<color rgba="0.768627 0.886275 0.952941 1.0"/>
</material>
</visual>
<inertial>
<origin xyz="3.67355e-05 -2.09868e-05 5.31199e-07" rpy="0 0 0"/>
<mass value="9.9564e-05" />
<inertia ixx="9.26988e-10" ixy="4.8503e-10"  ixz="2.09591e-13" iyy="1.48655e-09" iyz="-2.62533e-14" izz="1.76782e-09" />
</inertial>
</link>

<joint name="wheel3_sub3" type="revolute">
<origin xyz="-0.0142894 0.00825 0.0189056" rpy="1.13033 -0.481285 -1.87957" />
<parent link="horn2_1" />
<child link="wheel3_sub3_1" />
<axis xyz="-0.866025 0.5 0"/>
<limit effort="1" velocity="20" />
<joint_properties friction="0.0"/>
</joint>

<link name="wheel3_sub1_1">
<collision>
<origin xyz="0.0534199 -0.0535157 0.032114" rpy="-4.97677e-17 -4.08822e-17 -1.52152e-17" />
<geometry>
<mesh filename="package://sub_wheel.stl"/>
</geometry>
<material name="sub_wheel_material">
<color rgba="0.768627 0.886275 0.952941 1.0"/>
</material>
</collision>
<visual>
<origin xyz="0 0 0" rpy="0 -0 0" />
<geometry>
<mesh filename="package://wheel3_sub1_1.stl"/>
</geometry>
<material name="wheel3_sub1_1_material">
<color rgba="0.768627 0.886275 0.952941 1.0"/>
</material>
</visual>
<inertial>
<origin xyz="3.67355e-05 -2.09868e-05 5.31199e-07" rpy="0 0 0"/>
<mass value="9.9564e-05" />
<inertia ixx="9.26988e-10" ixy="4.8503e-10"  ixz="2.09591e-13" iyy="1.48655e-09" iyz="-2.62533e-14" izz="1.76782e-09" />
</inertial>
</link>

<joint name="wheel3_sub4" type="revolute">
<origin xyz="-0.0142894 -0.00825 0.0189056" rpy="2.1658 -0.445999 1.81033" />
<parent link="horn2_1" />
<child link="wheel3_sub1_1" />
<axis xyz="-0.866025 0.5 0"/>
<limit effort="1" velocity="20" />
<joint_properties friction="0.0"/>
</joint>

<link name="wheel3_sub12_1">
<collision>
<origin xyz="0.0534199 -0.0535157 0.032114" rpy="-4.46338e-17 -2.50378e-18 3.55096e-17" />
<geometry>
<mesh filename="package://sub_wheel.stl"/>
</geometry>
<material name="sub_wheel_material">
<color rgba="0.768627 0.886275 0.952941 1.0"/>
</material>
</collision>
<visual>
<origin xyz="0 0 0" rpy="0 -0 0" />
<geometry>
<mesh filename="package://wheel3_sub12_1.stl"/>
</geometry>
<material name="wheel3_sub12_1_material">
<color rgba="0.768627 0.886275 0.952941 1.0"/>
</material>
</visual>
<inertial>
<origin xyz="3.67355e-05 -2.09868e-05 5.31199e-07" rpy="0 0 0"/>
<mass value="9.9564e-05" />
<inertia ixx="9.26988e-10" ixy="4.8503e-10"  ixz="2.09591e-13" iyy="1.48655e-09" iyz="-2.62533e-14" izz="1.76782e-09" />
</inertial>
</link>

<joint name="wheel3_sub5" type="revolute">
<origin xyz="0.0142894 -0.00825 0.0189056" rpy="1.13033 -0.481285 -1.87957" />
<parent link="horn2_1" />
<child link="wheel3_sub12_1" />
<axis xyz="-0.866025 0.5 0"/>
<limit effort="1" velocity="20" />
<joint_properties friction="0.0"/>
</joint>

<link name="wheel3_sub9_1">
<collision>
<origin xyz="0.0534199 -0.0535157 0.032114" rpy="-5.96873e-17 -6.06243e-18 4.02317e-17" />
<geometry>
<mesh filename="package://sub_wheel.stl"/>
</geometry>
<material name="sub_wheel_material">
<color rgba="0.768627 0.886275 0.952941 1.0"/>
</material>
</collision>
<visual>
<origin xyz="0 0 0" rpy="0 -0 0" />
<geometry>
<mesh filename="package://wheel3_sub9_1.stl"/>
</geometry>
<material name="wheel3_sub9_1_material">
<color rgba="0.768627 0.886275 0.952941 1.0"/>
</material>
</visual>
<inertial>
<origin xyz="3.67355e-05 -2.09868e-05 5.31199e-07" rpy="0 0 0"/>
<mass value="9.9564e-05" />
<inertia ixx="9.26988e-10" ixy="4.8503e-10"  ixz="2.09591e-13" iyy="1.48655e-09" iyz="-2.62533e-14" izz="1.76782e-09" />
</inertial>
</link>

<joint name="wheel3_sub6" type="revolute">
<origin xyz="2.42861e-17 -0.0165 0.0189056" rpy="1.78384 -0.513754 3.03568" />
<parent link="horn2_1" />
<child link="wheel3_sub9_1" />
<axis xyz="-0.866025 0.5 0"/>
<limit effort="1" velocity="20" />
<joint_properties friction="0.0"/>
</joint>

<link name="wheel3_sub5_1">
<collision>
<origin xyz="0.0534199 -0.0535157 0.032114" rpy="-3.03987e-18 3.3682e-17 -4.89015e-18" />
<geometry>
<mesh filename="package://sub_wheel.stl"/>
</geometry>
<material name="sub_wheel_material">
<color rgba="0.768627 0.886275 0.952941 1.0"/>
</material>
</collision>
<visual>
<origin xyz="0 0 0" rpy="0 -0 0" />
<geometry>
<mesh filename="package://wheel3_sub5_1.stl"/>
</geometry>
<material name="wheel3_sub5_1_material">
<color rgba="0.768627 0.886275 0.952941 1.0"/>
</material>
</visual>
<inertial>
<origin xyz="3.67355e-05 -2.09868e-05 5.31199e-07" rpy="0 0 0"/>
<mass value="9.9564e-05" />
<inertia ixx="9.26988e-10" ixy="4.8503e-10"  ixz="2.09591e-13" iyy="1.48655e-09" iyz="-2.62533e-14" izz="1.76782e-09" />
</inertial>
</link>

<joint name="wheel3_sub7" type="revolute">
<origin xyz="0.00825 0.0142894 0.0102056" rpy="2.03522 -0.476522 2.39213" />
<parent link="horn2_1" />
<child link="wheel3_sub5_1" />
<axis xyz="-0.866025 0.5 0"/>
<limit effort="1" velocity="20" />
<joint_properties friction="0.0"/>
</joint>

<link name="wheel3_sub4_1">
<collision>
<origin xyz="0.0534199 -0.0535157 0.032114" rpy="6.67926e-18 -7.03253e-18 4.2568e-17" />
<geometry>
<mesh filename="package://sub_wheel.stl"/>
</geometry>
<material name="sub_wheel_material">
<color rgba="0.768627 0.886275 0.952941 1.0"/>
</material>
</collision>
<visual>
<origin xyz="0 0 0" rpy="0 -0 0" />
<geometry>
<mesh filename="package://wheel3_sub4_1.stl"/>
</geometry>
<material name="wheel3_sub4_1_material">
<color rgba="0.768627 0.886275 0.952941 1.0"/>
</material>
</visual>
<inertial>
<origin xyz="3.67355e-05 -2.09868e-05 5.31199e-07" rpy="0 0 0"/>
<mass value="9.9564e-05" />
<inertia ixx="9.26988e-10" ixy="4.8503e-10"  ixz="2.09591e-13" iyy="1.48655e-09" iyz="-2.62533e-14" izz="1.76782e-09" />
</inertial>
</link>

<joint name="wheel3_sub8" type="revolute">
<origin xyz="0.0165 2.77556e-17 0.0102056" rpy="-0.471208 0.25633 -1.10905" />
<parent link="horn2_1" />
<child link="wheel3_sub4_1" />
<axis xyz="-0.866025 0.5 0"/>
<limit effort="1" velocity="20" />
<joint_properties friction="0.0"/>
</joint>

<link name="wheel3_sub11_1">
<collision>
<origin xyz="0.0534199 -0.0535157 0.032114" rpy="8.61122e-17 7.20586e-18 6.95597e-17" />
<geometry>
<mesh filename="package://sub_wheel.stl"/>
</geometry>
<material name="sub_wheel_material">
<color rgba="0.768627 0.886275 0.952941 1.0"/>
</material>
</collision>
<visual>
<origin xyz="0 0 0" rpy="0 -0 0" />
<geometry>
<mesh filename="package://wheel3_sub11_1.stl"/>
</geometry>
<material name="wheel3_sub11_1_material">
<color rgba="0.768627 0.886275 0.952941 1.0"/>
</material>
</visual>
<inertial>
<origin xyz="3.67355e-05 -2.09868e-05 5.31199e-07" rpy="0 0 0"/>
<mass value="9.9564e-05" />
<inertia ixx="9.26988e-10" ixy="4.8503e-10"  ixz="2.09591e-13" iyy="1.48655e-09" iyz="-2.62533e-14" izz="1.76782e-09" />
</inertial>
</link>

<joint name="wheel3_sub9" type="revolute">
<origin xyz="0.00825 -0.0142894 0.0102056" rpy="1.43612 -0.519669 -2.55081" />
<parent link="horn2_1" />
<child link="wheel3_sub11_1" />
<axis xyz="-0.866025 0.5 0"/>
<limit effort="1" velocity="20" />
<joint_properties friction="0.0"/>
</joint>

<link name="wheel3_sub8_1">
<collision>
<origin xyz="0.0534199 -0.0535157 0.032114" rpy="-1.22724e-17 -1.06364e-17 4.69372e-18" />
<geometry>
<mesh filename="package://sub_wheel.stl"/>
</geometry>
<material name="sub_wheel_material">
<color rgba="0.768627 0.886275 0.952941 1.0"/>
</material>
</collision>
<visual>
<origin xyz="0 0 0" rpy="0 -0 0" />
<geometry>
<mesh filename="package://wheel3_sub8_1.stl"/>
</geometry>
<material name="wheel3_sub8_1_material">
<color rgba="0.768627 0.886275 0.952941 1.0"/>
</material>
</visual>
<inertial>
<origin xyz="3.67355e-05 -2.09868e-05 5.31199e-07" rpy="0 0 0"/>
<mass value="9.9564e-05" />
<inertia ixx="9.26988e-10" ixy="4.8503e-10"  ixz="2.09591e-13" iyy="1.48655e-09" iyz="-2.62533e-14" izz="1.76782e-09" />
</inertial>
</link>

<joint name="wheel3_sub10" type="revolute">
<origin xyz="-0.00825 -0.0142894 0.0102056" rpy="2.03522 -0.476522 2.39213" />
<parent link="horn2_1" />
<child link="wheel3_sub8_1" />
<axis xyz="-0.866025 0.5 0"/>
<limit effort="1" velocity="20" />
<joint_properties friction="0.0"/>
</joint>

<link name="wheel3_sub10_1">
<collision>
<origin xyz="0.0534199 -0.0535157 0.032114" rpy="5.96187e-17 -4.80461e-17 -1.243e-17" />
<geometry>
<mesh filename="package://sub_wheel.stl"/>
</geometry>
<material name="sub_wheel_material">
<color rgba="0.768627 0.886275 0.952941 1.0"/>
</material>
</collision>
<visual>
<origin xyz="0 0 0" rpy="0 -0 0" />
<geometry>
<mesh filename="package://wheel3_sub10_1.stl"/>
</geometry>
<material name="wheel3_sub10_1_material">
<color rgba="0.768627 0.886275 0.952941 1.0"/>
</material>
</visual>
<inertial>
<origin xyz="3.67355e-05 -2.09868e-05 5.31199e-07" rpy="0 0 0"/>
<mass value="9.9564e-05" />
<inertia ixx="9.26988e-10" ixy="4.8503e-10"  ixz="2.09591e-13" iyy="1.48655e-09" iyz="-2.62533e-14" izz="1.76782e-09" />
</inertial>
</link>

<joint name="wheel3_sub11" type="revolute">
<origin xyz="-0.00825 0.0142894 0.0102056" rpy="1.43612 -0.519669 -2.55081" />
<parent link="horn2_1" />
<child link="wheel3_sub10_1" />
<axis xyz="-0.866025 0.5 0"/>
<limit effort="1" velocity="20" />
<joint_properties friction="0.0"/>
</joint>

<link name="wheel3_sub7_1">
<collision>
<origin xyz="0.0534199 -0.0535157 0.032114" rpy="7.3931e-17 -4.60966e-17 -4.23408e-17" />
<geometry>
<mesh filename="package://sub_wheel.stl"/>
</geometry>
<material name="sub_wheel_material">
<color rgba="0.768627 0.886275 0.952941 1.0"/>
</material>
</collision>
<visual>
<origin xyz="0 0 0" rpy="0 -0 0" />
<geometry>
<mesh filename="package://wheel3_sub7_1.stl"/>
</geometry>
<material name="wheel3_sub7_1_material">
<color rgba="0.768627 0.886275 0.952941 1.0"/>
</material>
</visual>
<inertial>
<origin xyz="3.67355e-05 -2.09868e-05 5.31199e-07" rpy="0 0 0"/>
<mass value="9.9564e-05" />
<inertia ixx="9.26988e-10" ixy="4.8503e-10"  ixz="2.09591e-13" iyy="1.48655e-09" iyz="-2.62533e-14" izz="1.76782e-09" />
</inertial>
</link>

<joint name="wheel3_sub12" type="revolute">
<origin xyz="-0.0165 -2.77556e-17 0.0102056" rpy="-0.471208 0.25633 -1.10905" />
<parent link="horn2_1" />
<child link="wheel3_sub7_1" />
<axis xyz="-0.866025 0.5 0"/>
<limit effort="1" velocity="20" />
<joint_properties friction="0.0"/>
</joint>

<joint name="wheel1" type="revolute">
<origin xyz="0.0537824 0.0575285 -0.138971" rpy="1.5708 -0.202005 2.13103" />
<parent link="body_1" />
<child link="horn2_1" />
<axis xyz="0 0 -1"/>
<limit effort="1" velocity="20" />
<joint_properties friction="0.0"/>
</joint>

<link name="horn1_1">
<collision>
<origin xyz="-0.171498 -0.217932 0.00431" rpy="3.14159 9.82996e-17 1.94653e-17" />
<geometry>
<mesh filename="package://horn.stl"/>
</geometry>
<material name="horn_material">
<color rgba="0.231373 0.380392 0.705882 1.0"/>
</material>
</collision>
<collision>
<origin xyz="0.04517 -0.0678046 0.0423198" rpy="8.16394e-18 1.23518e-15 -6.04782e-17" />
<geometry>
<mesh filename="package://main_frame.stl"/>
</geometry>
<material name="main_frame_material">
<color rgba="0.980392 0.713725 0.00392157 1.0"/>
</material>
</collision>
<collision>
<origin xyz="0 -6.93889e-18 0.0012" rpy="2.6051e-17 1.67801e-19 -1.16379e-18" />
<geometry>
<mesh filename="package://mx-12w_horn.stl"/>
</geometry>
<material name="mx-12w_horn_material">
<color rgba="0.980392 0.713725 0.00392157 1.0"/>
</material>
</collision>
<visual>
<origin xyz="0 0 0" rpy="0 -0 0" />
<geometry>
<mesh filename="package://horn1_1.stl"/>
</geometry>
<material name="horn1_1_material">
<color rgba="0.937052 0.694438 0.0445389 1.0"/>
</material>
</visual>
<inertial>
<origin xyz="-1.11491e-06 -2.12888e-08 0.012158" rpy="0 0 0"/>
<mass value="0.0125567" />
<inertia ixx="1.27584e-06" ixy="-1.42503e-11"  ixz="-1.22446e-10" iyy="1.27561e-06" iyz="-1.41565e-11" izz="1.48771e-06" />
</inertial>
</link>

<link name="wheel4_sub11_1">
<collision>
<origin xyz="0.0534199 -0.0535157 0.032114" rpy="-1.33049e-17 1.59749e-17 -1.4801e-17" />
<geometry>
<mesh filename="package://sub_wheel.stl"/>
</geometry>
<material name="sub_wheel_material">
<color rgba="0.768627 0.886275 0.952941 1.0"/>
</material>
</collision>
<visual>
<origin xyz="0 0 0" rpy="0 -0 0" />
<geometry>
<mesh filename="package://wheel4_sub11_1.stl"/>
</geometry>
<material name="wheel4_sub11_1_material">
<color rgba="0.768627 0.886275 0.952941 1.0"/>
</material>
</visual>
<inertial>
<origin xyz="3.67355e-05 -2.09868e-05 5.31199e-07" rpy="0 0 0"/>
<mass value="9.9564e-05" />
<inertia ixx="9.26988e-10" ixy="4.8503e-10"  ixz="2.09591e-13" iyy="1.48655e-09" iyz="-2.62533e-14" izz="1.76782e-09" />
</inertial>
</link>

<joint name="wheel4_sub1" type="revolute">
<origin xyz="0.0142894 -0.00825 0.0189056" rpy="-1.75519 0.516227 -2.1862" />
<parent link="horn1_1" />
<child link="wheel4_sub11_1" />
<axis xyz="-0.866025 0.5 0"/>
<limit effort="1" velocity="20" />
<joint_properties friction="0.0"/>
</joint>

<link name="wheel4_sub5_1">
<collision>
<origin xyz="0.0534199 -0.0535157 0.032114" rpy="2.75408e-17 7.47097e-17 7.12879e-17" />
<geometry>
<mesh filename="package://sub_wheel.stl"/>
</geometry>
<material name="sub_wheel_material">
<color rgba="0.768627 0.886275 0.952941 1.0"/>
</material>
</collision>
<visual>
<origin xyz="0 0 0" rpy="0 -0 0" />
<geometry>
<mesh filename="package://wheel4_sub5_1.stl"/>
</geometry>
<material name="wheel4_sub5_1_material">
<color rgba="0.768627 0.886275 0.952941 1.0"/>
</material>
</visual>
<inertial>
<origin xyz="3.67355e-05 -2.09868e-05 5.31199e-07" rpy="0 0 0"/>
<mass value="9.9564e-05" />
<inertia ixx="9.26988e-10" ixy="4.8503e-10"  ixz="2.09591e-13" iyy="1.48655e-09" iyz="-2.62533e-14" izz="1.76782e-09" />
</inertial>
</link>

<joint name="wheel4_sub2" type="revolute">
<origin xyz="0.0142894 0.00825 0.0189056" rpy="-1.41279 0.518188 -0.968439" />
<parent link="horn1_1" />
<child link="wheel4_sub5_1" />
<axis xyz="-0.866025 0.5 0"/>
<limit effort="1" velocity="20" />
<joint_properties friction="0.0"/>
</joint>

<link name="wheel4_sub3_1">
<collision>
<origin xyz="0.0534199 -0.0535157 0.032114" rpy="4.57638e-17 1.1168e-17 2.06902e-17" />
<geometry>
<mesh filename="package://sub_wheel.stl"/>
</geometry>
<material name="sub_wheel_material">
<color rgba="0.768627 0.886275 0.952941 1.0"/>
</material>
</collision>
<visual>
<origin xyz="0 0 0" rpy="0 -0 0" />
<geometry>
<mesh filename="package://wheel4_sub3_1.stl"/>
</geometry>
<material name="wheel4_sub3_1_material">
<color rgba="0.768627 0.886275 0.952941 1.0"/>
</material>
</visual>
<inertial>
<origin xyz="3.67355e-05 -2.09868e-05 5.31199e-07" rpy="0 0 0"/>
<mass value="9.9564e-05" />
<inertia ixx="9.26988e-10" ixy="4.8503e-10"  ixz="2.09591e-13" iyy="1.48655e-09" iyz="-2.62533e-14" izz="1.76782e-09" />
</inertial>
</link>

<joint name="wheel4_sub3" type="revolute">
<origin xyz="5.55112e-17 0.0165 0.0189056" rpy="0.325326 -0.182478 0.493571" />
<parent link="horn1_1" />
<child link="wheel4_sub3_1" />
<axis xyz="-0.866025 0.5 0"/>
<limit effort="1" velocity="20" />
<joint_properties friction="0.0"/>
</joint>

<link name="wheel4_sub6_1">
<collision>
<origin xyz="0.0534199 -0.0535157 0.032114" rpy="-2.62446e-17 1.01069e-17 4.55375e-17" />
<geometry>
<mesh filename="package://sub_wheel.stl"/>
</geometry>
<material name="sub_wheel_material">
<color rgba="0.768627 0.886275 0.952941 1.0"/>
</material>
</collision>
<visual>
<origin xyz="0 0 0" rpy="0 -0 0" />
<geometry>
<mesh filename="package://wheel4_sub6_1.stl"/>
</geometry>
<material name="wheel4_sub6_1_material">
<color rgba="0.768627 0.886275 0.952941 1.0"/>
</material>
</visual>
<inertial>
<origin xyz="3.67355e-05 -2.09868e-05 5.31199e-07" rpy="0 0 0"/>
<mass value="9.9564e-05" />
<inertia ixx="9.26988e-10" ixy="4.8503e-10"  ixz="2.09591e-13" iyy="1.48655e-09" iyz="-2.62533e-14" izz="1.76782e-09" />
</inertial>
</link>

<joint name="wheel4_sub4" type="revolute">
<origin xyz="-0.0142894 0.00825 0.0189056" rpy="-1.75519 0.516227 -2.1862" />
<parent link="horn1_1" />
<child link="wheel4_sub6_1" />
<axis xyz="-0.866025 0.5 0"/>
<limit effort="1" velocity="20" />
<joint_properties friction="0.0"/>
</joint>

<link name="wheel4_sub10_1">
<collision>
<origin xyz="0.0534199 -0.0535157 0.032114" rpy="-2.16245e-17 4.803e-17 -6.25339e-17" />
<geometry>
<mesh filename="package://sub_wheel.stl"/>
</geometry>
<material name="sub_wheel_material">
<color rgba="0.768627 0.886275 0.952941 1.0"/>
</material>
</collision>
<visual>
<origin xyz="0 0 0" rpy="0 -0 0" />
<geometry>
<mesh filename="package://wheel4_sub10_1.stl"/>
</geometry>
<material name="wheel4_sub10_1_material">
<color rgba="0.768627 0.886275 0.952941 1.0"/>
</material>
</visual>
<inertial>
<origin xyz="3.67355e-05 -2.09868e-05 5.31199e-07" rpy="0 0 0"/>
<mass value="9.9564e-05" />
<inertia ixx="9.26988e-10" ixy="4.8503e-10"  ixz="2.09591e-13" iyy="1.48655e-09" iyz="-2.62533e-14" izz="1.76782e-09" />
</inertial>
</link>

<joint name="wheel4_sub5" type="revolute">
<origin xyz="-0.0142894 -0.00825 0.0189056" rpy="-1.41279 0.518188 -0.968439" />
<parent link="horn1_1" />
<child link="wheel4_sub10_1" />
<axis xyz="-0.866025 0.5 0"/>
<limit effort="1" velocity="20" />
<joint_properties friction="0.0"/>
</joint>

<link name="wheel4_sub9_1">
<collision>
<origin xyz="0.0534199 -0.0535157 0.032114" rpy="-4.06287e-17 3.21388e-17 -7.05327e-17" />
<geometry>
<mesh filename="package://sub_wheel.stl"/>
</geometry>
<material name="sub_wheel_material">
<color rgba="0.768627 0.886275 0.952941 1.0"/>
</material>
</collision>
<visual>
<origin xyz="0 0 0" rpy="0 -0 0" />
<geometry>
<mesh filename="package://wheel4_sub9_1.stl"/>
</geometry>
<material name="wheel4_sub9_1_material">
<color rgba="0.768627 0.886275 0.952941 1.0"/>
</material>
</visual>
<inertial>
<origin xyz="3.67355e-05 -2.09868e-05 5.31199e-07" rpy="0 0 0"/>
<mass value="9.9564e-05" />
<inertia ixx="9.26988e-10" ixy="4.8503e-10"  ixz="2.09591e-13" iyy="1.48655e-09" iyz="-2.62533e-14" izz="1.76782e-09" />
</inertial>
</link>

<joint name="wheel4_sub6" type="revolute">
<origin xyz="-8.32667e-17 -0.0165 0.0189056" rpy="0.325326 -0.182478 0.493571" />
<parent link="horn1_1" />
<child link="wheel4_sub9_1" />
<axis xyz="-0.866025 0.5 0"/>
<limit effort="1" velocity="20" />
<joint_properties friction="0.0"/>
</joint>

<link name="wheel4_sub8_1">
<collision>
<origin xyz="0.0534199 -0.0535157 0.032114" rpy="-6.77547e-17 1.95377e-17 -8.51508e-18" />
<geometry>
<mesh filename="package://sub_wheel.stl"/>
</geometry>
<material name="sub_wheel_material">
<color rgba="0.768627 0.886275 0.952941 1.0"/>
</material>
</collision>
<visual>
<origin xyz="0 0 0" rpy="0 -0 0" />
<geometry>
<mesh filename="package://wheel4_sub8_1.stl"/>
</geometry>
<material name="wheel4_sub8_1_material">
<color rgba="0.768627 0.886275 0.952941 1.0"/>
</material>
</visual>
<inertial>
<origin xyz="3.67355e-05 -2.09868e-05 5.31199e-07" rpy="0 0 0"/>
<mass value="9.9564e-05" />
<inertia ixx="9.26988e-10" ixy="4.8503e-10"  ixz="2.09591e-13" iyy="1.48655e-09" iyz="-2.62533e-14" izz="1.76782e-09" />
</inertial>
</link>

<joint name="wheel4_sub7" type="revolute">
<origin xyz="0.00825 -0.0142894 0.0102056" rpy="2.86836 -0.154554 -3.1203" />
<parent link="horn1_1" />
<child link="wheel4_sub8_1" />
<axis xyz="-0.866025 0.5 0"/>
<limit effort="1" velocity="20" />
<joint_properties friction="0.0"/>
</joint>

<link name="wheel4_sub7_1">
<collision>
<origin xyz="0.0534199 -0.0535157 0.032114" rpy="-3.36318e-17 3.01723e-17 5.20486e-17" />
<geometry>
<mesh filename="package://sub_wheel.stl"/>
</geometry>
<material name="sub_wheel_material">
<color rgba="0.768627 0.886275 0.952941 1.0"/>
</material>
</collision>
<visual>
<origin xyz="0 0 0" rpy="0 -0 0" />
<geometry>
<mesh filename="package://wheel4_sub7_1.stl"/>
</geometry>
<material name="wheel4_sub7_1_material">
<color rgba="0.768627 0.886275 0.952941 1.0"/>
</material>
</visual>
<inertial>
<origin xyz="3.67355e-05 -2.09868e-05 5.31199e-07" rpy="0 0 0"/>
<mass value="9.9564e-05" />
<inertia ixx="9.26988e-10" ixy="4.8503e-10"  ixz="2.09591e-13" iyy="1.48655e-09" iyz="-2.62533e-14" izz="1.76782e-09" />
</inertial>
</link>

<joint name="wheel4_sub8" type="revolute">
<origin xyz="-0.00825 -0.0142894 0.0102056" rpy="-1.23916 0.499683 -0.360075" />
<parent link="horn1_1" />
<child link="wheel4_sub7_1" />
<axis xyz="-0.866025 0.5 0"/>
<limit effort="1" velocity="20" />
<joint_properties friction="0.0"/>
</joint>

<link name="wheel4_sub4_1">
<collision>
<origin xyz="0.0534199 -0.0535157 0.032114" rpy="-5.80625e-19 -8.50848e-19 -7.4722e-18" />
<geometry>
<mesh filename="package://sub_wheel.stl"/>
</geometry>
<material name="sub_wheel_material">
<color rgba="0.768627 0.886275 0.952941 1.0"/>
</material>
</collision>
<visual>
<origin xyz="0 0 0" rpy="0 -0 0" />
<geometry>
<mesh filename="package://wheel4_sub4_1.stl"/>
</geometry>
<material name="wheel4_sub4_1_material">
<color rgba="0.768627 0.886275 0.952941 1.0"/>
</material>
</visual>
<inertial>
<origin xyz="3.67355e-05 -2.09868e-05 5.31199e-07" rpy="0 0 0"/>
<mass value="9.9564e-05" />
<inertia ixx="9.26988e-10" ixy="4.8503e-10"  ixz="2.09591e-13" iyy="1.48655e-09" iyz="-2.62533e-14" izz="1.76782e-09" />
</inertial>
</link>

<joint name="wheel4_sub9" type="revolute">
<origin xyz="-0.0165 2.77556e-17 0.0102056" rpy="-1.58335 0.523565 -1.57707" />
<parent link="horn1_1" />
<child link="wheel4_sub4_1" />
<axis xyz="-0.866025 0.5 0"/>
<limit effort="1" velocity="20" />
<joint_properties friction="0.0"/>
</joint>

<link name="wheel4_sub1_1">
<collision>
<origin xyz="0.0534199 -0.0535157 0.032114" rpy="5.63219e-17 -3.14753e-17 1.87613e-17" />
<geometry>
<mesh filename="package://sub_wheel.stl"/>
</geometry>
<material name="sub_wheel_material">
<color rgba="0.768627 0.886275 0.952941 1.0"/>
</material>
</collision>
<visual>
<origin xyz="0 0 0" rpy="0 -0 0" />
<geometry>
<mesh filename="package://wheel4_sub1_1.stl"/>
</geometry>
<material name="wheel4_sub1_1_material">
<color rgba="0.768627 0.886275 0.952941 1.0"/>
</material>
</visual>
<inertial>
<origin xyz="3.67355e-05 -2.09868e-05 5.31199e-07" rpy="0 0 0"/>
<mass value="9.9564e-05" />
<inertia ixx="9.26988e-10" ixy="4.8503e-10"  ixz="2.09591e-13" iyy="1.48655e-09" iyz="-2.62533e-14" izz="1.76782e-09" />
</inertial>
</link>

<joint name="wheel4_sub10" type="revolute">
<origin xyz="0.00825 0.0142894 0.0102056" rpy="-1.23916 0.499683 -0.360075" />
<parent link="horn1_1" />
<child link="wheel4_sub1_1" />
<axis xyz="-0.866025 0.5 0"/>
<limit effort="1" velocity="20" />
<joint_properties friction="0.0"/>
</joint>

<link name="wheel4_sub12_1">
<collision>
<origin xyz="0.0534199 -0.0535157 0.032114" rpy="2.98304e-17 -6.49597e-18 6.58617e-18" />
<geometry>
<mesh filename="package://sub_wheel.stl"/>
</geometry>
<material name="sub_wheel_material">
<color rgba="0.768627 0.886275 0.952941 1.0"/>
</material>
</collision>
<visual>
<origin xyz="0 0 0" rpy="0 -0 0" />
<geometry>
<mesh filename="package://wheel4_sub12_1.stl"/>
</geometry>
<material name="wheel4_sub12_1_material">
<color rgba="0.768627 0.886275 0.952941 1.0"/>
</material>
</visual>
<inertial>
<origin xyz="3.67355e-05 -2.09868e-05 5.31199e-07" rpy="0 0 0"/>
<mass value="9.9564e-05" />
<inertia ixx="9.26988e-10" ixy="4.8503e-10"  ixz="2.09591e-13" iyy="1.48655e-09" iyz="-2.62533e-14" izz="1.76782e-09" />
</inertial>
</link>

<joint name="wheel4_sub11" type="revolute">
<origin xyz="-0.00825 0.0142894 0.0102056" rpy="2.86836 -0.154554 -3.1203" />
<parent link="horn1_1" />
<child link="wheel4_sub12_1" />
<axis xyz="-0.866025 0.5 0"/>
<limit effort="1" velocity="20" />
<joint_properties friction="0.0"/>
</joint>

<link name="wheel4_sub2_1">
<collision>
<origin xyz="0.0534199 -0.0535157 0.032114" rpy="-5.18797e-20 2.07484e-19 -8.49103e-17" />
<geometry>
<mesh filename="package://sub_wheel.stl"/>
</geometry>
<material name="sub_wheel_material">
<color rgba="0.768627 0.886275 0.952941 1.0"/>
</material>
</collision>
<visual>
<origin xyz="0 0 0" rpy="0 -0 0" />
<geometry>
<mesh filename="package://wheel4_sub2_1.stl"/>
</geometry>
<material name="wheel4_sub2_1_material">
<color rgba="0.768627 0.886275 0.952941 1.0"/>
</material>
</visual>
<inertial>
<origin xyz="3.67355e-05 -2.09868e-05 5.31199e-07" rpy="0 0 0"/>
<mass value="9.9564e-05" />
<inertia ixx="9.26988e-10" ixy="4.8503e-10"  ixz="2.09591e-13" iyy="1.48655e-09" iyz="-2.62533e-14" izz="1.76782e-09" />
</inertial>
</link>

<joint name="wheel4_sub12" type="revolute">
<origin xyz="0.0165 3.1225e-17 0.0102056" rpy="-1.58335 0.523565 -1.57707" />
<parent link="horn1_1" />
<child link="wheel4_sub2_1" />
<axis xyz="-0.866025 0.5 0"/>
<limit effort="1" velocity="20" />
<joint_properties friction="0.0"/>
</joint>

<joint name="wheel3" type="revolute">
<origin xyz="-0.0553404 -0.0546608 -0.138971" rpy="1.57079 -1.56454 -1.01056" />
<parent link="body_1" />
<child link="horn1_1" />
<axis xyz="0 0 -1"/>
<limit effort="1" velocity="20" />
<joint_properties friction="0.0"/>
</joint>

<link name="horn4_2">
<collision>
<origin xyz="0.171498 0.217932 0.00431" rpy="-3.14159 1.11518e-17 3.14159" />
<geometry>
<mesh filename="package://horn.stl"/>
</geometry>
<material name="horn_material">
<color rgba="0.231373 0.380392 0.705882 1.0"/>
</material>
</collision>
<collision>
<origin xyz="0.0678046 0.04517 0.0423198" rpy="1.17593e-14 8.21185e-15 1.5708" />
<geometry>
<mesh filename="package://main_frame.stl"/>
</geometry>
<material name="main_frame_material">
<color rgba="0.980392 0.713725 0.00392157 1.0"/>
</material>
</collision>
<collision>
<origin xyz="-3.46945e-18 0 0.0012" rpy="1.25254e-20 1.51831e-17 -1.37212e-19" />
<geometry>
<mesh filename="package://mx-12w_horn.stl"/>
</geometry>
<material name="mx-12w_horn_material">
<color rgba="0.980392 0.713725 0.00392157 1.0"/>
</material>
</collision>
<visual>
<origin xyz="0 0 0" rpy="0 -0 0" />
<geometry>
<mesh filename="package://horn4_2.stl"/>
</geometry>
<material name="horn4_2_material">
<color rgba="0.937052 0.694438 0.0445389 1.0"/>
</material>
</visual>
<inertial>
<origin xyz="-9.44942e-07 -1.4867e-07 0.012158" rpy="0 0 0"/>
<mass value="0.0125567" />
<inertia ixx="1.27588e-06" ixy="1.42523e-11"  ixz="-1.50868e-10" iyy="1.27557e-06" iyz="-4.04238e-12" izz="1.48771e-06" />
</inertial>
</link>

<link name="wheel1_sub3_1">
<collision>
<origin xyz="0.0534199 -0.0535157 0.032114" rpy="8.03655e-17 4.50428e-21 -2.65058e-19" />
<geometry>
<mesh filename="package://sub_wheel.stl"/>
</geometry>
<material name="sub_wheel_material">
<color rgba="0.768627 0.886275 0.952941 1.0"/>
</material>
</collision>
<visual>
<origin xyz="0 0 0" rpy="0 -0 0" />
<geometry>
<mesh filename="package://wheel1_sub3_1.stl"/>
</geometry>
<material name="wheel1_sub3_1_material">
<color rgba="0.768627 0.886275 0.952941 1.0"/>
</material>
</visual>
<inertial>
<origin xyz="3.67355e-05 -2.09868e-05 5.31199e-07" rpy="0 0 0"/>
<mass value="9.9564e-05" />
<inertia ixx="9.26988e-10" ixy="4.8503e-10"  ixz="2.09591e-13" iyy="1.48655e-09" iyz="-2.62533e-14" izz="1.76782e-09" />
</inertial>
</link>

<joint name="wheel1_sub1" type="revolute">
<origin xyz="-0.0142894 -0.00825 0.0102056" rpy="-3.14159 6.54647e-09 -1.5708" />
<parent link="horn4_2" />
<child link="wheel1_sub3_1" />
<axis xyz="-0.866025 0.5 0"/>
<limit effort="1" velocity="20" />
<joint_properties friction="0.0"/>
</joint>

<link name="wheel1_sub7_1">
<collision>
<origin xyz="0.0534199 -0.0535157 0.032114" rpy="-8.46414e-20 -1.24167e-19 -2.08115e-18" />
<geometry>
<mesh filename="package://sub_wheel.stl"/>
</geometry>
<material name="sub_wheel_material">
<color rgba="0.768627 0.886275 0.952941 1.0"/>
</material>
</collision>
<visual>
<origin xyz="0 0 0" rpy="0 -0 0" />
<geometry>
<mesh filename="package://wheel1_sub7_1.stl"/>
</geometry>
<material name="wheel1_sub7_1_material">
<color rgba="0.768627 0.886275 0.952941 1.0"/>
</material>
</visual>
<inertial>
<origin xyz="3.67355e-05 -2.09868e-05 5.31199e-07" rpy="0 0 0"/>
<mass value="9.9564e-05" />
<inertia ixx="9.26988e-10" ixy="4.8503e-10"  ixz="2.09591e-13" iyy="1.48655e-09" iyz="-2.62533e-14" izz="1.76782e-09" />
</inertial>
</link>

<joint name="wheel1_sub2" type="revolute">
<origin xyz="5.20417e-17 -0.0165 0.0102056" rpy="-1.5708 0.523599 1.50893e-08" />
<parent link="horn4_2" />
<child link="wheel1_sub7_1" />
<axis xyz="-0.866025 0.5 0"/>
<limit effort="1" velocity="20" />
<joint_properties friction="0.0"/>
</joint>

<link name="wheel1_sub11_1">
<collision>
<origin xyz="0.0534199 -0.0535157 0.032114" rpy="2.77761e-17 -2.30939e-17 5.55921e-17" />
<geometry>
<mesh filename="package://sub_wheel.stl"/>
</geometry>
<material name="sub_wheel_material">
<color rgba="0.768627 0.886275 0.952941 1.0"/>
</material>
</collision>
<visual>
<origin xyz="0 0 0" rpy="0 -0 0" />
<geometry>
<mesh filename="package://wheel1_sub11_1.stl"/>
</geometry>
<material name="wheel1_sub11_1_material">
<color rgba="0.768627 0.886275 0.952941 1.0"/>
</material>
</visual>
<inertial>
<origin xyz="3.67355e-05 -2.09868e-05 5.31199e-07" rpy="0 0 0"/>
<mass value="9.9564e-05" />
<inertia ixx="9.26988e-10" ixy="4.8503e-10"  ixz="2.09591e-13" iyy="1.48655e-09" iyz="-2.62533e-14" izz="1.76782e-09" />
</inertial>
</link>

<joint name="wheel1_sub3" type="revolute">
<origin xyz="-0.0142894 0.00825 0.0102056" rpy="3.14159 -6.52124e-09 -2.61799" />
<parent link="horn4_2" />
<child link="wheel1_sub11_1" />
<axis xyz="-0.866025 0.5 0"/>
<limit effort="1" velocity="20" />
<joint_properties friction="0.0"/>
</joint>

<link name="wheel1_sub8_1">
<collision>
<origin xyz="0.0534199 -0.0535157 0.032114" rpy="2.57319e-20 7.60437e-20 1.63327e-18" />
<geometry>
<mesh filename="package://sub_wheel.stl"/>
</geometry>
<material name="sub_wheel_material">
<color rgba="0.768627 0.886275 0.952941 1.0"/>
</material>
</collision>
<visual>
<origin xyz="0 0 0" rpy="0 -0 0" />
<geometry>
<mesh filename="package://wheel1_sub8_1.stl"/>
</geometry>
<material name="wheel1_sub8_1_material">
<color rgba="0.768627 0.886275 0.952941 1.0"/>
</material>
</visual>
<inertial>
<origin xyz="3.67355e-05 -2.09868e-05 5.31199e-07" rpy="0 0 0"/>
<mass value="9.9564e-05" />
<inertia ixx="9.26988e-10" ixy="4.8503e-10"  ixz="2.09591e-13" iyy="1.48655e-09" iyz="-2.62533e-14" izz="1.76782e-09" />
</inertial>
</link>

<joint name="wheel1_sub4" type="revolute">
<origin xyz="-8.32667e-17 0.0165 0.0102056" rpy="-1.5708 0.523599 1.50893e-08" />
<parent link="horn4_2" />
<child link="wheel1_sub8_1" />
<axis xyz="-0.866025 0.5 0"/>
<limit effort="1" velocity="20" />
<joint_properties friction="0.0"/>
</joint>

<link name="wheel1_sub10_1">
<collision>
<origin xyz="0.0534199 -0.0535157 0.032114" rpy="2.59059e-17 -1.5024e-17 4.51414e-17" />
<geometry>
<mesh filename="package://sub_wheel.stl"/>
</geometry>
<material name="sub_wheel_material">
<color rgba="0.768627 0.886275 0.952941 1.0"/>
</material>
</collision>
<visual>
<origin xyz="0 0 0" rpy="0 -0 0" />
<geometry>
<mesh filename="package://wheel1_sub10_1.stl"/>
</geometry>
<material name="wheel1_sub10_1_material">
<color rgba="0.768627 0.886275 0.952941 1.0"/>
</material>
</visual>
<inertial>
<origin xyz="3.67355e-05 -2.09868e-05 5.31199e-07" rpy="0 0 0"/>
<mass value="9.9564e-05" />
<inertia ixx="9.26988e-10" ixy="4.8503e-10"  ixz="2.09591e-13" iyy="1.48655e-09" iyz="-2.62533e-14" izz="1.76782e-09" />
</inertial>
</link>

<joint name="wheel1_sub5" type="revolute">
<origin xyz="-0.00825 0.0142894 0.0189056" rpy="1.95889e-08 -1.13097e-08 1.0472" />
<parent link="horn4_2" />
<child link="wheel1_sub10_1" />
<axis xyz="-0.866025 0.5 0"/>
<limit effort="1" velocity="20" />
<joint_properties friction="0.0"/>
</joint>

<link name="wheel1_sub9_1">
<collision>
<origin xyz="0.0534199 -0.0535157 0.032114" rpy="2.8674e-17 6.27403e-18 1.25597e-18" />
<geometry>
<mesh filename="package://sub_wheel.stl"/>
</geometry>
<material name="sub_wheel_material">
<color rgba="0.768627 0.886275 0.952941 1.0"/>
</material>
</collision>
<visual>
<origin xyz="0 0 0" rpy="0 -0 0" />
<geometry>
<mesh filename="package://wheel1_sub9_1.stl"/>
</geometry>
<material name="wheel1_sub9_1_material">
<color rgba="0.768627 0.886275 0.952941 1.0"/>
</material>
</visual>
<inertial>
<origin xyz="3.67355e-05 -2.09868e-05 5.31199e-07" rpy="0 0 0"/>
<mass value="9.9564e-05" />
<inertia ixx="9.26988e-10" ixy="4.8503e-10"  ixz="2.09591e-13" iyy="1.48655e-09" iyz="-2.62533e-14" izz="1.76782e-09" />
</inertial>
</link>

<joint name="wheel1_sub6" type="revolute">
<origin xyz="-0.00825 -0.0142894 0.0189056" rpy="-1.5708 0.523599 -0.523599" />
<parent link="horn4_2" />
<child link="wheel1_sub9_1" />
<axis xyz="-0.866025 0.5 0"/>
<limit effort="1" velocity="20" />
<joint_properties friction="0.0"/>
</joint>

<link name="wheel1_sub4_1">
<collision>
<origin xyz="0.0534199 -0.0535157 0.032114" rpy="-2.42938e-17 -4.09874e-17 -1.34562e-17" />
<geometry>
<mesh filename="package://sub_wheel.stl"/>
</geometry>
<material name="sub_wheel_material">
<color rgba="0.768627 0.886275 0.952941 1.0"/>
</material>
</collision>
<visual>
<origin xyz="0 0 0" rpy="0 -0 0" />
<geometry>
<mesh filename="package://wheel1_sub4_1.stl"/>
</geometry>
<material name="wheel1_sub4_1_material">
<color rgba="0.768627 0.886275 0.952941 1.0"/>
</material>
</visual>
<inertial>
<origin xyz="3.67355e-05 -2.09868e-05 5.31199e-07" rpy="0 0 0"/>
<mass value="9.9564e-05" />
<inertia ixx="9.26988e-10" ixy="4.8503e-10"  ixz="2.09591e-13" iyy="1.48655e-09" iyz="-2.62533e-14" izz="1.76782e-09" />
</inertial>
</link>

<joint name="wheel1_sub7" type="revolute">
<origin xyz="0.00825 -0.0142894 0.0189056" rpy="-1.5708 0.523599 0.523599" />
<parent link="horn4_2" />
<child link="wheel1_sub4_1" />
<axis xyz="-0.866025 0.5 0"/>
<limit effort="1" velocity="20" />
<joint_properties friction="0.0"/>
</joint>

<link name="wheel1_sub1_1">
<collision>
<origin xyz="0.0534199 -0.0535157 0.032114" rpy="-5.29684e-18 2.58257e-17 2.60584e-18" />
<geometry>
<mesh filename="package://sub_wheel.stl"/>
</geometry>
<material name="sub_wheel_material">
<color rgba="0.768627 0.886275 0.952941 1.0"/>
</material>
</collision>
<visual>
<origin xyz="0 0 0" rpy="0 -0 0" />
<geometry>
<mesh filename="package://wheel1_sub1_1.stl"/>
</geometry>
<material name="wheel1_sub1_1_material">
<color rgba="0.768627 0.886275 0.952941 1.0"/>
</material>
</visual>
<inertial>
<origin xyz="3.67355e-05 -2.09868e-05 5.31199e-07" rpy="0 0 0"/>
<mass value="9.9564e-05" />
<inertia ixx="9.26988e-10" ixy="4.8503e-10"  ixz="2.09591e-13" iyy="1.48655e-09" iyz="-2.62533e-14" izz="1.76782e-09" />
</inertial>
</link>

<joint name="wheel1_sub8" type="revolute">
<origin xyz="-0.0165 2.77556e-17 0.0189056" rpy="-3.14159 1.45692e-11 -2.0944" />
<parent link="horn4_2" />
<child link="wheel1_sub1_1" />
<axis xyz="-0.866025 0.5 0"/>
<limit effort="1" velocity="20" />
<joint_properties friction="0.0"/>
</joint>

<link name="wheel1_sub12_1">
<collision>
<origin xyz="0.0534199 -0.0535157 0.032114" rpy="1.20919e-17 5.2866e-17 -1.90727e-17" />
<geometry>
<mesh filename="package://sub_wheel.stl"/>
</geometry>
<material name="sub_wheel_material">
<color rgba="0.768627 0.886275 0.952941 1.0"/>
</material>
</collision>
<visual>
<origin xyz="0 0 0" rpy="0 -0 0" />
<geometry>
<mesh filename="package://wheel1_sub12_1.stl"/>
</geometry>
<material name="wheel1_sub12_1_material">
<color rgba="0.768627 0.886275 0.952941 1.0"/>
</material>
</visual>
<inertial>
<origin xyz="3.67355e-05 -2.09868e-05 5.31199e-07" rpy="0 0 0"/>
<mass value="9.9564e-05" />
<inertia ixx="9.26988e-10" ixy="4.8503e-10"  ixz="2.09591e-13" iyy="1.48655e-09" iyz="-2.62533e-14" izz="1.76782e-09" />
</inertial>
</link>

<joint name="wheel1_sub9" type="revolute">
<origin xyz="0.00825 0.0142894 0.0189056" rpy="-1.5708 0.523599 -0.523599" />
<parent link="horn4_2" />
<child link="wheel1_sub12_1" />
<axis xyz="-0.866025 0.5 0"/>
<limit effort="1" velocity="20" />
<joint_properties friction="0.0"/>
</joint>

<link name="wheel1_sub6_1">
<collision>
<origin xyz="0.0534199 -0.0535157 0.032114" rpy="1.74577e-17 -2.20231e-17 9.11037e-17" />
<geometry>
<mesh filename="package://sub_wheel.stl"/>
</geometry>
<material name="sub_wheel_material">
<color rgba="0.768627 0.886275 0.952941 1.0"/>
</material>
</collision>
<visual>
<origin xyz="0 0 0" rpy="0 -0 0" />
<geometry>
<mesh filename="package://wheel1_sub6_1.stl"/>
</geometry>
<material name="wheel1_sub6_1_material">
<color rgba="0.768627 0.886275 0.952941 1.0"/>
</material>
</visual>
<inertial>
<origin xyz="3.67355e-05 -2.09868e-05 5.31199e-07" rpy="0 0 0"/>
<mass value="9.9564e-05" />
<inertia ixx="9.26988e-10" ixy="4.8503e-10"  ixz="2.09591e-13" iyy="1.48655e-09" iyz="-2.62533e-14" izz="1.76782e-09" />
</inertial>
</link>

<joint name="wheel1_sub10" type="revolute">
<origin xyz="0.0165 -1.11022e-16 0.0189056" rpy="-2.52434e-11 1.45839e-11 2.0944" />
<parent link="horn4_2" />
<child link="wheel1_sub6_1" />
<axis xyz="-0.866025 0.5 0"/>
<limit effort="1" velocity="20" />
<joint_properties friction="0.0"/>
</joint>

<link name="wheel1_sub5_1">
<collision>
<origin xyz="0.0534199 -0.0535157 0.032114" rpy="-3.24406e-18 -1.86372e-17 3.38951e-17" />
<geometry>
<mesh filename="package://sub_wheel.stl"/>
</geometry>
<material name="sub_wheel_material">
<color rgba="0.768627 0.886275 0.952941 1.0"/>
</material>
</collision>
<visual>
<origin xyz="0 0 0" rpy="0 -0 0" />
<geometry>
<mesh filename="package://wheel1_sub5_1.stl"/>
</geometry>
<material name="wheel1_sub5_1_material">
<color rgba="0.768627 0.886275 0.952941 1.0"/>
</material>
</visual>
<inertial>
<origin xyz="3.67355e-05 -2.09868e-05 5.31199e-07" rpy="0 0 0"/>
<mass value="9.9564e-05" />
<inertia ixx="9.26988e-10" ixy="4.8503e-10"  ixz="2.09591e-13" iyy="1.48655e-09" iyz="-2.62533e-14" izz="1.76782e-09" />
</inertial>
</link>

<joint name="wheel1_sub11" type="revolute">
<origin xyz="0.0142894 -0.00825 0.0102056" rpy="-3.14159 6.52124e-09 0.523599" />
<parent link="horn4_2" />
<child link="wheel1_sub5_1" />
<axis xyz="-0.866025 0.5 0"/>
<limit effort="1" velocity="20" />
<joint_properties friction="0.0"/>
</joint>

<link name="wheel1_sub2_1">
<collision>
<origin xyz="0.0534199 -0.0535157 0.032114" rpy="-2.40881e-17 -5.94068e-20 -3.49158e-19" />
<geometry>
<mesh filename="package://sub_wheel.stl"/>
</geometry>
<material name="sub_wheel_material">
<color rgba="0.768627 0.886275 0.952941 1.0"/>
</material>
</collision>
<visual>
<origin xyz="0 0 0" rpy="0 -0 0" />
<geometry>
<mesh filename="package://wheel1_sub2_1.stl"/>
</geometry>
<material name="wheel1_sub2_1_material">
<color rgba="0.768627 0.886275 0.952941 1.0"/>
</material>
</visual>
<inertial>
<origin xyz="3.67355e-05 -2.09868e-05 5.31199e-07" rpy="0 0 0"/>
<mass value="9.9564e-05" />
<inertia ixx="9.26988e-10" ixy="4.8503e-10"  ixz="2.09591e-13" iyy="1.48655e-09" iyz="-2.62533e-14" izz="1.76782e-09" />
</inertial>
</link>

<joint name="wheel1_sub12" type="revolute">
<origin xyz="0.0142894 0.00825 0.0102056" rpy="-3.14159 6.54647e-09 -1.5708" />
<parent link="horn4_2" />
<child link="wheel1_sub2_1" />
<axis xyz="-0.866025 0.5 0"/>
<limit effort="1" velocity="20" />
<joint_properties friction="0.0"/>
</joint>

<joint name="wheel2" type="revolute">
<origin xyz="-0.0577404 0.0532068 -0.138971" rpy="1.5708 -0.00111608 -2.05776" />
<parent link="body_1" />
<child link="horn4_2" />
<axis xyz="0 0 -1"/>
<limit effort="1" velocity="20" />
<joint_properties friction="0.0"/>
</joint>

<link name="roller_stick_1">
<collision>
<origin xyz="-0.04445 -0.29536 -0.137105" rpy="-2.64112e-22 2.28958e-23 -4.68924e-18" />
<geometry>
<mesh filename="package://solenoid_stick.stl"/>
</geometry>
<material name="solenoid_stick_material">
<color rgba="0.972549 0.529412 0.00392157 1.0"/>
</material>
</collision>
<visual>
<origin xyz="0 0 0" rpy="0 -0 0" />
<geometry>
<mesh filename="package://roller_stick_1.stl"/>
</geometry>
<material name="roller_stick_1_material">
<color rgba="0.972549 0.529412 0.00392157 1.0"/>
</material>
</visual>
<inertial>
<origin xyz="6.93889e-18 -2.08555e-19 -2.77556e-17" rpy="0 0 0"/>
<mass value="0.0115774" />
<inertia ixx="1.72634e-07" ixy="-3.35404e-23"  ixz="-1.68722e-28" iyy="7.7112e-06" iyz="-8.68708e-27" izz="7.7112e-06" />
</inertial>
</link>

<joint name="stick" type="prismatic">
<origin xyz="0.00142928 -0.00185338 -0.131263" rpy="-5.12956e-06 9.95073e-08 -1.534" />
<parent link="body_1" />
<child link="roller_stick_1" />
<axis xyz="-1 0 0"/>
<limit effort="1" velocity="20" />
<joint_properties friction="0.0"/>
</joint>

<link name="jetson_nano_board_1">
<collision>
<origin xyz="0.0359932 -0.0256017 -0.0461966" rpy="3.14159 -9.45786e-08 -3.09132" />
<geometry>
<mesh filename="package://jetson_nano_board.stl"/>
</geometry>
<material name="jetson_nano_board_material">
<color rgba="0.470588 0.470588 0.470588 1.0"/>
</material>
</collision>
<visual>
<origin xyz="0 0 0" rpy="0 -0 0" />
<geometry>
<mesh filename="package://jetson_nano_board_1.stl"/>
</geometry>
<material name="jetson_nano_board_1_material">
<color rgba="0.470588 0.470588 0.470588 1.0"/>
</material>
</visual>
<inertial>
<origin xyz="-0.00860993 0.00258917 -0.0553562" rpy="0 0 0"/>
<mass value="0.313249" />
<inertia ixx="0.000144213" ixy="9.11453e-06"  ixz="7.10396e-07" iyy="0.000199833" iyz="2.02698e-05" izz="0.000304634" />
</inertial>
</link>

<joint name="14f6a0fa-50fd-4e0a-876d-cfa0b13145a9_fixing" type="fixed">
<origin xyz="0 0 0" rpy="0 -0 0" />
<parent link="body_1" />
<child link="jetson_nano_board_1" />
<axis xyz="0 0 1"/>
<limit effort="1" velocity="20" />
<joint_properties friction="0.0"/>
</joint>

<link name="antenna_1">
<collision>
<origin xyz="0.0110749 -0.00324886 -0.0436566" rpy="1.5708 -9.72302e-08 1.58414" />
<geometry>
<mesh filename="package://antenna_hub.step.stl"/>
</geometry>
<material name="antenna_hub.step_material">
<color rgba="0.666667 0.694118 0.764706 1.0"/>
</material>
</collision>
<collision>
<origin xyz="0.0106149 -0.00325235 -0.0436566" rpy="1.5708 -9.72302e-08 1.58414" />
<geometry>
<mesh filename="package://antennae.step.stl"/>
</geometry>
<material name="antennae.step_material">
<color rgba="0.109804 0.109804 0.109804 1.0"/>
</material>
</collision>
<visual>
<origin xyz="0 0 0" rpy="0 -0 0" />
<geometry>
<mesh filename="package://antenna_1.stl"/>
</geometry>
<material name="antenna_1_material">
<color rgba="0.231213 0.237197 0.252587 1.0"/>
</material>
</visual>
<inertial>
<origin xyz="0.0489384 0.0551749 0.031378" rpy="0 0 0"/>
<mass value="0.0230466" />
<inertia ixx="2.4591e-05" ixy="-7.54169e-10"  ixz="-4.40646e-07" iyy="5.96118e-05" iyz="1.75881e-08" izz="3.54165e-05" />
</inertial>
</link>

<joint name="85c3ce43-975a-45fe-98eb-e7c46caedfb9_fixing" type="fixed">
<origin xyz="0 0 0" rpy="0 -0 0" />
<parent link="body_1" />
<child link="antenna_1" />
<axis xyz="0 0 1"/>
<limit effort="1" velocity="20" />
<joint_properties friction="0.0"/>
</joint>

<link name="antenna_2">
<collision>
<origin xyz="-0.0864915 -0.00399694 -0.0436566" rpy="1.5708 -9.72302e-08 1.58414" />
<geometry>
<mesh filename="package://antenna_hub.step.stl"/>
</geometry>
<material name="antenna_hub.step_material">
<color rgba="0.666667 0.694118 0.764706 1.0"/>
</material>
</collision>
<collision>
<origin xyz="-0.0869515 -0.00400043 -0.0436566" rpy="1.5708 -9.72302e-08 1.58414" />
<geometry>
<mesh filename="package://antennae.step.stl"/>
</geometry>
<material name="antennae.step_material">
<color rgba="0.109804 0.109804 0.109804 1.0"/>
</material>
</collision>
<visual>
<origin xyz="0 0 0" rpy="0 -0 0" />
<geometry>
<mesh filename="package://antenna_2.stl"/>
</geometry>
<material name="antenna_2_material">
<color rgba="0.231213 0.237197 0.252587 1.0"/>
</material>
</visual>
<inertial>
<origin xyz="-0.048628 0.0544269 0.031378" rpy="0 0 0"/>
<mass value="0.0230466" />
<inertia ixx="2.4591e-05" ixy="-7.54169e-10"  ixz="-4.40646e-07" iyy="5.96118e-05" iyz="1.75881e-08" izz="3.54165e-05" />
</inertial>
</link>

<joint name="4d612aa2-3d1d-4034-86c5-11ee521d0272_fixing" type="fixed">
<origin xyz="0 0 0" rpy="0 -0 0" />
<parent link="body_1" />
<child link="antenna_2" />
<axis xyz="0 0 1"/>
<limit effort="1" velocity="20" />
<joint_properties friction="0.0"/>
</joint>

<link name="jetbot_mainboard_1">
<collision>
<origin xyz="0.000855957 -0.00169305 -0.0476566" rpy="1.5708 -9.50057e-08 -3.09557" />
<geometry>
<mesh filename="package://____.step.stl"/>
</geometry>
<material name="____.step_material">
<color rgba="0.196078 0.207843 0.262745 1.0"/>
</material>
</collision>
<collision>
<origin xyz="0.000855957 -0.00169305 -0.0476566" rpy="1.5708 -9.50057e-08 -3.09557" />
<geometry>
<mesh filename="package://____.step.stl"/>
</geometry>
<material name="____.step_material">
<color rgba="0.788235 0.788235 0.788235 1.0"/>
</material>
</collision>
<collision>
<origin xyz="0.000855957 -0.00169305 -0.0476566" rpy="1.5708 -9.50057e-08 -3.09557" />
<geometry>
<mesh filename="package://____.step.stl"/>
</geometry>
<material name="____.step_material">
<color rgba="0.196078 0.207843 0.262745 1.0"/>
</material>
</collision>
<collision>
<origin xyz="0.000855957 -0.00169305 -0.0476566" rpy="1.5708 -9.50057e-08 -3.09557" />
<geometry>
<mesh filename="package://____.step.stl"/>
</geometry>
<material name="____.step_material">
<color rgba="0.788235 0.788235 0.788235 1.0"/>
</material>
</collision>
<collision>
<origin xyz="0.000855957 -0.00169305 -0.0476566" rpy="1.5708 -9.50057e-08 -3.09557" />
<geometry>
<mesh filename="package://pcb.step.stl"/>
</geometry>
<material name="pcb.step_material">
<color rgba="0.298039 0.298039 0.298039 1.0"/>
</material>
</collision>
<collision>
<origin xyz="0.000855957 -0.00169305 -0.0476566" rpy="1.5708 -9.50057e-08 -3.09557" />
<geometry>
<mesh filename="package://____.step.stl"/>
</geometry>
<material name="____.step_material">
<color rgba="0.788235 0.788235 0.788235 1.0"/>
</material>
</collision>
<collision>
<origin xyz="0.000855957 -0.00169305 -0.0476566" rpy="1.5708 -9.50057e-08 -3.09557" />
<geometry>
<mesh filename="package://____.step.stl"/>
</geometry>
<material name="____.step_material">
<color rgba="0.788235 0.788235 0.788235 1.0"/>
</material>
</collision>
<collision>
<origin xyz="0.000855957 -0.00169305 -0.0476566" rpy="1.5708 -9.50057e-08 -3.09557" />
<geometry>
<mesh filename="package://pcb.step.stl"/>
</geometry>
<material name="pcb.step_material">
<color rgba="0.792157 0.792157 0.792157 1.0"/>
</material>
</collision>
<collision>
<origin xyz="0.000855957 -0.00169305 -0.0476566" rpy="1.5708 -9.50057e-08 -3.09557" />
<geometry>
<mesh filename="package://______.step.stl"/>
</geometry>
<material name="______.step_material">
<color rgba="1 1 1 1.0"/>
</material>
</collision>
<collision>
<origin xyz="0.000855957 -0.00169305 -0.0476566" rpy="1.5708 -9.50057e-08 -3.09557" />
<geometry>
<mesh filename="package://____.step.stl"/>
</geometry>
<material name="____.step_material">
<color rgba="0.784314 0.784314 0.784314 1.0"/>
</material>
</collision>
<collision>
<origin xyz="0.000855957 -0.00169305 -0.0476566" rpy="1.5708 -9.50057e-08 -3.09557" />
<geometry>
<mesh filename="package://____.step.stl"/>
</geometry>
<material name="____.step_material">
<color rgba="0.788235 0.788235 0.788235 1.0"/>
</material>
</collision>
<collision>
<origin xyz="0.000855957 -0.00169305 -0.0476566" rpy="1.5708 -9.50057e-08 -3.09557" />
<geometry>
<mesh filename="package://12v.step.stl"/>
</geometry>
<material name="12v.step_material">
<color rgba="0.054902 0.054902 0.054902 1.0"/>
</material>
</collision>
<collision>
<origin xyz="0.000855957 -0.00169305 -0.0476566" rpy="1.5708 -9.50057e-08 -3.09557" />
<geometry>
<mesh filename="package://pcb.step.stl"/>
</geometry>
<material name="pcb.step_material">
<color rgba="0.792157 0.792157 0.792157 1.0"/>
</material>
</collision>
<collision>
<origin xyz="0.000855957 -0.00169305 -0.0476566" rpy="1.5708 -9.50057e-08 -3.09557" />
<geometry>
<mesh filename="package://____.step.stl"/>
</geometry>
<material name="____.step_material">
<color rgba="0.788235 0.788235 0.788235 1.0"/>
</material>
</collision>
<collision>
<origin xyz="0.000855957 -0.00169305 -0.0476566" rpy="1.5708 -9.50057e-08 -3.09557" />
<geometry>
<mesh filename="package://1.14_tft_ips_-_13p_-_reverse_mount.step.stl"/>
</geometry>
<material name="1.14_tft_ips_-_13p_-_reverse_mount.step_material">
<color rgba="1 1 1 1.0"/>
</material>
</collision>
<visual>
<origin xyz="0 0 0" rpy="0 -0 0" />
<geometry>
<mesh filename="package://jetbot_mainboard_1.stl"/>
</geometry>
<material name="jetbot_mainboard_1_material">
<color rgba="0.662744 0.662751 0.662788 1.0"/>
</material>
</visual>
<inertial>
<origin xyz="-0.00151147 -0.00236581 -0.0397633" rpy="0 0 0"/>
<mass value="0.050638" />
<inertia ixx="3.13809e-05" ixy="-9.87308e-07"  ixz="-1.68428e-06" iyy="4.15679e-05" iyz="2.17178e-08" izz="7.02134e-05" />
</inertial>
</link>

<joint name="c8f045ff-b4f9-47ef-91d8-236058e12b27_fixing" type="fixed">
<origin xyz="0 0 0" rpy="0 -0 0" />
<parent link="body_1" />
<child link="jetbot_mainboard_1" />
<axis xyz="0 0 1"/>
<limit effort="1" velocity="20" />
<joint_properties friction="0.0"/>
</joint>

<link name="camera_holder_1">
<collision>
<origin xyz="0.00308185 0.274018 -0.0436566" rpy="-9.45786e-08 1.00791e-07 -1.52052" />
<geometry>
<mesh filename="package://camera_holder.stl"/>
</geometry>
<material name="camera_holder_material">
<color rgba="0.498039 0.498039 0.498039 1.0"/>
</material>
</collision>
<visual>
<origin xyz="0 0 0" rpy="0 -0 0" />
<geometry>
<mesh filename="package://camera_holder_1.stl"/>
</geometry>
<material name="camera_holder_1_material">
<color rgba="0.498039 0.498039 0.498039 1.0"/>
</material>
</visual>
<inertial>
<origin xyz="0.00184445 -0.0676636 -0.0373718" rpy="0 0 0"/>
<mass value="0.00309401" />
<inertia ixx="3.40706e-07" ixy="6.19345e-09"  ixz="-7.30947e-09" iyy="4.84187e-07" iyz="-1.23852e-07" izz="4.68613e-07" />
</inertial>
</link>

<link name="rspcameramia_1">
<collision>
<origin xyz="0.00202223 -0.0745669 -0.0321728" rpy="3.14159 -1.34625 -1.52052" />
<geometry>
<mesh filename="package://picamerapcb.stl"/>
</geometry>
<material name="picamerapcb_material">
<color rgba="0 0.517647 0 1.0"/>
</material>
</collision>
<collision>
<origin xyz="0.00245589 -0.0809561 -0.0309191" rpy="-1.5708 1.34625 1.62107" />
<geometry>
<mesh filename="package://ova5647_lens_fov.stl"/>
</geometry>
<material name="ova5647_lens_fov_material">
<color rgba="0 0 0 1.0"/>
</material>
</collision>
<collision>
<origin xyz="0.00220653 -0.0761239 -0.0298149" rpy="-1.5708 1.34625 1.62107" />
<geometry>
<mesh filename="package://ova5647_housing.stl"/>
</geometry>
<material name="ova5647_housing_material">
<color rgba="0.74902 0.74902 0.74902 1.0"/>
</material>
</collision>
<collision>
<origin xyz="0.00250476 -0.0765314 -0.0298367" rpy="-2.91705 9.45786e-08 0.0502736" />
<geometry>
<mesh filename="package://ribbon_cam.stl"/>
</geometry>
<material name="ribbon_cam_material">
<color rgba="1 0.945098 0.694118 1.0"/>
</material>
</collision>
<visual>
<origin xyz="0 0 0" rpy="0 -0 0" />
<geometry>
<mesh filename="package://rspcameramia_1.stl"/>
</geometry>
<material name="rspcameramia_1_material">
<color rgba="0.116168 0.499506 0.115092 1.0"/>
</material>
</visual>
<inertial>
<origin xyz="0.00221312 -0.0760991 -0.031586" rpy="0 0 0"/>
<mass value="0.00106392" />
<inertia ixx="7.88407e-08" ixy="-1.1471e-10"  ixz="-8.40461e-09" iyy="4.18615e-08" iyz="1.07649e-09" izz="4.36329e-08" />
</inertial>
</link>

<joint name="4980d050-d321-4e49-bd05-d17c1db043ca_fixing" type="fixed">
<origin xyz="0 0 0" rpy="0 -0 0" />
<parent link="camera_holder_1" />
<child link="rspcameramia_1" />
<axis xyz="0 0 1"/>
<limit effort="1" velocity="20" />
<joint_properties friction="0.0"/>
</joint>

<joint name="bdd03161-6324-48e1-a508-5bb3d436fb97_fixing" type="fixed">
<origin xyz="0 0 0" rpy="0 -0 0" />
<parent link="body_1" />
<child link="camera_holder_1" />
<axis xyz="0 0 1"/>
<limit effort="1" velocity="20" />
<joint_properties friction="0.0"/>
</joint>

<link name="ir_sensor_1">
<collision>
<origin xyz="-0.0344401 -0.0499897 -0.113737" rpy="-3.81895e-08 -1.32836e-07 2.65463" />
<geometry>
<mesh filename="package://part_1.stl"/>
</geometry>
<material name="part_1_material">
<color rgba="0.792157 0.819608 0.933333 1.0"/>
</material>
</collision>
<visual>
<origin xyz="0 0 0" rpy="0 -0 0" />
<geometry>
<mesh filename="package://ir_sensor_1.stl"/>
</geometry>
<material name="ir_sensor_1_material">
<color rgba="nan nan nan 1.0"/>
</material>
</visual>
<inertial>
<origin xyz="0 0 0" rpy="0 0 0"/>
<mass value="0" />
<inertia ixx="0" ixy="0"  ixz="0" iyy="0" iyz="0" izz="0" />
</inertial>
</link>

<joint name="a85a78fa-f816-41c1-bdfe-77bd1e57c4a7_fixing" type="fixed">
<origin xyz="0 0 0" rpy="0 -0 0" />
<parent link="body_1" />
<child link="ir_sensor_1" />
<axis xyz="0 0 1"/>
<limit effort="1" velocity="20" />
<joint_properties friction="0.0"/>
</joint>

<link name="lidar_frame_1">
<collision>
<origin xyz="-0.222709 0.0367899 -0.0787366" rpy="-9.70802e-08 9.83834e-08 -1.54564" />
<geometry>
<mesh filename="package://part_13.stl"/>
</geometry>
<material name="part_13_material">
<color rgba="0.980392 0.713725 0.00392157 1.0"/>
</material>
</collision>
<visual>
<origin xyz="0 0 0" rpy="0 -0 0" />
<geometry>
<mesh filename="package://lidar_frame_1.stl"/>
</geometry>
<material name="lidar_frame_1_material">
<color rgba="nan nan nan 1.0"/>
</material>
</visual>
<inertial>
<origin xyz="0 0 0" rpy="0 0 0"/>
<mass value="0" />
<inertia ixx="0" ixy="0"  ixz="0" iyy="0" iyz="0" izz="0" />
</inertial>
</link>

<link name="lidar_sensor_1">
<collision>
<origin xyz="0.0031877 -0.0718233 -0.0670486" rpy="3.14159 -9.70802e-08 -3.11644" />
<geometry>
<mesh filename="package://part_1.stl"/>
</geometry>
<material name="part_1_material">
<color rgba="0.25098 0.25098 0.25098 1.0"/>
</material>
</collision>
<visual>
<origin xyz="0 0 0" rpy="0 -0 0" />
<geometry>
<mesh filename="package://lidar_sensor_1.stl"/>
</geometry>
<material name="lidar_sensor_1_material">
<color rgba="nan nan nan 1.0"/>
</material>
</visual>
<inertial>
<origin xyz="0 0 0" rpy="0 0 0"/>
<mass value="0" />
<inertia ixx="0" ixy="0"  ixz="0" iyy="0" iyz="0" izz="0" />
</inertial>
</link>

<joint name="6d8d2cbc-e57e-4da0-a2b0-a74fcc6ed085_fixing" type="fixed">
<origin xyz="0 0 0" rpy="0 -0 0" />
<parent link="lidar_frame_1" />
<child link="lidar_sensor_1" />
<axis xyz="0 0 1"/>
<limit effort="1" velocity="20" />
<joint_properties friction="0.0"/>
</joint>

<joint name="d9433598-071a-4b82-afa4-afa2501c5f8f_fixing" type="fixed">
<origin xyz="0 0 0" rpy="0 -0 0" />
<parent link="body_1" />
<child link="lidar_frame_1" />
<axis xyz="0 0 1"/>
<limit effort="1" velocity="20" />
<joint_properties friction="0.0"/>
</joint>


</robot>
