<?xml version="1.0"?>
<robot name="onshape" xmlns:xacro="http://www.ros.org/wiki/xacro">
    <!-- Used for fixing jetbot_soccer to Gazebo 'base_link' -->
    <link name="world" />
    <joint name="world_joint" type="fixed">
      <parent link="world"/>
      <child link="body_1"/>
      <origin xyz="0.0 0.0 0.0" rpy="0.0 0.0 0.0" />
    </joint>

	<link name="body_1">
		<collision>
			<origin xyz="-0.527668 -0.248144 -0.28112" rpy="-5.12956e-06 9.95073e-08 -1.534" />
			<geometry>
				<mesh filename="file://$(find jetbot_description)/urdf/jetbot_soccer/solenoid_body.stl"/>
			</geometry>
			<material name="solenoid_body_material">
				<color rgba="0.647059 0.647059 0.647059 1.0"/>
			</material>
		</collision>
		<collision>
			<origin xyz="-0.323564 -0.262737 -0.103045" rpy="-1.5708 -9.70802e-08 -3.11644" />
			<geometry>
				<mesh filename="file://$(find jetbot_description)/urdf/jetbot_soccer/motor.stl"/>
			</geometry>
			<material name="motor_material">
				<color rgba="0.768627 0.886275 0.952941 1.0"/>
			</material>
		</collision>
		<collision>
			<origin xyz="-0.287534 -0.270327 -0.118627" rpy="3.14159 3.81895e-08 -2.05776" />
			<geometry>
				<mesh filename="file://$(find jetbot_description)/urdf/jetbot_soccer/body_1.stl"/>
			</geometry>
			<material name="body_1_material">
				<color rgba="0.615686 0.811765 0.929412 1.0"/>
			</material>
		</collision>
		<collision>
			<origin xyz="-0.363649 -0.112549 -0.0808432" rpy="3.14159 9.72302e-08 -1.55745" />
			<geometry>
				<mesh filename="file://$(find jetbot_description)/urdf/jetbot_soccer/m3_l30mm.stl"/>
			</geometry>
			<material name="m3_l30mm_material">
				<color rgba="0 0 0 1.0"/>
			</material>
		</collision>
		<collision>
			<origin xyz="0.0751363 -0.217473 -0.0810866" rpy="3.14159 9.83834e-08 -1.54564" />
			<geometry>
				<mesh filename="file://$(find jetbot_description)/urdf/jetbot_soccer/part_14.stl"/>
			</geometry>
			<material name="part_14_material">
				<color rgba="0.615686 0.811765 0.929412 1.0"/>
			</material>
		</collision>
		<collision>
			<origin xyz="-0.0696374 -0.358936 -0.145101" rpy="-3.14159 -3.90241e-08 1.09012" />
			<geometry>
				<mesh filename="file://$(find jetbot_description)/urdf/jetbot_soccer/prt0002_1.stl"/>
			</geometry>
			<material name="prt0002_1_material">
				<color rgba="0.615686 0.811765 0.929412 1.0"/>
			</material>
		</collision>
		<collision>
			<origin xyz="-0.15576 -0.310534 -0.151139" rpy="-9.59279e-08 9.95073e-08 -1.534" />
			<geometry>
				<mesh filename="file://$(find jetbot_description)/urdf/jetbot_soccer/solenoid_case_1.stl"/>
			</geometry>
			<material name="solenoid_case_1_material">
				<color rgba="0.917647 0.917647 0.917647 1.0"/>
			</material>
		</collision>
		<collision>
			<origin xyz="-0.177112 -0.286403 -0.118627" rpy="3.14159 -1.32836e-07 2.65463" />
			<geometry>
				<mesh filename="file://$(find jetbot_description)/urdf/jetbot_soccer/m3_l35mm.stl"/>
			</geometry>
			<material name="m3_l35mm_material">
				<color rgba="0 0 0 1.0"/>
			</material>
		</collision>
		<collision>
			<origin xyz="-0.0660393 -0.360371 -0.145101" rpy="-3.14159 -3.81895e-08 1.08383" />
			<geometry>
				<mesh filename="file://$(find jetbot_description)/urdf/jetbot_soccer/prt0007_3.stl"/>
			</geometry>
			<material name="prt0007_3_material">
				<color rgba="0.498039 0.498039 0.498039 1.0"/>
			</material>
		</collision>
		<collision>
			<origin xyz="-0.251755 -0.0467974 -0.0810866" rpy="3.14159 9.72302e-08 -1.55745" />
			<geometry>
				<mesh filename="file://$(find jetbot_description)/urdf/jetbot_soccer/m3_l30mm.stl"/>
			</geometry>
			<material name="m3_l30mm_material">
				<color rgba="0 0 0 1.0"/>
			</material>
		</collision>
		<collision>
			<origin xyz="-0.326683 -0.0473719 -0.0810866" rpy="3.14159 9.72302e-08 -1.55745" />
			<geometry>
				<mesh filename="file://$(find jetbot_description)/urdf/jetbot_soccer/m3_l30mm.stl"/>
			</geometry>
			<material name="m3_l30mm_material">
				<color rgba="0 0 0 1.0"/>
			</material>
		</collision>
		<collision>
			<origin xyz="-0.175298 -0.0198846 -0.0485466" rpy="3.14159 9.72302e-08 -1.55745" />
			<geometry>
				<mesh filename="file://$(find jetbot_description)/urdf/jetbot_soccer/body_3.stl"/>
			</geometry>
			<material name="body_3_material">
				<color rgba="0.917647 0.917647 0.917647 1.0"/>
			</material>
		</collision>
		<collision>
			<origin xyz="-0.187792 -0.502048 -0.121167" rpy="-3.14159 3.3345e-08 0.56023" />
			<geometry>
				<mesh filename="file://$(find jetbot_description)/urdf/jetbot_soccer/suspention.stl"/>
			</geometry>
			<material name="suspention_material">
				<color rgba="0.647059 0.647059 0.647059 1.0"/>
			</material>
		</collision>
		<collision>
			<origin xyz="-0.0624155 -0.347134 -0.118627" rpy="3.14159 -1.32836e-07 2.65463" />
			<geometry>
				<mesh filename="file://$(find jetbot_description)/urdf/jetbot_soccer/m3_l35mm.stl"/>
			</geometry>
			<material name="m3_l35mm_material">
				<color rgba="0 0 0 1.0"/>
			</material>
		</collision>
		<collision>
			<origin xyz="-0.213794 -0.1114 -0.0810866" rpy="3.14159 9.72302e-08 -1.55745" />
			<geometry>
				<mesh filename="file://$(find jetbot_description)/urdf/jetbot_soccer/m3_l30mm.stl"/>
			</geometry>
			<material name="m3_l30mm_material">
				<color rgba="0 0 0 1.0"/>
			</material>
		</collision>
		<collision>
			<origin xyz="-0.0698326 -0.36041 -0.145101" rpy="-3.14159 -3.81895e-08 1.08383" />
			<geometry>
				<mesh filename="file://$(find jetbot_description)/urdf/jetbot_soccer/prt0001_2.stl"/>
			</geometry>
			<material name="prt0001_2_material">
				<color rgba="0.917647 0.917647 0.917647 1.0"/>
			</material>
		</collision>
		<collision>
			<origin xyz="-0.359219 -0.181162 -0.0810866" rpy="3.14159 1.15683e-07 -1.34599" />
			<geometry>
				<mesh filename="file://$(find jetbot_description)/urdf/jetbot_soccer/m3_l30mm.stl"/>
			</geometry>
			<material name="m3_l30mm_material">
				<color rgba="0 0 0 1.0"/>
			</material>
		</collision>
		<collision>
			<origin xyz="-0.0323069 -0.118892 -0.121167" rpy="3.14159 -1.32836e-07 2.65463" />
			<geometry>
				<mesh filename="file://$(find jetbot_description)/urdf/jetbot_soccer/suspention.stl"/>
			</geometry>
			<material name="suspention_material">
				<color rgba="0.647059 0.647059 0.647059 1.0"/>
			</material>
		</collision>
		<collision>
			<origin xyz="-0.284434 -0.563543 -0.121167" rpy="-3.14159 3.25007e-08 0.56652" />
			<geometry>
				<mesh filename="file://$(find jetbot_description)/urdf/jetbot_soccer/suspention.stl"/>
			</geometry>
			<material name="suspention_material">
				<color rgba="0.647059 0.647059 0.647059 1.0"/>
			</material>
		</collision>
		<collision>
			<origin xyz="-0.472997 -0.326162 -0.121167" rpy="3.14159 9.95073e-08 -1.534" />
			<geometry>
				<mesh filename="file://$(find jetbot_description)/urdf/jetbot_soccer/solenoid_case_2.stl"/>
			</geometry>
			<material name="solenoid_case_2_material">
				<color rgba="0.768627 0.886275 0.952941 1.0"/>
			</material>
		</collision>
		<collision>
			<origin xyz="0.092678 -0.21303 -0.0810866" rpy="3.14159 9.83834e-08 -1.54564" />
			<geometry>
				<mesh filename="file://$(find jetbot_description)/urdf/jetbot_soccer/part_15.stl"/>
			</geometry>
			<material name="part_15_material">
				<color rgba="0.647059 0.647059 0.647059 1.0"/>
			</material>
		</collision>
		<collision>
			<origin xyz="-0.212175 -0.352622 -0.118627" rpy="3.14159 -1.32836e-07 2.65463" />
			<geometry>
				<mesh filename="file://$(find jetbot_description)/urdf/jetbot_soccer/m3_l35mm.stl"/>
			</geometry>
			<material name="m3_l35mm_material">
				<color rgba="0 0 0 1.0"/>
			</material>
		</collision>
		<collision>
			<origin xyz="-0.0688884 -0.258153 -0.0810866" rpy="3.14159 9.83834e-08 -1.54564" />
			<geometry>
				<mesh filename="file://$(find jetbot_description)/urdf/jetbot_soccer/body_2.stl"/>
			</geometry>
			<material name="body_2_material">
				<color rgba="0.647059 0.647059 0.647059 1.0"/>
			</material>
		</collision>
		<collision>
			<origin xyz="-0.540905 -0.418258 -0.121167" rpy="-3.14159 1.32836e-07 -0.486967" />
			<geometry>
				<mesh filename="file://$(find jetbot_description)/urdf/jetbot_soccer/suspention.stl"/>
			</geometry>
			<material name="suspention_material">
				<color rgba="0.647059 0.647059 0.647059 1.0"/>
			</material>
		</collision>
		<collision>
			<origin xyz="-0.32294 -0.287529 -0.103045" rpy="-1.5708 -9.70802e-08 -3.11644" />
			<geometry>
				<mesh filename="file://$(find jetbot_description)/urdf/jetbot_soccer/gearbox.stl"/>
			</geometry>
			<material name="gearbox_material">
				<color rgba="0.231373 0.380392 0.705882 1.0"/>
			</material>
		</collision>
		<collision>
			<origin xyz="-0.25076 -0.176576 -0.0810866" rpy="3.14159 9.72302e-08 -1.55745" />
			<geometry>
				<mesh filename="file://$(find jetbot_description)/urdf/jetbot_soccer/m3_l30mm.stl"/>
			</geometry>
			<material name="m3_l30mm_material">
				<color rgba="0 0 0 1.0"/>
			</material>
		</collision>
		<collision>
			<origin xyz="-0.0660393 -0.360371 -0.145101" rpy="-3.14159 -3.81895e-08 1.08383" />
			<geometry>
				<mesh filename="file://$(find jetbot_description)/urdf/jetbot_soccer/prt0007.stl"/>
			</geometry>
			<material name="prt0007_material">
				<color rgba="0.972549 0.529412 0.00392157 1.0"/>
			</material>
		</collision>
		<collision>
			<origin xyz="-0.102232 -0.283658 -0.118627" rpy="3.14159 -1.32836e-07 2.65463" />
			<geometry>
				<mesh filename="file://$(find jetbot_description)/urdf/jetbot_soccer/m3_l35mm.stl"/>
			</geometry>
			<material name="m3_l35mm_material">
				<color rgba="0 0 0 1.0"/>
			</material>
		</collision>
		<visual>
			<origin xyz="0 0 0" rpy="0 -0 0" />
			<geometry>
				<mesh filename="file://$(find jetbot_description)/urdf/jetbot_soccer/body_1.stl"/>
			</geometry>
			<material name="body_1_material">
				<color rgba="0.694351 0.700607 0.692106 1.0"/>
			</material>
		</visual>
		<inertial>
			<origin xyz="-0.288406 -0.268011 -0.121718" rpy="0 0 0"/>
			<mass value="0.793815" />
			<inertia ixx="0.00152165" ixy="-4.72314e-05"  ixz="2.02257e-05" iyy="0.00182701" iyz="5.60563e-05" izz="0.0018822" />
		</inertial>
	</link>
	<link name="roller_1">
		<collision>
			<origin xyz="-0.010626 0.128506 -0.0653485" rpy="-1.95836e-16 -1.52306e-16 3.34047e-16" />
			<geometry>
				<mesh filename="file://$(find jetbot_description)/urdf/jetbot_soccer/roller_core.stl"/>
			</geometry>
			<material name="roller_core_material">
				<color rgba="0.972549 0.529412 0.00392157 1.0"/>
			</material>
		</collision>
		<collision>
			<origin xyz="-0.0106197 0.0432059 -0.0646269" rpy="-4.83846e-17 -4.08122e-17 7.88239e-16" />
			<geometry>
				<mesh filename="file://$(find jetbot_description)/urdf/jetbot_soccer/roller.stl"/>
			</geometry>
			<material name="roller_material">
				<color rgba="0.768627 0.886275 0.952941 1.0"/>
			</material>
		</collision>
		<collision>
			<origin xyz="5.55112e-17 5.55112e-17 0" rpy="-2.92316e-20 6.97285e-23 -2.38597e-18" />
			<geometry>
				<mesh filename="file://$(find jetbot_description)/urdf/jetbot_soccer/output_shaft.stl"/>
			</geometry>
			<material name="output_shaft_material">
				<color rgba="0.917647 0.917647 0.917647 1.0"/>
			</material>
		</collision>
		<visual>
			<origin xyz="0 0 0" rpy="0 -0 0" />
			<geometry>
				<mesh filename="file://$(find jetbot_description)/urdf/jetbot_soccer/roller_1.stl"/>
			</geometry>
			<material name="roller_1_material">
				<color rgba="0.805152 0.828341 0.796446 1.0"/>
			</material>
		</visual>
		<inertial>
			<origin xyz="-0.0348369 -8.01773e-05 -6.96608e-18" rpy="0 0 0"/>
			<mass value="0.0499297" />
			<inertia ixx="5.72787e-06" ixy="-2.57499e-09"  ixz="-3.25434e-21" iyy="1.43276e-05" iyz="2.34158e-20" izz="1.43282e-05" />
		</inertial>
	</link>
	<joint name="roller" type="revolute">
		<origin xyz="-0.322298 -0.313021 -0.103045" rpy="-3.14056 -9.70802e-08 -3.11644" />
		<parent link="body_1" />
		<child link="roller_1" />
		<axis xyz="-1 0 0"/>
		<limit lower="-0.02" upper="0.10" effort="100" velocity="20" />
		<joint_properties friction="0.0"/>
	</joint>
	<link name="horn4_1">
		<collision>
			<origin xyz="1.38778e-17 1.11022e-16 0.0012" rpy="-4.63089e-17 1.26657e-18 -5.85746e-18" />
			<geometry>
				<mesh filename="file://$(find jetbot_description)/urdf/jetbot_soccer/mx-12w_horn.stl"/>
			</geometry>
			<material name="mx-12w_horn_material">
				<color rgba="0.980392 0.713725 0.00392157 1.0"/>
			</material>
		</collision>
		<collision>
			<origin xyz="0.171498 0.217932 0.00431" rpy="-3.14159 -4.58463e-14 3.14159" />
			<geometry>
				<mesh filename="file://$(find jetbot_description)/urdf/jetbot_soccer/horn.stl"/>
			</geometry>
			<material name="horn_material">
				<color rgba="0.231373 0.380392 0.705882 1.0"/>
			</material>
		</collision>
		<collision>
			<origin xyz="0.0678046 0.04517 0.0423198" rpy="2.07014e-14 3.21742e-16 1.5708" />
			<geometry>
				<mesh filename="file://$(find jetbot_description)/urdf/jetbot_soccer/main_frame.stl"/>
			</geometry>
			<material name="main_frame_material">
				<color rgba="0.980392 0.713725 0.00392157 1.0"/>
			</material>
		</collision>
		<visual>
			<origin xyz="0 0 0" rpy="0 -0 0" />
			<geometry>
				<mesh filename="file://$(find jetbot_description)/urdf/jetbot_soccer/horn4_1.stl"/>
			</geometry>
			<material name="horn4_1_material">
				<color rgba="0.937052 0.694438 0.0445389 1.0"/>
			</material>
		</visual>
		<inertial>
			<origin xyz="-9.44942e-07 -1.4867e-07 0.012158" rpy="0 0 0"/>
			<mass value="0.0125567" />
			<inertia ixx="1.27588e-06" ixy="1.42523e-11"  ixz="-1.50868e-10" iyy="1.27557e-06" iyz="-4.04238e-12" izz="1.48771e-06" />
		</inertial>
	</link>
	<link name="wheel2_sub2_1">
		<collision>
			<origin xyz="0.0534199 -0.0535157 0.032114" rpy="-1.69557e-17 4.97211e-18 1.44232e-18" />
			<geometry>
				<mesh filename="file://$(find jetbot_description)/urdf/jetbot_soccer/sub_wheel.stl"/>
			</geometry>
			<material name="sub_wheel_material">
				<color rgba="0.768627 0.886275 0.952941 1.0"/>
			</material>
		</collision>
		<visual>
			<origin xyz="0 0 0" rpy="0 -0 0" />
			<geometry>
				<mesh filename="file://$(find jetbot_description)/urdf/jetbot_soccer/wheel2_sub2_1.stl"/>
			</geometry>
			<material name="wheel2_sub2_1_material">
				<color rgba="0.768627 0.886275 0.952941 1.0"/>
			</material>
		</visual>
		<inertial>
			<origin xyz="3.67355e-05 -2.09868e-05 5.31199e-07" rpy="0 0 0"/>
			<mass value="9.9564e-05" />
			<inertia ixx="9.26988e-10" ixy="4.8503e-10"  ixz="2.09591e-13" iyy="1.48655e-09" iyz="-2.62533e-14" izz="1.76782e-09" />
		</inertial>
	</link>
	<joint name="wheel2_sub1" type="revolute">
		<origin xyz="-0.00825 0.0142894 0.0189056" rpy="-3.14159 7.95939e-09 -3.14159" />
		<parent link="horn4_1" />
		<child link="wheel2_sub2_1" />
		<axis xyz="-0.866025 0.5 0"/>
		<limit lower="-0.02" upper="0.10" effort="100" velocity="20" />
		<joint_properties friction="0.0"/>
	</joint>
	<link name="wheel2_sub7_1">
		<collision>
			<origin xyz="0.0534199 -0.0535157 0.032114" rpy="1.01053e-16 3.61299e-19 -5.55757e-18" />
			<geometry>
				<mesh filename="file://$(find jetbot_description)/urdf/jetbot_soccer/sub_wheel.stl"/>
			</geometry>
			<material name="sub_wheel_material">
				<color rgba="0.768627 0.886275 0.952941 1.0"/>
			</material>
		</collision>
		<visual>
			<origin xyz="0 0 0" rpy="0 -0 0" />
			<geometry>
				<mesh filename="file://$(find jetbot_description)/urdf/jetbot_soccer/wheel2_sub7_1.stl"/>
			</geometry>
			<material name="wheel2_sub7_1_material">
				<color rgba="0.768627 0.886275 0.952941 1.0"/>
			</material>
		</visual>
		<inertial>
			<origin xyz="3.67355e-05 -2.09868e-05 5.31199e-07" rpy="0 0 0"/>
			<mass value="9.9564e-05" />
			<inertia ixx="9.26988e-10" ixy="4.8503e-10"  ixz="2.09591e-13" iyy="1.48655e-09" iyz="-2.62533e-14" izz="1.76782e-09" />
		</inertial>
	</link>
	<joint name="wheel2_sub2" type="revolute">
		<origin xyz="0.00825 0.0142894 0.0189056" rpy="8.65297e-09 -4.99578e-09 1.8586e-12" />
		<parent link="horn4_1" />
		<child link="wheel2_sub7_1" />
		<axis xyz="-0.866025 0.5 0"/>
		<limit lower="-0.02" upper="0.10" effort="100" velocity="20" />
		<joint_properties friction="0.0"/>
	</joint>
	<link name="wheel2_sub3_1">
		<collision>
			<origin xyz="0.0534199 -0.0535157 0.032114" rpy="4.78359e-18 -8.79089e-18 7.77206e-19" />
			<geometry>
				<mesh filename="file://$(find jetbot_description)/urdf/jetbot_soccer/sub_wheel.stl"/>
			</geometry>
			<material name="sub_wheel_material">
				<color rgba="0.768627 0.886275 0.952941 1.0"/>
			</material>
		</collision>
		<visual>
			<origin xyz="0 0 0" rpy="0 -0 0" />
			<geometry>
				<mesh filename="file://$(find jetbot_description)/urdf/jetbot_soccer/wheel2_sub3_1.stl"/>
			</geometry>
			<material name="wheel2_sub3_1_material">
				<color rgba="0.768627 0.886275 0.952941 1.0"/>
			</material>
		</visual>
		<inertial>
			<origin xyz="3.67355e-05 -2.09868e-05 5.31199e-07" rpy="0 0 0"/>
			<mass value="9.9564e-05" />
			<inertia ixx="9.26988e-10" ixy="4.8503e-10"  ixz="2.09591e-13" iyy="1.48655e-09" iyz="-2.62533e-14" izz="1.76782e-09" />
		</inertial>
	</link>
	<joint name="wheel2_sub3" type="revolute">
		<origin xyz="0.0165 2.22045e-16 0.0189056" rpy="1.5708 -0.523599 -1.5708" />
		<parent link="horn4_1" />
		<child link="wheel2_sub3_1" />
		<axis xyz="-0.866025 0.5 0"/>
		<limit lower="-0.02" upper="0.10" effort="100" velocity="20" />
		<joint_properties friction="0.0"/>
	</joint>
	<link name="wheel2_sub9_1">
		<collision>
			<origin xyz="0.0534199 -0.0535157 0.032114" rpy="-2.20988e-17 7.25516e-18 -7.82545e-18" />
			<geometry>
				<mesh filename="file://$(find jetbot_description)/urdf/jetbot_soccer/sub_wheel.stl"/>
			</geometry>
			<material name="sub_wheel_material">
				<color rgba="0.768627 0.886275 0.952941 1.0"/>
			</material>
		</collision>
		<visual>
			<origin xyz="0 0 0" rpy="0 -0 0" />
			<geometry>
				<mesh filename="file://$(find jetbot_description)/urdf/jetbot_soccer/wheel2_sub9_1.stl"/>
			</geometry>
			<material name="wheel2_sub9_1_material">
				<color rgba="0.768627 0.886275 0.952941 1.0"/>
			</material>
		</visual>
		<inertial>
			<origin xyz="3.67355e-05 -2.09868e-05 5.31199e-07" rpy="0 0 0"/>
			<mass value="9.9564e-05" />
			<inertia ixx="9.26988e-10" ixy="4.8503e-10"  ixz="2.09591e-13" iyy="1.48655e-09" iyz="-2.62533e-14" izz="1.76782e-09" />
		</inertial>
	</link>
	<joint name="wheel2_sub4" type="revolute">
		<origin xyz="0.00825 -0.0142894 0.0189056" rpy="-3.14159 7.95939e-09 3.14159" />
		<parent link="horn4_1" />
		<child link="wheel2_sub9_1" />
		<axis xyz="-0.866025 0.5 0"/>
		<limit lower="-0.02" upper="0.10" effort="100" velocity="20" />
		<joint_properties friction="0.0"/>
	</joint>
	<link name="wheel2_sub5_1">
		<collision>
			<origin xyz="0.0534199 -0.0535157 0.032114" rpy="4.78154e-17 -3.21276e-18 -7.9342e-18" />
			<geometry>
				<mesh filename="file://$(find jetbot_description)/urdf/jetbot_soccer/sub_wheel.stl"/>
			</geometry>
			<material name="sub_wheel_material">
				<color rgba="0.768627 0.886275 0.952941 1.0"/>
			</material>
		</collision>
		<visual>
			<origin xyz="0 0 0" rpy="0 -0 0" />
			<geometry>
				<mesh filename="file://$(find jetbot_description)/urdf/jetbot_soccer/wheel2_sub5_1.stl"/>
			</geometry>
			<material name="wheel2_sub5_1_material">
				<color rgba="0.768627 0.886275 0.952941 1.0"/>
			</material>
		</visual>
		<inertial>
			<origin xyz="3.67355e-05 -2.09868e-05 5.31199e-07" rpy="0 0 0"/>
			<mass value="9.9564e-05" />
			<inertia ixx="9.26988e-10" ixy="4.8503e-10"  ixz="2.09591e-13" iyy="1.48655e-09" iyz="-2.62533e-14" izz="1.76782e-09" />
		</inertial>
	</link>
	<joint name="wheel2_sub5" type="revolute">
		<origin xyz="-0.00825 -0.0142894 0.0189056" rpy="8.65297e-09 -4.99578e-09 4.49181e-12" />
		<parent link="horn4_1" />
		<child link="wheel2_sub5_1" />
		<axis xyz="-0.866025 0.5 0"/>
		<limit lower="-0.02" upper="0.10" effort="100" velocity="20" />
		<joint_properties friction="0.0"/>
	</joint>
	<link name="wheel2_sub4_1">
		<collision>
			<origin xyz="0.0534199 -0.0535157 0.032114" rpy="4.78359e-18 -8.79089e-18 7.77206e-19" />
			<geometry>
				<mesh filename="file://$(find jetbot_description)/urdf/jetbot_soccer/sub_wheel.stl"/>
			</geometry>
			<material name="sub_wheel_material">
				<color rgba="0.768627 0.886275 0.952941 1.0"/>
			</material>
		</collision>
		<visual>
			<origin xyz="0 0 0" rpy="0 -0 0" />
			<geometry>
				<mesh filename="file://$(find jetbot_description)/urdf/jetbot_soccer/wheel2_sub4_1.stl"/>
			</geometry>
			<material name="wheel2_sub4_1_material">
				<color rgba="0.768627 0.886275 0.952941 1.0"/>
			</material>
		</visual>
		<inertial>
			<origin xyz="3.67355e-05 -2.09868e-05 5.31199e-07" rpy="0 0 0"/>
			<mass value="9.9564e-05" />
			<inertia ixx="9.26988e-10" ixy="4.8503e-10"  ixz="2.09591e-13" iyy="1.48655e-09" iyz="-2.62533e-14" izz="1.76782e-09" />
		</inertial>
	</link>
	<joint name="wheel2_sub6" type="revolute">
		<origin xyz="-0.0165 0 0.0189056" rpy="1.5708 -0.523599 -1.5708" />
		<parent link="horn4_1" />
		<child link="wheel2_sub4_1" />
		<axis xyz="-0.866025 0.5 0"/>
		<limit lower="-0.02" upper="0.10" effort="100" velocity="20" />
		<joint_properties friction="0.0"/>
	</joint>
	<link name="wheel2_sub1_1">
		<collision>
			<origin xyz="0.0534199 -0.0535157 0.032114" rpy="3.0074e-17 -2.16757e-17 1.21311e-17" />
			<geometry>
				<mesh filename="file://$(find jetbot_description)/urdf/jetbot_soccer/sub_wheel.stl"/>
			</geometry>
			<material name="sub_wheel_material">
				<color rgba="0.768627 0.886275 0.952941 1.0"/>
			</material>
		</collision>
		<visual>
			<origin xyz="0 0 0" rpy="0 -0 0" />
			<geometry>
				<mesh filename="file://$(find jetbot_description)/urdf/jetbot_soccer/wheel2_sub1_1.stl"/>
			</geometry>
			<material name="wheel2_sub1_1_material">
				<color rgba="0.768627 0.886275 0.952941 1.0"/>
			</material>
		</visual>
		<inertial>
			<origin xyz="3.67355e-05 -2.09868e-05 5.31199e-07" rpy="0 0 0"/>
			<mass value="9.9564e-05" />
			<inertia ixx="9.26988e-10" ixy="4.8503e-10"  ixz="2.09591e-13" iyy="1.48655e-09" iyz="-2.62533e-14" izz="1.76782e-09" />
		</inertial>
	</link>
	<joint name="wheel2_sub7" type="revolute">
		<origin xyz="3.19189e-16 -0.0165 0.0102056" rpy="-3.14159 1.71102e-09 2.61799" />
		<parent link="horn4_1" />
		<child link="wheel2_sub1_1" />
		<axis xyz="-0.866025 0.5 0"/>
		<limit lower="-0.02" upper="0.10" effort="100" velocity="20" />
		<joint_properties friction="0.0"/>
	</joint>
	<link name="wheel2_sub8_1">
		<collision>
			<origin xyz="0.0534199 -0.0535157 0.032114" rpy="-7.15197e-18 -6.27321e-17 -7.98054e-18" />
			<geometry>
				<mesh filename="file://$(find jetbot_description)/urdf/jetbot_soccer/sub_wheel.stl"/>
			</geometry>
			<material name="sub_wheel_material">
				<color rgba="0.768627 0.886275 0.952941 1.0"/>
			</material>
		</collision>
		<visual>
			<origin xyz="0 0 0" rpy="0 -0 0" />
			<geometry>
				<mesh filename="file://$(find jetbot_description)/urdf/jetbot_soccer/wheel2_sub8_1.stl"/>
			</geometry>
			<material name="wheel2_sub8_1_material">
				<color rgba="0.768627 0.886275 0.952941 1.0"/>
			</material>
		</visual>
		<inertial>
			<origin xyz="3.67355e-05 -2.09868e-05 5.31199e-07" rpy="0 0 0"/>
			<mass value="9.9564e-05" />
			<inertia ixx="9.26988e-10" ixy="4.8503e-10"  ixz="2.09591e-13" iyy="1.48655e-09" iyz="-2.62533e-14" izz="1.76782e-09" />
		</inertial>
	</link>
	<joint name="wheel2_sub8" type="revolute">
		<origin xyz="0.0142894 -0.00825 0.0102056" rpy="1.5708 -0.523599 -2.0944" />
		<parent link="horn4_1" />
		<child link="wheel2_sub8_1" />
		<axis xyz="-0.866025 0.5 0"/>
		<limit lower="-0.02" upper="0.10" effort="100" velocity="20" />
		<joint_properties friction="0.0"/>
	</joint>
	<link name="wheel2_sub10_1">
		<collision>
			<origin xyz="0.0534199 -0.0535157 0.032114" rpy="1.58513e-17 -3.81923e-17 1.25725e-17" />
			<geometry>
				<mesh filename="file://$(find jetbot_description)/urdf/jetbot_soccer/sub_wheel.stl"/>
			</geometry>
			<material name="sub_wheel_material">
				<color rgba="0.768627 0.886275 0.952941 1.0"/>
			</material>
		</collision>
		<visual>
			<origin xyz="0 0 0" rpy="0 -0 0" />
			<geometry>
				<mesh filename="file://$(find jetbot_description)/urdf/jetbot_soccer/wheel2_sub10_1.stl"/>
			</geometry>
			<material name="wheel2_sub10_1_material">
				<color rgba="0.768627 0.886275 0.952941 1.0"/>
			</material>
		</visual>
		<inertial>
			<origin xyz="3.67355e-05 -2.09868e-05 5.31199e-07" rpy="0 0 0"/>
			<mass value="9.9564e-05" />
			<inertia ixx="9.26988e-10" ixy="4.8503e-10"  ixz="2.09591e-13" iyy="1.48655e-09" iyz="-2.62533e-14" izz="1.76782e-09" />
		</inertial>
	</link>
	<joint name="wheel2_sub9" type="revolute">
		<origin xyz="0.0142894 0.00825 0.0102056" rpy="1.5708 -0.523599 -1.0472" />
		<parent link="horn4_1" />
		<child link="wheel2_sub10_1" />
		<axis xyz="-0.866025 0.5 0"/>
		<limit lower="-0.02" upper="0.10" effort="100" velocity="20" />
		<joint_properties friction="0.0"/>
	</joint>
	<link name="wheel2_sub12_1">
		<collision>
			<origin xyz="0.0534199 -0.0535157 0.032114" rpy="-2.2267e-18 4.8509e-17 1.51445e-17" />
			<geometry>
				<mesh filename="file://$(find jetbot_description)/urdf/jetbot_soccer/sub_wheel.stl"/>
			</geometry>
			<material name="sub_wheel_material">
				<color rgba="0.768627 0.886275 0.952941 1.0"/>
			</material>
		</collision>
		<visual>
			<origin xyz="0 0 0" rpy="0 -0 0" />
			<geometry>
				<mesh filename="file://$(find jetbot_description)/urdf/jetbot_soccer/wheel2_sub12_1.stl"/>
			</geometry>
			<material name="wheel2_sub12_1_material">
				<color rgba="0.768627 0.886275 0.952941 1.0"/>
			</material>
		</visual>
		<inertial>
			<origin xyz="3.67355e-05 -2.09868e-05 5.31199e-07" rpy="0 0 0"/>
			<mass value="9.9564e-05" />
			<inertia ixx="9.26988e-10" ixy="4.8503e-10"  ixz="2.09591e-13" iyy="1.48655e-09" iyz="-2.62533e-14" izz="1.76782e-09" />
		</inertial>
	</link>
	<joint name="wheel2_sub10" type="revolute">
		<origin xyz="-0.0142894 0.00825 0.0102056" rpy="1.5708 -0.523599 -2.0944" />
		<parent link="horn4_1" />
		<child link="wheel2_sub12_1" />
		<axis xyz="-0.866025 0.5 0"/>
		<limit lower="-0.02" upper="0.10" effort="100" velocity="20" />
		<joint_properties friction="0.0"/>
	</joint>
	<link name="wheel2_sub6_1">
		<collision>
			<origin xyz="0.0534199 -0.0535157 0.032114" rpy="-2.76205e-17 8.0487e-18 -1.80541e-17" />
			<geometry>
				<mesh filename="file://$(find jetbot_description)/urdf/jetbot_soccer/sub_wheel.stl"/>
			</geometry>
			<material name="sub_wheel_material">
				<color rgba="0.768627 0.886275 0.952941 1.0"/>
			</material>
		</collision>
		<visual>
			<origin xyz="0 0 0" rpy="0 -0 0" />
			<geometry>
				<mesh filename="file://$(find jetbot_description)/urdf/jetbot_soccer/wheel2_sub6_1.stl"/>
			</geometry>
			<material name="wheel2_sub6_1_material">
				<color rgba="0.768627 0.886275 0.952941 1.0"/>
			</material>
		</visual>
		<inertial>
			<origin xyz="3.67355e-05 -2.09868e-05 5.31199e-07" rpy="0 0 0"/>
			<mass value="9.9564e-05" />
			<inertia ixx="9.26988e-10" ixy="4.8503e-10"  ixz="2.09591e-13" iyy="1.48655e-09" iyz="-2.62533e-14" izz="1.76782e-09" />
		</inertial>
	</link>
	<joint name="wheel2_sub11" type="revolute">
		<origin xyz="-0.0142894 -0.00825 0.0102056" rpy="1.5708 -0.523599 -1.0472" />
		<parent link="horn4_1" />
		<child link="wheel2_sub6_1" />
		<axis xyz="-0.866025 0.5 0"/>
		<limit lower="-0.02" upper="0.10" effort="100" velocity="20" />
		<joint_properties friction="0.0"/>
	</joint>
	<link name="wheel2_sub11_1">
		<collision>
			<origin xyz="0.0534199 -0.0535157 0.032114" rpy="-4.48617e-17 1.22849e-17 2.79806e-18" />
			<geometry>
				<mesh filename="file://$(find jetbot_description)/urdf/jetbot_soccer/sub_wheel.stl"/>
			</geometry>
			<material name="sub_wheel_material">
				<color rgba="0.768627 0.886275 0.952941 1.0"/>
			</material>
		</collision>
		<visual>
			<origin xyz="0 0 0" rpy="0 -0 0" />
			<geometry>
				<mesh filename="file://$(find jetbot_description)/urdf/jetbot_soccer/wheel2_sub11_1.stl"/>
			</geometry>
			<material name="wheel2_sub11_1_material">
				<color rgba="0.768627 0.886275 0.952941 1.0"/>
			</material>
		</visual>
		<inertial>
			<origin xyz="3.67355e-05 -2.09868e-05 5.31199e-07" rpy="0 0 0"/>
			<mass value="9.9564e-05" />
			<inertia ixx="9.26988e-10" ixy="4.8503e-10"  ixz="2.09591e-13" iyy="1.48655e-09" iyz="-2.62533e-14" izz="1.76782e-09" />
		</inertial>
	</link>
	<joint name="wheel2_sub12" type="revolute">
		<origin xyz="-2.498e-16 0.0165 0.0102056" rpy="-3.14159 1.71103e-09 2.61799" />
		<parent link="horn4_1" />
		<child link="wheel2_sub11_1" />
		<axis xyz="-0.866025 0.5 0"/>
		<limit lower="-0.02" upper="0.10" effort="100" velocity="20" />
		<joint_properties friction="0.0"/>
	</joint>
	<joint name="wheel4" type="revolute">
		<origin xyz="-0.228004 -0.320164 -0.143861" rpy="1.5708 1.43948 1.08383" />
		<parent link="body_1" />
		<child link="horn4_1" />
		<axis xyz="0 0 -1"/>
		<limit lower="-0.02" upper="0.10" effort="100" velocity="20" />
		<joint_properties friction="0.0"/>
	</joint>
	<link name="horn2_1">
		<collision>
			<origin xyz="0.04517 -0.0678046 0.0423198" rpy="1.08808e-14 2.10681e-15 1.40281e-16" />
			<geometry>
				<mesh filename="file://$(find jetbot_description)/urdf/jetbot_soccer/main_frame.stl"/>
			</geometry>
			<material name="main_frame_material">
				<color rgba="0.980392 0.713725 0.00392157 1.0"/>
			</material>
		</collision>
		<collision>
			<origin xyz="0.217932 -0.171498 0.00431" rpy="-3.14159 -1.04733e-14 1.5708" />
			<geometry>
				<mesh filename="file://$(find jetbot_description)/urdf/jetbot_soccer/horn.stl"/>
			</geometry>
			<material name="horn_material">
				<color rgba="0.231373 0.380392 0.705882 1.0"/>
			</material>
		</collision>
		<collision>
			<origin xyz="6.93889e-17 0 0.0012" rpy="1.17038e-19 -9.92348e-17 2.01863e-19" />
			<geometry>
				<mesh filename="file://$(find jetbot_description)/urdf/jetbot_soccer/mx-12w_horn.stl"/>
			</geometry>
			<material name="mx-12w_horn_material">
				<color rgba="0.980392 0.713725 0.00392157 1.0"/>
			</material>
		</collision>
		<visual>
			<origin xyz="0 0 0" rpy="0 -0 0" />
			<geometry>
				<mesh filename="file://$(find jetbot_description)/urdf/jetbot_soccer/horn2_1.stl"/>
			</geometry>
			<material name="horn2_1_material">
				<color rgba="0.937052 0.694438 0.0445389 1.0"/>
			</material>
		</visual>
		<inertial>
			<origin xyz="-1.11491e-06 -2.12888e-08 0.012158" rpy="0 0 0"/>
			<mass value="0.0125567" />
			<inertia ixx="1.27584e-06" ixy="-1.42503e-11"  ixz="-1.22446e-10" iyy="1.27561e-06" iyz="-1.41565e-11" izz="1.48771e-06" />
		</inertial>
	</link>
	<link name="wheel3_sub6_1">
		<collision>
			<origin xyz="0.0534199 -0.0535157 0.032114" rpy="-2.6825e-17 -5.12919e-18 4.47024e-18" />
			<geometry>
				<mesh filename="file://$(find jetbot_description)/urdf/jetbot_soccer/sub_wheel.stl"/>
			</geometry>
			<material name="sub_wheel_material">
				<color rgba="0.768627 0.886275 0.952941 1.0"/>
			</material>
		</collision>
		<visual>
			<origin xyz="0 0 0" rpy="0 -0 0" />
			<geometry>
				<mesh filename="file://$(find jetbot_description)/urdf/jetbot_soccer/wheel3_sub6_1.stl"/>
			</geometry>
			<material name="wheel3_sub6_1_material">
				<color rgba="0.768627 0.886275 0.952941 1.0"/>
			</material>
		</visual>
		<inertial>
			<origin xyz="3.67355e-05 -2.09868e-05 5.31199e-07" rpy="0 0 0"/>
			<mass value="9.9564e-05" />
			<inertia ixx="9.26988e-10" ixy="4.8503e-10"  ixz="2.09591e-13" iyy="1.48655e-09" iyz="-2.62533e-14" izz="1.76782e-09" />
		</inertial>
	</link>
	<joint name="wheel3_sub1" type="revolute">
		<origin xyz="0.0142894 0.00825 0.0189056" rpy="1.5708 -0.523599 2.0944" />
		<parent link="horn2_1" />
		<child link="wheel3_sub6_1" />
		<axis xyz="-0.866025 0.5 0"/>
		<limit lower="-0.02" upper="0.10" effort="100" velocity="20" />
		<joint_properties friction="0.0"/>
	</joint>
	<link name="wheel3_sub2_1">
		<collision>
			<origin xyz="0.0534199 -0.0535157 0.032114" rpy="3.95361e-19 -3.15149e-19 -2.5524e-17" />
			<geometry>
				<mesh filename="file://$(find jetbot_description)/urdf/jetbot_soccer/sub_wheel.stl"/>
			</geometry>
			<material name="sub_wheel_material">
				<color rgba="0.768627 0.886275 0.952941 1.0"/>
			</material>
		</collision>
		<visual>
			<origin xyz="0 0 0" rpy="0 -0 0" />
			<geometry>
				<mesh filename="file://$(find jetbot_description)/urdf/jetbot_soccer/wheel3_sub2_1.stl"/>
			</geometry>
			<material name="wheel3_sub2_1_material">
				<color rgba="0.768627 0.886275 0.952941 1.0"/>
			</material>
		</visual>
		<inertial>
			<origin xyz="3.67355e-05 -2.09868e-05 5.31199e-07" rpy="0 0 0"/>
			<mass value="9.9564e-05" />
			<inertia ixx="9.26988e-10" ixy="4.8503e-10"  ixz="2.09591e-13" iyy="1.48655e-09" iyz="-2.62533e-14" izz="1.76782e-09" />
		</inertial>
	</link>
	<joint name="wheel3_sub2" type="revolute">
		<origin xyz="-1.11022e-16 0.0165 0.0189056" rpy="1.5708 -0.523599 -3.14159" />
		<parent link="horn2_1" />
		<child link="wheel3_sub2_1" />
		<axis xyz="-0.866025 0.5 0"/>
		<limit lower="-0.02" upper="0.10" effort="100" velocity="20" />
		<joint_properties friction="0.0"/>
	</joint>
	<link name="wheel3_sub3_1">
		<collision>
			<origin xyz="0.0534199 -0.0535157 0.032114" rpy="3.37123e-17 -1.02086e-17 -6.54788e-17" />
			<geometry>
				<mesh filename="file://$(find jetbot_description)/urdf/jetbot_soccer/sub_wheel.stl"/>
			</geometry>
			<material name="sub_wheel_material">
				<color rgba="0.768627 0.886275 0.952941 1.0"/>
			</material>
		</collision>
		<visual>
			<origin xyz="0 0 0" rpy="0 -0 0" />
			<geometry>
				<mesh filename="file://$(find jetbot_description)/urdf/jetbot_soccer/wheel3_sub3_1.stl"/>
			</geometry>
			<material name="wheel3_sub3_1_material">
				<color rgba="0.768627 0.886275 0.952941 1.0"/>
			</material>
		</visual>
		<inertial>
			<origin xyz="3.67355e-05 -2.09868e-05 5.31199e-07" rpy="0 0 0"/>
			<mass value="9.9564e-05" />
			<inertia ixx="9.26988e-10" ixy="4.8503e-10"  ixz="2.09591e-13" iyy="1.48655e-09" iyz="-2.62533e-14" izz="1.76782e-09" />
		</inertial>
	</link>
	<joint name="wheel3_sub3" type="revolute">
		<origin xyz="-0.0142894 0.00825 0.0189056" rpy="1.5708 -0.523599 -2.0944" />
		<parent link="horn2_1" />
		<child link="wheel3_sub3_1" />
		<axis xyz="-0.866025 0.5 0"/>
		<limit lower="-0.02" upper="0.10" effort="100" velocity="20" />
		<joint_properties friction="0.0"/>
	</joint>
	<link name="wheel3_sub1_1">
		<collision>
			<origin xyz="0.0534199 -0.0535157 0.032114" rpy="3.88985e-17 4.45114e-17 8.01063e-18" />
			<geometry>
				<mesh filename="file://$(find jetbot_description)/urdf/jetbot_soccer/sub_wheel.stl"/>
			</geometry>
			<material name="sub_wheel_material">
				<color rgba="0.768627 0.886275 0.952941 1.0"/>
			</material>
		</collision>
		<visual>
			<origin xyz="0 0 0" rpy="0 -0 0" />
			<geometry>
				<mesh filename="file://$(find jetbot_description)/urdf/jetbot_soccer/wheel3_sub1_1.stl"/>
			</geometry>
			<material name="wheel3_sub1_1_material">
				<color rgba="0.768627 0.886275 0.952941 1.0"/>
			</material>
		</visual>
		<inertial>
			<origin xyz="3.67355e-05 -2.09868e-05 5.31199e-07" rpy="0 0 0"/>
			<mass value="9.9564e-05" />
			<inertia ixx="9.26988e-10" ixy="4.8503e-10"  ixz="2.09591e-13" iyy="1.48655e-09" iyz="-2.62533e-14" izz="1.76782e-09" />
		</inertial>
	</link>
	<joint name="wheel3_sub4" type="revolute">
		<origin xyz="-0.0142894 -0.00825 0.0189056" rpy="1.5708 -0.523599 2.0944" />
		<parent link="horn2_1" />
		<child link="wheel3_sub1_1" />
		<axis xyz="-0.866025 0.5 0"/>
		<limit lower="-0.02" upper="0.10" effort="100" velocity="20" />
		<joint_properties friction="0.0"/>
	</joint>
	<link name="wheel3_sub12_1">
		<collision>
			<origin xyz="0.0534199 -0.0535157 0.032114" rpy="-2.02865e-17 -9.82982e-18 -1.85274e-16" />
			<geometry>
				<mesh filename="file://$(find jetbot_description)/urdf/jetbot_soccer/sub_wheel.stl"/>
			</geometry>
			<material name="sub_wheel_material">
				<color rgba="0.768627 0.886275 0.952941 1.0"/>
			</material>
		</collision>
		<visual>
			<origin xyz="0 0 0" rpy="0 -0 0" />
			<geometry>
				<mesh filename="file://$(find jetbot_description)/urdf/jetbot_soccer/wheel3_sub12_1.stl"/>
			</geometry>
			<material name="wheel3_sub12_1_material">
				<color rgba="0.768627 0.886275 0.952941 1.0"/>
			</material>
		</visual>
		<inertial>
			<origin xyz="3.67355e-05 -2.09868e-05 5.31199e-07" rpy="0 0 0"/>
			<mass value="9.9564e-05" />
			<inertia ixx="9.26988e-10" ixy="4.8503e-10"  ixz="2.09591e-13" iyy="1.48655e-09" iyz="-2.62533e-14" izz="1.76782e-09" />
		</inertial>
	</link>
	<joint name="wheel3_sub5" type="revolute">
		<origin xyz="0.0142894 -0.00825 0.0189056" rpy="1.5708 -0.523599 -2.0944" />
		<parent link="horn2_1" />
		<child link="wheel3_sub12_1" />
		<axis xyz="-0.866025 0.5 0"/>
		<limit lower="-0.02" upper="0.10" effort="100" velocity="20" />
		<joint_properties friction="0.0"/>
	</joint>
	<link name="wheel3_sub9_1">
		<collision>
			<origin xyz="0.0534199 -0.0535157 0.032114" rpy="3.95361e-19 -3.15149e-19 -2.5524e-17" />
			<geometry>
				<mesh filename="file://$(find jetbot_description)/urdf/jetbot_soccer/sub_wheel.stl"/>
			</geometry>
			<material name="sub_wheel_material">
				<color rgba="0.768627 0.886275 0.952941 1.0"/>
			</material>
		</collision>
		<visual>
			<origin xyz="0 0 0" rpy="0 -0 0" />
			<geometry>
				<mesh filename="file://$(find jetbot_description)/urdf/jetbot_soccer/wheel3_sub9_1.stl"/>
			</geometry>
			<material name="wheel3_sub9_1_material">
				<color rgba="0.768627 0.886275 0.952941 1.0"/>
			</material>
		</visual>
		<inertial>
			<origin xyz="3.67355e-05 -2.09868e-05 5.31199e-07" rpy="0 0 0"/>
			<mass value="9.9564e-05" />
			<inertia ixx="9.26988e-10" ixy="4.8503e-10"  ixz="2.09591e-13" iyy="1.48655e-09" iyz="-2.62533e-14" izz="1.76782e-09" />
		</inertial>
	</link>
	<joint name="wheel3_sub6" type="revolute">
		<origin xyz="6.93889e-17 -0.0165 0.0189056" rpy="1.5708 -0.523599 -3.14159" />
		<parent link="horn2_1" />
		<child link="wheel3_sub9_1" />
		<axis xyz="-0.866025 0.5 0"/>
		<limit lower="-0.02" upper="0.10" effort="100" velocity="20" />
		<joint_properties friction="0.0"/>
	</joint>
	<link name="wheel3_sub5_1">
		<collision>
			<origin xyz="0.0534199 -0.0535157 0.032114" rpy="-1.15505e-16 3.83023e-17 4.03925e-18" />
			<geometry>
				<mesh filename="file://$(find jetbot_description)/urdf/jetbot_soccer/sub_wheel.stl"/>
			</geometry>
			<material name="sub_wheel_material">
				<color rgba="0.768627 0.886275 0.952941 1.0"/>
			</material>
		</collision>
		<visual>
			<origin xyz="0 0 0" rpy="0 -0 0" />
			<geometry>
				<mesh filename="file://$(find jetbot_description)/urdf/jetbot_soccer/wheel3_sub5_1.stl"/>
			</geometry>
			<material name="wheel3_sub5_1_material">
				<color rgba="0.768627 0.886275 0.952941 1.0"/>
			</material>
		</visual>
		<inertial>
			<origin xyz="3.67355e-05 -2.09868e-05 5.31199e-07" rpy="0 0 0"/>
			<mass value="9.9564e-05" />
			<inertia ixx="9.26988e-10" ixy="4.8503e-10"  ixz="2.09591e-13" iyy="1.48655e-09" iyz="-2.62533e-14" izz="1.76782e-09" />
		</inertial>
	</link>
	<joint name="wheel3_sub7" type="revolute">
		<origin xyz="0.00825 0.0142894 0.0102056" rpy="1.5708 -0.523599 2.61799" />
		<parent link="horn2_1" />
		<child link="wheel3_sub5_1" />
		<axis xyz="-0.866025 0.5 0"/>
		<limit lower="-0.02" upper="0.10" effort="100" velocity="20" />
		<joint_properties friction="0.0"/>
	</joint>
	<link name="wheel3_sub4_1">
		<collision>
			<origin xyz="0.0534199 -0.0535157 0.032114" rpy="8.6727e-17 8.08906e-18 3.8081e-17" />
			<geometry>
				<mesh filename="file://$(find jetbot_description)/urdf/jetbot_soccer/sub_wheel.stl"/>
			</geometry>
			<material name="sub_wheel_material">
				<color rgba="0.768627 0.886275 0.952941 1.0"/>
			</material>
		</collision>
		<visual>
			<origin xyz="0 0 0" rpy="0 -0 0" />
			<geometry>
				<mesh filename="file://$(find jetbot_description)/urdf/jetbot_soccer/wheel3_sub4_1.stl"/>
			</geometry>
			<material name="wheel3_sub4_1_material">
				<color rgba="0.768627 0.886275 0.952941 1.0"/>
			</material>
		</visual>
		<inertial>
			<origin xyz="3.67355e-05 -2.09868e-05 5.31199e-07" rpy="0 0 0"/>
			<mass value="9.9564e-05" />
			<inertia ixx="9.26988e-10" ixy="4.8503e-10"  ixz="2.09591e-13" iyy="1.48655e-09" iyz="-2.62533e-14" izz="1.76782e-09" />
		</inertial>
	</link>
	<joint name="wheel3_sub8" type="revolute">
		<origin xyz="0.0165 2.77556e-17 0.0102056" rpy="-4.91531e-12 2.85044e-12 -1.0472" />
		<parent link="horn2_1" />
		<child link="wheel3_sub4_1" />
		<axis xyz="-0.866025 0.5 0"/>
		<limit lower="-0.02" upper="0.10" effort="100" velocity="20" />
		<joint_properties friction="0.0"/>
	</joint>
	<link name="wheel3_sub11_1">
		<collision>
			<origin xyz="0.0534199 -0.0535157 0.032114" rpy="2.04207e-17 5.10306e-18 8.19505e-17" />
			<geometry>
				<mesh filename="file://$(find jetbot_description)/urdf/jetbot_soccer/sub_wheel.stl"/>
			</geometry>
			<material name="sub_wheel_material">
				<color rgba="0.768627 0.886275 0.952941 1.0"/>
			</material>
		</collision>
		<visual>
			<origin xyz="0 0 0" rpy="0 -0 0" />
			<geometry>
				<mesh filename="file://$(find jetbot_description)/urdf/jetbot_soccer/wheel3_sub11_1.stl"/>
			</geometry>
			<material name="wheel3_sub11_1_material">
				<color rgba="0.768627 0.886275 0.952941 1.0"/>
			</material>
		</visual>
		<inertial>
			<origin xyz="3.67355e-05 -2.09868e-05 5.31199e-07" rpy="0 0 0"/>
			<mass value="9.9564e-05" />
			<inertia ixx="9.26988e-10" ixy="4.8503e-10"  ixz="2.09591e-13" iyy="1.48655e-09" iyz="-2.62533e-14" izz="1.76782e-09" />
		</inertial>
	</link>
	<joint name="wheel3_sub9" type="revolute">
		<origin xyz="0.00825 -0.0142894 0.0102056" rpy="1.5708 -0.523599 -2.61799" />
		<parent link="horn2_1" />
		<child link="wheel3_sub11_1" />
		<axis xyz="-0.866025 0.5 0"/>
		<limit lower="-0.02" upper="0.10" effort="100" velocity="20" />
		<joint_properties friction="0.0"/>
	</joint>
	<link name="wheel3_sub8_1">
		<collision>
			<origin xyz="0.0534199 -0.0535157 0.032114" rpy="-1.00831e-16 -5.47854e-18 -3.89101e-17" />
			<geometry>
				<mesh filename="file://$(find jetbot_description)/urdf/jetbot_soccer/sub_wheel.stl"/>
			</geometry>
			<material name="sub_wheel_material">
				<color rgba="0.768627 0.886275 0.952941 1.0"/>
			</material>
		</collision>
		<visual>
			<origin xyz="0 0 0" rpy="0 -0 0" />
			<geometry>
				<mesh filename="file://$(find jetbot_description)/urdf/jetbot_soccer/wheel3_sub8_1.stl"/>
			</geometry>
			<material name="wheel3_sub8_1_material">
				<color rgba="0.768627 0.886275 0.952941 1.0"/>
			</material>
		</visual>
		<inertial>
			<origin xyz="3.67355e-05 -2.09868e-05 5.31199e-07" rpy="0 0 0"/>
			<mass value="9.9564e-05" />
			<inertia ixx="9.26988e-10" ixy="4.8503e-10"  ixz="2.09591e-13" iyy="1.48655e-09" iyz="-2.62533e-14" izz="1.76782e-09" />
		</inertial>
	</link>
	<joint name="wheel3_sub10" type="revolute">
		<origin xyz="-0.00825 -0.0142894 0.0102056" rpy="1.5708 -0.523599 2.61799" />
		<parent link="horn2_1" />
		<child link="wheel3_sub8_1" />
		<axis xyz="-0.866025 0.5 0"/>
		<limit lower="-0.02" upper="0.10" effort="100" velocity="20" />
		<joint_properties friction="0.0"/>
	</joint>
	<link name="wheel3_sub10_1">
		<collision>
			<origin xyz="0.0534199 -0.0535157 0.032114" rpy="-2.25467e-20 -4.97225e-17 3.59535e-17" />
			<geometry>
				<mesh filename="file://$(find jetbot_description)/urdf/jetbot_soccer/sub_wheel.stl"/>
			</geometry>
			<material name="sub_wheel_material">
				<color rgba="0.768627 0.886275 0.952941 1.0"/>
			</material>
		</collision>
		<visual>
			<origin xyz="0 0 0" rpy="0 -0 0" />
			<geometry>
				<mesh filename="file://$(find jetbot_description)/urdf/jetbot_soccer/wheel3_sub10_1.stl"/>
			</geometry>
			<material name="wheel3_sub10_1_material">
				<color rgba="0.768627 0.886275 0.952941 1.0"/>
			</material>
		</visual>
		<inertial>
			<origin xyz="3.67355e-05 -2.09868e-05 5.31199e-07" rpy="0 0 0"/>
			<mass value="9.9564e-05" />
			<inertia ixx="9.26988e-10" ixy="4.8503e-10"  ixz="2.09591e-13" iyy="1.48655e-09" iyz="-2.62533e-14" izz="1.76782e-09" />
		</inertial>
	</link>
	<joint name="wheel3_sub11" type="revolute">
		<origin xyz="-0.00825 0.0142894 0.0102056" rpy="1.5708 -0.523599 -2.61799" />
		<parent link="horn2_1" />
		<child link="wheel3_sub10_1" />
		<axis xyz="-0.866025 0.5 0"/>
		<limit lower="-0.02" upper="0.10" effort="100" velocity="20" />
		<joint_properties friction="0.0"/>
	</joint>
	<link name="wheel3_sub7_1">
		<collision>
			<origin xyz="0.0534199 -0.0535157 0.032114" rpy="8.6727e-17 8.08906e-18 3.8081e-17" />
			<geometry>
				<mesh filename="file://$(find jetbot_description)/urdf/jetbot_soccer/sub_wheel.stl"/>
			</geometry>
			<material name="sub_wheel_material">
				<color rgba="0.768627 0.886275 0.952941 1.0"/>
			</material>
		</collision>
		<visual>
			<origin xyz="0 0 0" rpy="0 -0 0" />
			<geometry>
				<mesh filename="file://$(find jetbot_description)/urdf/jetbot_soccer/wheel3_sub7_1.stl"/>
			</geometry>
			<material name="wheel3_sub7_1_material">
				<color rgba="0.768627 0.886275 0.952941 1.0"/>
			</material>
		</visual>
		<inertial>
			<origin xyz="3.67355e-05 -2.09868e-05 5.31199e-07" rpy="0 0 0"/>
			<mass value="9.9564e-05" />
			<inertia ixx="9.26988e-10" ixy="4.8503e-10"  ixz="2.09591e-13" iyy="1.48655e-09" iyz="-2.62533e-14" izz="1.76782e-09" />
		</inertial>
	</link>
	<joint name="wheel3_sub12" type="revolute">
		<origin xyz="-0.0165 -5.55112e-17 0.0102056" rpy="-4.91531e-12 2.85044e-12 -1.0472" />
		<parent link="horn2_1" />
		<child link="wheel3_sub7_1" />
		<axis xyz="-0.866025 0.5 0"/>
		<limit lower="-0.02" upper="0.10" effort="100" velocity="20" />
		<joint_properties friction="0.0"/>
	</joint>
	<joint name="wheel1" type="revolute">
		<origin xyz="-0.233751 -0.212799 -0.143861" rpy="1.5708 0.00210312 2.13103" />
		<parent link="body_1" />
		<child link="horn2_1" />
		<axis xyz="0 0 -1"/>
		<limit lower="-0.02" upper="0.10" effort="100" velocity="20" />
		<joint_properties friction="0.0"/>
	</joint>
	<link name="horn1_1">
		<collision>
			<origin xyz="-0.171498 -0.217932 0.00431" rpy="3.14159 2.12094e-16 1.54139e-17" />
			<geometry>
				<mesh filename="file://$(find jetbot_description)/urdf/jetbot_soccer/horn.stl"/>
			</geometry>
			<material name="horn_material">
				<color rgba="0.231373 0.380392 0.705882 1.0"/>
			</material>
		</collision>
		<collision>
			<origin xyz="0.04517 -0.0678046 0.0423198" rpy="-4.93315e-17 1.56976e-15 2.24744e-17" />
			<geometry>
				<mesh filename="file://$(find jetbot_description)/urdf/jetbot_soccer/main_frame.stl"/>
			</geometry>
			<material name="main_frame_material">
				<color rgba="0.980392 0.713725 0.00392157 1.0"/>
			</material>
		</collision>
		<collision>
			<origin xyz="0 -1.38778e-17 0.0012" rpy="1.0142e-16 -5.43184e-18 1.26211e-17" />
			<geometry>
				<mesh filename="file://$(find jetbot_description)/urdf/jetbot_soccer/mx-12w_horn.stl"/>
			</geometry>
			<material name="mx-12w_horn_material">
				<color rgba="0.980392 0.713725 0.00392157 1.0"/>
			</material>
		</collision>
		<visual>
			<origin xyz="0 0 0" rpy="0 -0 0" />
			<geometry>
				<mesh filename="file://$(find jetbot_description)/urdf/jetbot_soccer/horn1_1.stl"/>
			</geometry>
			<material name="horn1_1_material">
				<color rgba="0.937052 0.694438 0.0445389 1.0"/>
			</material>
		</visual>
		<inertial>
			<origin xyz="-1.11491e-06 -2.12888e-08 0.012158" rpy="0 0 0"/>
			<mass value="0.0125567" />
			<inertia ixx="1.27584e-06" ixy="-1.42503e-11"  ixz="-1.22446e-10" iyy="1.27561e-06" iyz="-1.41565e-11" izz="1.48771e-06" />
		</inertial>
	</link>
	<link name="wheel4_sub11_1">
		<collision>
			<origin xyz="0.0534199 -0.0535157 0.032114" rpy="2.94433e-17 2.93683e-17 -4.16149e-18" />
			<geometry>
				<mesh filename="file://$(find jetbot_description)/urdf/jetbot_soccer/sub_wheel.stl"/>
			</geometry>
			<material name="sub_wheel_material">
				<color rgba="0.768627 0.886275 0.952941 1.0"/>
			</material>
		</collision>
		<visual>
			<origin xyz="0 0 0" rpy="0 -0 0" />
			<geometry>
				<mesh filename="file://$(find jetbot_description)/urdf/jetbot_soccer/wheel4_sub11_1.stl"/>
			</geometry>
			<material name="wheel4_sub11_1_material">
				<color rgba="0.768627 0.886275 0.952941 1.0"/>
			</material>
		</visual>
		<inertial>
			<origin xyz="3.67355e-05 -2.09868e-05 5.31199e-07" rpy="0 0 0"/>
			<mass value="9.9564e-05" />
			<inertia ixx="9.26988e-10" ixy="4.8503e-10"  ixz="2.09591e-13" iyy="1.48655e-09" iyz="-2.62533e-14" izz="1.76782e-09" />
		</inertial>
	</link>
	<joint name="wheel4_sub1" type="revolute">
		<origin xyz="0.0142894 -0.00825 0.0189056" rpy="-1.5708 0.523599 -2.0944" />
		<parent link="horn1_1" />
		<child link="wheel4_sub11_1" />
		<axis xyz="-0.866025 0.5 0"/>
		<limit lower="-0.02" upper="0.10" effort="100" velocity="20" />
		<joint_properties friction="0.0"/>
	</joint>
	<link name="wheel4_sub5_1">
		<collision>
			<origin xyz="0.0534199 -0.0535157 0.032114" rpy="-5.16363e-17 -7.16316e-19 -7.32282e-17" />
			<geometry>
				<mesh filename="file://$(find jetbot_description)/urdf/jetbot_soccer/sub_wheel.stl"/>
			</geometry>
			<material name="sub_wheel_material">
				<color rgba="0.768627 0.886275 0.952941 1.0"/>
			</material>
		</collision>
		<visual>
			<origin xyz="0 0 0" rpy="0 -0 0" />
			<geometry>
				<mesh filename="file://$(find jetbot_description)/urdf/jetbot_soccer/wheel4_sub5_1.stl"/>
			</geometry>
			<material name="wheel4_sub5_1_material">
				<color rgba="0.768627 0.886275 0.952941 1.0"/>
			</material>
		</visual>
		<inertial>
			<origin xyz="3.67355e-05 -2.09868e-05 5.31199e-07" rpy="0 0 0"/>
			<mass value="9.9564e-05" />
			<inertia ixx="9.26988e-10" ixy="4.8503e-10"  ixz="2.09591e-13" iyy="1.48655e-09" iyz="-2.62533e-14" izz="1.76782e-09" />
		</inertial>
	</link>
	<joint name="wheel4_sub2" type="revolute">
		<origin xyz="0.0142894 0.00825 0.0189056" rpy="-1.5708 0.523599 -1.0472" />
		<parent link="horn1_1" />
		<child link="wheel4_sub5_1" />
		<axis xyz="-0.866025 0.5 0"/>
		<limit lower="-0.02" upper="0.10" effort="100" velocity="20" />
		<joint_properties friction="0.0"/>
	</joint>
	<link name="wheel4_sub3_1">
		<collision>
			<origin xyz="0.0534199 -0.0535157 0.032114" rpy="-5.63109e-17 -9.20147e-19 -4.64908e-17" />
			<geometry>
				<mesh filename="file://$(find jetbot_description)/urdf/jetbot_soccer/sub_wheel.stl"/>
			</geometry>
			<material name="sub_wheel_material">
				<color rgba="0.768627 0.886275 0.952941 1.0"/>
			</material>
		</collision>
		<visual>
			<origin xyz="0 0 0" rpy="0 -0 0" />
			<geometry>
				<mesh filename="file://$(find jetbot_description)/urdf/jetbot_soccer/wheel4_sub3_1.stl"/>
			</geometry>
			<material name="wheel4_sub3_1_material">
				<color rgba="0.768627 0.886275 0.952941 1.0"/>
			</material>
		</visual>
		<inertial>
			<origin xyz="3.67355e-05 -2.09868e-05 5.31199e-07" rpy="0 0 0"/>
			<mass value="9.9564e-05" />
			<inertia ixx="9.26988e-10" ixy="4.8503e-10"  ixz="2.09591e-13" iyy="1.48655e-09" iyz="-2.62533e-14" izz="1.76782e-09" />
		</inertial>
	</link>
	<joint name="wheel4_sub3" type="revolute">
		<origin xyz="8.32667e-17 0.0165 0.0189056" rpy="-3.22184e-10 1.86015e-10 0.523599" />
		<parent link="horn1_1" />
		<child link="wheel4_sub3_1" />
		<axis xyz="-0.866025 0.5 0"/>
		<limit lower="-0.02" upper="0.10" effort="100" velocity="20" />
		<joint_properties friction="0.0"/>
	</joint>
	<link name="wheel4_sub6_1">
		<collision>
			<origin xyz="0.0534199 -0.0535157 0.032114" rpy="-6.67581e-18 -3.99587e-17 -2.4506e-17" />
			<geometry>
				<mesh filename="file://$(find jetbot_description)/urdf/jetbot_soccer/sub_wheel.stl"/>
			</geometry>
			<material name="sub_wheel_material">
				<color rgba="0.768627 0.886275 0.952941 1.0"/>
			</material>
		</collision>
		<visual>
			<origin xyz="0 0 0" rpy="0 -0 0" />
			<geometry>
				<mesh filename="file://$(find jetbot_description)/urdf/jetbot_soccer/wheel4_sub6_1.stl"/>
			</geometry>
			<material name="wheel4_sub6_1_material">
				<color rgba="0.768627 0.886275 0.952941 1.0"/>
			</material>
		</visual>
		<inertial>
			<origin xyz="3.67355e-05 -2.09868e-05 5.31199e-07" rpy="0 0 0"/>
			<mass value="9.9564e-05" />
			<inertia ixx="9.26988e-10" ixy="4.8503e-10"  ixz="2.09591e-13" iyy="1.48655e-09" iyz="-2.62533e-14" izz="1.76782e-09" />
		</inertial>
	</link>
	<joint name="wheel4_sub4" type="revolute">
		<origin xyz="-0.0142894 0.00825 0.0189056" rpy="-1.5708 0.523599 -2.0944" />
		<parent link="horn1_1" />
		<child link="wheel4_sub6_1" />
		<axis xyz="-0.866025 0.5 0"/>
		<limit lower="-0.02" upper="0.10" effort="100" velocity="20" />
		<joint_properties friction="0.0"/>
	</joint>
	<link name="wheel4_sub10_1">
		<collision>
			<origin xyz="0.0534199 -0.0535157 0.032114" rpy="4.65446e-17 2.80469e-18 -5.13106e-17" />
			<geometry>
				<mesh filename="file://$(find jetbot_description)/urdf/jetbot_soccer/sub_wheel.stl"/>
			</geometry>
			<material name="sub_wheel_material">
				<color rgba="0.768627 0.886275 0.952941 1.0"/>
			</material>
		</collision>
		<visual>
			<origin xyz="0 0 0" rpy="0 -0 0" />
			<geometry>
				<mesh filename="file://$(find jetbot_description)/urdf/jetbot_soccer/wheel4_sub10_1.stl"/>
			</geometry>
			<material name="wheel4_sub10_1_material">
				<color rgba="0.768627 0.886275 0.952941 1.0"/>
			</material>
		</visual>
		<inertial>
			<origin xyz="3.67355e-05 -2.09868e-05 5.31199e-07" rpy="0 0 0"/>
			<mass value="9.9564e-05" />
			<inertia ixx="9.26988e-10" ixy="4.8503e-10"  ixz="2.09591e-13" iyy="1.48655e-09" iyz="-2.62533e-14" izz="1.76782e-09" />
		</inertial>
	</link>
	<joint name="wheel4_sub5" type="revolute">
		<origin xyz="-0.0142894 -0.00825 0.0189056" rpy="-1.5708 0.523599 -1.0472" />
		<parent link="horn1_1" />
		<child link="wheel4_sub10_1" />
		<axis xyz="-0.866025 0.5 0"/>
		<limit lower="-0.02" upper="0.10" effort="100" velocity="20" />
		<joint_properties friction="0.0"/>
	</joint>
	<link name="wheel4_sub9_1">
		<collision>
			<origin xyz="0.0534199 -0.0535157 0.032114" rpy="-5.63109e-17 -9.20147e-19 -4.64908e-17" />
			<geometry>
				<mesh filename="file://$(find jetbot_description)/urdf/jetbot_soccer/sub_wheel.stl"/>
			</geometry>
			<material name="sub_wheel_material">
				<color rgba="0.768627 0.886275 0.952941 1.0"/>
			</material>
		</collision>
		<visual>
			<origin xyz="0 0 0" rpy="0 -0 0" />
			<geometry>
				<mesh filename="file://$(find jetbot_description)/urdf/jetbot_soccer/wheel4_sub9_1.stl"/>
			</geometry>
			<material name="wheel4_sub9_1_material">
				<color rgba="0.768627 0.886275 0.952941 1.0"/>
			</material>
		</visual>
		<inertial>
			<origin xyz="3.67355e-05 -2.09868e-05 5.31199e-07" rpy="0 0 0"/>
			<mass value="9.9564e-05" />
			<inertia ixx="9.26988e-10" ixy="4.8503e-10"  ixz="2.09591e-13" iyy="1.48655e-09" iyz="-2.62533e-14" izz="1.76782e-09" />
		</inertial>
	</link>
	<joint name="wheel4_sub6" type="revolute">
		<origin xyz="-5.55112e-17 -0.0165 0.0189056" rpy="-3.22184e-10 1.86015e-10 0.523599" />
		<parent link="horn1_1" />
		<child link="wheel4_sub9_1" />
		<axis xyz="-0.866025 0.5 0"/>
		<limit lower="-0.02" upper="0.10" effort="100" velocity="20" />
		<joint_properties friction="0.0"/>
	</joint>
	<link name="wheel4_sub8_1">
		<collision>
			<origin xyz="0.0534199 -0.0535157 0.032114" rpy="1.7026e-16 -3.16574e-18 8.97456e-18" />
			<geometry>
				<mesh filename="file://$(find jetbot_description)/urdf/jetbot_soccer/sub_wheel.stl"/>
			</geometry>
			<material name="sub_wheel_material">
				<color rgba="0.768627 0.886275 0.952941 1.0"/>
			</material>
		</collision>
		<visual>
			<origin xyz="0 0 0" rpy="0 -0 0" />
			<geometry>
				<mesh filename="file://$(find jetbot_description)/urdf/jetbot_soccer/wheel4_sub8_1.stl"/>
			</geometry>
			<material name="wheel4_sub8_1_material">
				<color rgba="0.768627 0.886275 0.952941 1.0"/>
			</material>
		</visual>
		<inertial>
			<origin xyz="3.67355e-05 -2.09868e-05 5.31199e-07" rpy="0 0 0"/>
			<mass value="9.9564e-05" />
			<inertia ixx="9.26988e-10" ixy="4.8503e-10"  ixz="2.09591e-13" iyy="1.48655e-09" iyz="-2.62533e-14" izz="1.76782e-09" />
		</inertial>
	</link>
	<joint name="wheel4_sub7" type="revolute">
		<origin xyz="0.00825 -0.0142894 0.0102056" rpy="3.14159 -5.55605e-10 3.14159" />
		<parent link="horn1_1" />
		<child link="wheel4_sub8_1" />
		<axis xyz="-0.866025 0.5 0"/>
		<limit lower="-0.02" upper="0.10" effort="100" velocity="20" />
		<joint_properties friction="0.0"/>
	</joint>
	<link name="wheel4_sub7_1">
		<collision>
			<origin xyz="0.0534199 -0.0535157 0.032114" rpy="-4.93525e-17 -2.60294e-17 7.03443e-17" />
			<geometry>
				<mesh filename="file://$(find jetbot_description)/urdf/jetbot_soccer/sub_wheel.stl"/>
			</geometry>
			<material name="sub_wheel_material">
				<color rgba="0.768627 0.886275 0.952941 1.0"/>
			</material>
		</collision>
		<visual>
			<origin xyz="0 0 0" rpy="0 -0 0" />
			<geometry>
				<mesh filename="file://$(find jetbot_description)/urdf/jetbot_soccer/wheel4_sub7_1.stl"/>
			</geometry>
			<material name="wheel4_sub7_1_material">
				<color rgba="0.768627 0.886275 0.952941 1.0"/>
			</material>
		</visual>
		<inertial>
			<origin xyz="3.67355e-05 -2.09868e-05 5.31199e-07" rpy="0 0 0"/>
			<mass value="9.9564e-05" />
			<inertia ixx="9.26988e-10" ixy="4.8503e-10"  ixz="2.09591e-13" iyy="1.48655e-09" iyz="-2.62533e-14" izz="1.76782e-09" />
		</inertial>
	</link>
	<joint name="wheel4_sub8" type="revolute">
		<origin xyz="-0.00825 -0.0142894 0.0102056" rpy="-1.5708 0.523599 -0.523599" />
		<parent link="horn1_1" />
		<child link="wheel4_sub7_1" />
		<axis xyz="-0.866025 0.5 0"/>
		<limit lower="-0.02" upper="0.10" effort="100" velocity="20" />
		<joint_properties friction="0.0"/>
	</joint>
	<link name="wheel4_sub4_1">
		<collision>
			<origin xyz="0.0534199 -0.0535157 0.032114" rpy="8.88428e-18 -2.14463e-19 2.32876e-17" />
			<geometry>
				<mesh filename="file://$(find jetbot_description)/urdf/jetbot_soccer/sub_wheel.stl"/>
			</geometry>
			<material name="sub_wheel_material">
				<color rgba="0.768627 0.886275 0.952941 1.0"/>
			</material>
		</collision>
		<visual>
			<origin xyz="0 0 0" rpy="0 -0 0" />
			<geometry>
				<mesh filename="file://$(find jetbot_description)/urdf/jetbot_soccer/wheel4_sub4_1.stl"/>
			</geometry>
			<material name="wheel4_sub4_1_material">
				<color rgba="0.768627 0.886275 0.952941 1.0"/>
			</material>
		</visual>
		<inertial>
			<origin xyz="3.67355e-05 -2.09868e-05 5.31199e-07" rpy="0 0 0"/>
			<mass value="9.9564e-05" />
			<inertia ixx="9.26988e-10" ixy="4.8503e-10"  ixz="2.09591e-13" iyy="1.48655e-09" iyz="-2.62533e-14" izz="1.76782e-09" />
		</inertial>
	</link>
	<joint name="wheel4_sub9" type="revolute">
		<origin xyz="-0.0165 4.16334e-17 0.0102056" rpy="-1.5708 0.523599 -1.5708" />
		<parent link="horn1_1" />
		<child link="wheel4_sub4_1" />
		<axis xyz="-0.866025 0.5 0"/>
		<limit lower="-0.02" upper="0.10" effort="100" velocity="20" />
		<joint_properties friction="0.0"/>
	</joint>
	<link name="wheel4_sub1_1">
		<collision>
			<origin xyz="0.0534199 -0.0535157 0.032114" rpy="7.58334e-17 -6.04174e-18 -9.41813e-17" />
			<geometry>
				<mesh filename="file://$(find jetbot_description)/urdf/jetbot_soccer/sub_wheel.stl"/>
			</geometry>
			<material name="sub_wheel_material">
				<color rgba="0.768627 0.886275 0.952941 1.0"/>
			</material>
		</collision>
		<visual>
			<origin xyz="0 0 0" rpy="0 -0 0" />
			<geometry>
				<mesh filename="file://$(find jetbot_description)/urdf/jetbot_soccer/wheel4_sub1_1.stl"/>
			</geometry>
			<material name="wheel4_sub1_1_material">
				<color rgba="0.768627 0.886275 0.952941 1.0"/>
			</material>
		</visual>
		<inertial>
			<origin xyz="3.67355e-05 -2.09868e-05 5.31199e-07" rpy="0 0 0"/>
			<mass value="9.9564e-05" />
			<inertia ixx="9.26988e-10" ixy="4.8503e-10"  ixz="2.09591e-13" iyy="1.48655e-09" iyz="-2.62533e-14" izz="1.76782e-09" />
		</inertial>
	</link>
	<joint name="wheel4_sub10" type="revolute">
		<origin xyz="0.00825 0.0142894 0.0102056" rpy="-1.5708 0.523599 -0.523599" />
		<parent link="horn1_1" />
		<child link="wheel4_sub1_1" />
		<axis xyz="-0.866025 0.5 0"/>
		<limit lower="-0.02" upper="0.10" effort="100" velocity="20" />
		<joint_properties friction="0.0"/>
	</joint>
	<link name="wheel4_sub12_1">
		<collision>
			<origin xyz="0.0534199 -0.0535157 0.032114" rpy="-2.35626e-18 7.93948e-20 -8.14046e-18" />
			<geometry>
				<mesh filename="file://$(find jetbot_description)/urdf/jetbot_soccer/sub_wheel.stl"/>
			</geometry>
			<material name="sub_wheel_material">
				<color rgba="0.768627 0.886275 0.952941 1.0"/>
			</material>
		</collision>
		<visual>
			<origin xyz="0 0 0" rpy="0 -0 0" />
			<geometry>
				<mesh filename="file://$(find jetbot_description)/urdf/jetbot_soccer/wheel4_sub12_1.stl"/>
			</geometry>
			<material name="wheel4_sub12_1_material">
				<color rgba="0.768627 0.886275 0.952941 1.0"/>
			</material>
		</visual>
		<inertial>
			<origin xyz="3.67355e-05 -2.09868e-05 5.31199e-07" rpy="0 0 0"/>
			<mass value="9.9564e-05" />
			<inertia ixx="9.26988e-10" ixy="4.8503e-10"  ixz="2.09591e-13" iyy="1.48655e-09" iyz="-2.62533e-14" izz="1.76782e-09" />
		</inertial>
	</link>
	<joint name="wheel4_sub11" type="revolute">
		<origin xyz="-0.00825 0.0142894 0.0102056" rpy="3.14159 -5.55606e-10 -3.14159" />
		<parent link="horn1_1" />
		<child link="wheel4_sub12_1" />
		<axis xyz="-0.866025 0.5 0"/>
		<limit lower="-0.02" upper="0.10" effort="100" velocity="20" />
		<joint_properties friction="0.0"/>
	</joint>
	<link name="wheel4_sub2_1">
		<collision>
			<origin xyz="0.0534199 -0.0535157 0.032114" rpy="8.88428e-18 -2.14463e-19 2.32876e-17" />
			<geometry>
				<mesh filename="file://$(find jetbot_description)/urdf/jetbot_soccer/sub_wheel.stl"/>
			</geometry>
			<material name="sub_wheel_material">
				<color rgba="0.768627 0.886275 0.952941 1.0"/>
			</material>
		</collision>
		<visual>
			<origin xyz="0 0 0" rpy="0 -0 0" />
			<geometry>
				<mesh filename="file://$(find jetbot_description)/urdf/jetbot_soccer/wheel4_sub2_1.stl"/>
			</geometry>
			<material name="wheel4_sub2_1_material">
				<color rgba="0.768627 0.886275 0.952941 1.0"/>
			</material>
		</visual>
		<inertial>
			<origin xyz="3.67355e-05 -2.09868e-05 5.31199e-07" rpy="0 0 0"/>
			<mass value="9.9564e-05" />
			<inertia ixx="9.26988e-10" ixy="4.8503e-10"  ixz="2.09591e-13" iyy="1.48655e-09" iyz="-2.62533e-14" izz="1.76782e-09" />
		</inertial>
	</link>
	<joint name="wheel4_sub12" type="revolute">
		<origin xyz="0.0165 4.16334e-17 0.0102056" rpy="-1.5708 0.523599 -1.5708" />
		<parent link="horn1_1" />
		<child link="wheel4_sub2_1" />
		<axis xyz="-0.866025 0.5 0"/>
		<limit lower="-0.02" upper="0.10" effort="100" velocity="20" />
		<joint_properties friction="0.0"/>
	</joint>
	<joint name="wheel3" type="revolute">
		<origin xyz="-0.342729 -0.32513 -0.143861" rpy="1.5708 -1.44174 -1.00428" />
		<parent link="body_1" />
		<child link="horn1_1" />
		<axis xyz="0 0 -1"/>
		<limit lower="-0.02" upper="0.10" effort="100" velocity="20" />
		<joint_properties friction="0.0"/>
	</joint>
	<link name="horn4_2">
		<collision>
			<origin xyz="0.171498 0.217932 0.00431" rpy="-3.14159 7.57925e-17 -3.14159" />
			<geometry>
				<mesh filename="file://$(find jetbot_description)/urdf/jetbot_soccer/horn.stl"/>
			</geometry>
			<material name="horn_material">
				<color rgba="0.231373 0.380392 0.705882 1.0"/>
			</material>
		</collision>
		<collision>
			<origin xyz="0.0678046 0.04517 0.0423198" rpy="1.16427e-14 8.2903e-15 1.5708" />
			<geometry>
				<mesh filename="file://$(find jetbot_description)/urdf/jetbot_soccer/main_frame.stl"/>
			</geometry>
			<material name="main_frame_material">
				<color rgba="0.980392 0.713725 0.00392157 1.0"/>
			</material>
		</collision>
		<collision>
			<origin xyz="-5.55112e-17 0 0.0012" rpy="-7.77983e-21 6.15646e-17 -1.39145e-19" />
			<geometry>
				<mesh filename="file://$(find jetbot_description)/urdf/jetbot_soccer/mx-12w_horn.stl"/>
			</geometry>
			<material name="mx-12w_horn_material">
				<color rgba="0.980392 0.713725 0.00392157 1.0"/>
			</material>
		</collision>
		<visual>
			<origin xyz="0 0 0" rpy="0 -0 0" />
			<geometry>
				<mesh filename="file://$(find jetbot_description)/urdf/jetbot_soccer/horn4_2.stl"/>
			</geometry>
			<material name="horn4_2_material">
				<color rgba="0.937052 0.694438 0.0445389 1.0"/>
			</material>
		</visual>
		<inertial>
			<origin xyz="-9.44942e-07 -1.4867e-07 0.012158" rpy="0 0 0"/>
			<mass value="0.0125567" />
			<inertia ixx="1.27588e-06" ixy="1.42523e-11"  ixz="-1.50868e-10" iyy="1.27557e-06" iyz="-4.04238e-12" izz="1.48771e-06" />
		</inertial>
	</link>
	<link name="wheel1_sub3_1">
		<collision>
			<origin xyz="0.0534199 -0.0535157 0.032114" rpy="7.79919e-17 1.99347e-20 -4.8392e-19" />
			<geometry>
				<mesh filename="file://$(find jetbot_description)/urdf/jetbot_soccer/sub_wheel.stl"/>
			</geometry>
			<material name="sub_wheel_material">
				<color rgba="0.768627 0.886275 0.952941 1.0"/>
			</material>
		</collision>
		<visual>
			<origin xyz="0 0 0" rpy="0 -0 0" />
			<geometry>
				<mesh filename="file://$(find jetbot_description)/urdf/jetbot_soccer/wheel1_sub3_1.stl"/>
			</geometry>
			<material name="wheel1_sub3_1_material">
				<color rgba="0.768627 0.886275 0.952941 1.0"/>
			</material>
		</visual>
		<inertial>
			<origin xyz="3.67355e-05 -2.09868e-05 5.31199e-07" rpy="0 0 0"/>
			<mass value="9.9564e-05" />
			<inertia ixx="9.26988e-10" ixy="4.8503e-10"  ixz="2.09591e-13" iyy="1.48655e-09" iyz="-2.62533e-14" izz="1.76782e-09" />
		</inertial>
	</link>
	<joint name="wheel1_sub1" type="revolute">
		<origin xyz="-0.0142894 -0.00825 0.0102056" rpy="-3.14159 6.54647e-09 -1.5708" />
		<parent link="horn4_2" />
		<child link="wheel1_sub3_1" />
		<axis xyz="-0.866025 0.5 0"/>
		<limit lower="-0.02" upper="0.10" effort="100" velocity="20" />
		<joint_properties friction="0.0"/>
	</joint>
	<link name="wheel1_sub7_1">
		<collision>
			<origin xyz="0.0534199 -0.0535157 0.032114" rpy="9.60976e-21 9.64578e-20 3.13688e-18" />
			<geometry>
				<mesh filename="file://$(find jetbot_description)/urdf/jetbot_soccer/sub_wheel.stl"/>
			</geometry>
			<material name="sub_wheel_material">
				<color rgba="0.768627 0.886275 0.952941 1.0"/>
			</material>
		</collision>
		<visual>
			<origin xyz="0 0 0" rpy="0 -0 0" />
			<geometry>
				<mesh filename="file://$(find jetbot_description)/urdf/jetbot_soccer/wheel1_sub7_1.stl"/>
			</geometry>
			<material name="wheel1_sub7_1_material">
				<color rgba="0.768627 0.886275 0.952941 1.0"/>
			</material>
		</visual>
		<inertial>
			<origin xyz="3.67355e-05 -2.09868e-05 5.31199e-07" rpy="0 0 0"/>
			<mass value="9.9564e-05" />
			<inertia ixx="9.26988e-10" ixy="4.8503e-10"  ixz="2.09591e-13" iyy="1.48655e-09" iyz="-2.62533e-14" izz="1.76782e-09" />
		</inertial>
	</link>
	<joint name="wheel1_sub2" type="revolute">
		<origin xyz="0 -0.0165 0.0102056" rpy="-1.5708 0.523599 1.50893e-08" />
		<parent link="horn4_2" />
		<child link="wheel1_sub7_1" />
		<axis xyz="-0.866025 0.5 0"/>
		<limit lower="-0.02" upper="0.10" effort="100" velocity="20" />
		<joint_properties friction="0.0"/>
	</joint>
	<link name="wheel1_sub11_1">
		<collision>
			<origin xyz="0.0534199 -0.0535157 0.032114" rpy="8.4502e-18 -2.73865e-17 -3.20989e-18" />
			<geometry>
				<mesh filename="file://$(find jetbot_description)/urdf/jetbot_soccer/sub_wheel.stl"/>
			</geometry>
			<material name="sub_wheel_material">
				<color rgba="0.768627 0.886275 0.952941 1.0"/>
			</material>
		</collision>
		<visual>
			<origin xyz="0 0 0" rpy="0 -0 0" />
			<geometry>
				<mesh filename="file://$(find jetbot_description)/urdf/jetbot_soccer/wheel1_sub11_1.stl"/>
			</geometry>
			<material name="wheel1_sub11_1_material">
				<color rgba="0.768627 0.886275 0.952941 1.0"/>
			</material>
		</visual>
		<inertial>
			<origin xyz="3.67355e-05 -2.09868e-05 5.31199e-07" rpy="0 0 0"/>
			<mass value="9.9564e-05" />
			<inertia ixx="9.26988e-10" ixy="4.8503e-10"  ixz="2.09591e-13" iyy="1.48655e-09" iyz="-2.62533e-14" izz="1.76782e-09" />
		</inertial>
	</link>
	<joint name="wheel1_sub3" type="revolute">
		<origin xyz="-0.0142894 0.00825 0.0102056" rpy="3.14159 -6.52124e-09 -2.61799" />
		<parent link="horn4_2" />
		<child link="wheel1_sub11_1" />
		<axis xyz="-0.866025 0.5 0"/>
		<limit lower="-0.02" upper="0.10" effort="100" velocity="20" />
		<joint_properties friction="0.0"/>
	</joint>
	<link name="wheel1_sub8_1">
		<collision>
			<origin xyz="0.0534199 -0.0535157 0.032114" rpy="1.19954e-19 -2.86339e-20 9.81969e-18" />
			<geometry>
				<mesh filename="file://$(find jetbot_description)/urdf/jetbot_soccer/sub_wheel.stl"/>
			</geometry>
			<material name="sub_wheel_material">
				<color rgba="0.768627 0.886275 0.952941 1.0"/>
			</material>
		</collision>
		<visual>
			<origin xyz="0 0 0" rpy="0 -0 0" />
			<geometry>
				<mesh filename="file://$(find jetbot_description)/urdf/jetbot_soccer/wheel1_sub8_1.stl"/>
			</geometry>
			<material name="wheel1_sub8_1_material">
				<color rgba="0.768627 0.886275 0.952941 1.0"/>
			</material>
		</visual>
		<inertial>
			<origin xyz="3.67355e-05 -2.09868e-05 5.31199e-07" rpy="0 0 0"/>
			<mass value="9.9564e-05" />
			<inertia ixx="9.26988e-10" ixy="4.8503e-10"  ixz="2.09591e-13" iyy="1.48655e-09" iyz="-2.62533e-14" izz="1.76782e-09" />
		</inertial>
	</link>
	<joint name="wheel1_sub4" type="revolute">
		<origin xyz="-1.11022e-16 0.0165 0.0102056" rpy="-1.5708 0.523599 1.50893e-08" />
		<parent link="horn4_2" />
		<child link="wheel1_sub8_1" />
		<axis xyz="-0.866025 0.5 0"/>
		<limit lower="-0.02" upper="0.10" effort="100" velocity="20" />
		<joint_properties friction="0.0"/>
	</joint>
	<link name="wheel1_sub10_1">
		<collision>
			<origin xyz="0.0534199 -0.0535157 0.032114" rpy="7.80118e-17 4.64905e-17 -1.87475e-17" />
			<geometry>
				<mesh filename="file://$(find jetbot_description)/urdf/jetbot_soccer/sub_wheel.stl"/>
			</geometry>
			<material name="sub_wheel_material">
				<color rgba="0.768627 0.886275 0.952941 1.0"/>
			</material>
		</collision>
		<visual>
			<origin xyz="0 0 0" rpy="0 -0 0" />
			<geometry>
				<mesh filename="file://$(find jetbot_description)/urdf/jetbot_soccer/wheel1_sub10_1.stl"/>
			</geometry>
			<material name="wheel1_sub10_1_material">
				<color rgba="0.768627 0.886275 0.952941 1.0"/>
			</material>
		</visual>
		<inertial>
			<origin xyz="3.67355e-05 -2.09868e-05 5.31199e-07" rpy="0 0 0"/>
			<mass value="9.9564e-05" />
			<inertia ixx="9.26988e-10" ixy="4.8503e-10"  ixz="2.09591e-13" iyy="1.48655e-09" iyz="-2.62533e-14" izz="1.76782e-09" />
		</inertial>
	</link>
	<joint name="wheel1_sub5" type="revolute">
		<origin xyz="-0.00825 0.0142894 0.0189056" rpy="1.95889e-08 -1.13097e-08 1.0472" />
		<parent link="horn4_2" />
		<child link="wheel1_sub10_1" />
		<axis xyz="-0.866025 0.5 0"/>
		<limit lower="-0.02" upper="0.10" effort="100" velocity="20" />
		<joint_properties friction="0.0"/>
	</joint>
	<link name="wheel1_sub9_1">
		<collision>
			<origin xyz="0.0534199 -0.0535157 0.032114" rpy="2.04759e-17 3.37381e-17 -2.04905e-17" />
			<geometry>
				<mesh filename="file://$(find jetbot_description)/urdf/jetbot_soccer/sub_wheel.stl"/>
			</geometry>
			<material name="sub_wheel_material">
				<color rgba="0.768627 0.886275 0.952941 1.0"/>
			</material>
		</collision>
		<visual>
			<origin xyz="0 0 0" rpy="0 -0 0" />
			<geometry>
				<mesh filename="file://$(find jetbot_description)/urdf/jetbot_soccer/wheel1_sub9_1.stl"/>
			</geometry>
			<material name="wheel1_sub9_1_material">
				<color rgba="0.768627 0.886275 0.952941 1.0"/>
			</material>
		</visual>
		<inertial>
			<origin xyz="3.67355e-05 -2.09868e-05 5.31199e-07" rpy="0 0 0"/>
			<mass value="9.9564e-05" />
			<inertia ixx="9.26988e-10" ixy="4.8503e-10"  ixz="2.09591e-13" iyy="1.48655e-09" iyz="-2.62533e-14" izz="1.76782e-09" />
		</inertial>
	</link>
	<joint name="wheel1_sub6" type="revolute">
		<origin xyz="-0.00825 -0.0142894 0.0189056" rpy="-1.5708 0.523599 -0.523599" />
		<parent link="horn4_2" />
		<child link="wheel1_sub9_1" />
		<axis xyz="-0.866025 0.5 0"/>
		<limit lower="-0.02" upper="0.10" effort="100" velocity="20" />
		<joint_properties friction="0.0"/>
	</joint>
	<link name="wheel1_sub4_1">
		<collision>
			<origin xyz="0.0534199 -0.0535157 0.032114" rpy="1.59031e-17 6.23138e-17 3.448e-17" />
			<geometry>
				<mesh filename="file://$(find jetbot_description)/urdf/jetbot_soccer/sub_wheel.stl"/>
			</geometry>
			<material name="sub_wheel_material">
				<color rgba="0.768627 0.886275 0.952941 1.0"/>
			</material>
		</collision>
		<visual>
			<origin xyz="0 0 0" rpy="0 -0 0" />
			<geometry>
				<mesh filename="file://$(find jetbot_description)/urdf/jetbot_soccer/wheel1_sub4_1.stl"/>
			</geometry>
			<material name="wheel1_sub4_1_material">
				<color rgba="0.768627 0.886275 0.952941 1.0"/>
			</material>
		</visual>
		<inertial>
			<origin xyz="3.67355e-05 -2.09868e-05 5.31199e-07" rpy="0 0 0"/>
			<mass value="9.9564e-05" />
			<inertia ixx="9.26988e-10" ixy="4.8503e-10"  ixz="2.09591e-13" iyy="1.48655e-09" iyz="-2.62533e-14" izz="1.76782e-09" />
		</inertial>
	</link>
	<joint name="wheel1_sub7" type="revolute">
		<origin xyz="0.00825 -0.0142894 0.0189056" rpy="-1.5708 0.523599 0.523599" />
		<parent link="horn4_2" />
		<child link="wheel1_sub4_1" />
		<axis xyz="-0.866025 0.5 0"/>
		<limit lower="-0.02" upper="0.10" effort="100" velocity="20" />
		<joint_properties friction="0.0"/>
	</joint>
	<link name="wheel1_sub1_1">
		<collision>
			<origin xyz="0.0534199 -0.0535157 0.032114" rpy="5.0812e-17 -3.48911e-17 -5.93399e-17" />
			<geometry>
				<mesh filename="file://$(find jetbot_description)/urdf/jetbot_soccer/sub_wheel.stl"/>
			</geometry>
			<material name="sub_wheel_material">
				<color rgba="0.768627 0.886275 0.952941 1.0"/>
			</material>
		</collision>
		<visual>
			<origin xyz="0 0 0" rpy="0 -0 0" />
			<geometry>
				<mesh filename="file://$(find jetbot_description)/urdf/jetbot_soccer/wheel1_sub1_1.stl"/>
			</geometry>
			<material name="wheel1_sub1_1_material">
				<color rgba="0.768627 0.886275 0.952941 1.0"/>
			</material>
		</visual>
		<inertial>
			<origin xyz="3.67355e-05 -2.09868e-05 5.31199e-07" rpy="0 0 0"/>
			<mass value="9.9564e-05" />
			<inertia ixx="9.26988e-10" ixy="4.8503e-10"  ixz="2.09591e-13" iyy="1.48655e-09" iyz="-2.62533e-14" izz="1.76782e-09" />
		</inertial>
	</link>
	<joint name="wheel1_sub8" type="revolute">
		<origin xyz="-0.0165 2.77556e-17 0.0189056" rpy="-3.14159 1.45691e-11 -2.0944" />
		<parent link="horn4_2" />
		<child link="wheel1_sub1_1" />
		<axis xyz="-0.866025 0.5 0"/>
		<limit lower="-0.02" upper="0.10" effort="100" velocity="20" />
		<joint_properties friction="0.0"/>
	</joint>
	<link name="wheel1_sub12_1">
		<collision>
			<origin xyz="0.0534199 -0.0535157 0.032114" rpy="-4.59191e-17 6.71012e-18 -3.00458e-18" />
			<geometry>
				<mesh filename="file://$(find jetbot_description)/urdf/jetbot_soccer/sub_wheel.stl"/>
			</geometry>
			<material name="sub_wheel_material">
				<color rgba="0.768627 0.886275 0.952941 1.0"/>
			</material>
		</collision>
		<visual>
			<origin xyz="0 0 0" rpy="0 -0 0" />
			<geometry>
				<mesh filename="file://$(find jetbot_description)/urdf/jetbot_soccer/wheel1_sub12_1.stl"/>
			</geometry>
			<material name="wheel1_sub12_1_material">
				<color rgba="0.768627 0.886275 0.952941 1.0"/>
			</material>
		</visual>
		<inertial>
			<origin xyz="3.67355e-05 -2.09868e-05 5.31199e-07" rpy="0 0 0"/>
			<mass value="9.9564e-05" />
			<inertia ixx="9.26988e-10" ixy="4.8503e-10"  ixz="2.09591e-13" iyy="1.48655e-09" iyz="-2.62533e-14" izz="1.76782e-09" />
		</inertial>
	</link>
	<joint name="wheel1_sub9" type="revolute">
		<origin xyz="0.00825 0.0142894 0.0189056" rpy="-1.5708 0.523599 -0.523599" />
		<parent link="horn4_2" />
		<child link="wheel1_sub12_1" />
		<axis xyz="-0.866025 0.5 0"/>
		<limit lower="-0.02" upper="0.10" effort="100" velocity="20" />
		<joint_properties friction="0.0"/>
	</joint>
	<link name="wheel1_sub6_1">
		<collision>
			<origin xyz="0.0534199 -0.0535157 0.032114" rpy="-6.3062e-17 1.57722e-17 1.02964e-16" />
			<geometry>
				<mesh filename="file://$(find jetbot_description)/urdf/jetbot_soccer/sub_wheel.stl"/>
			</geometry>
			<material name="sub_wheel_material">
				<color rgba="0.768627 0.886275 0.952941 1.0"/>
			</material>
		</collision>
		<visual>
			<origin xyz="0 0 0" rpy="0 -0 0" />
			<geometry>
				<mesh filename="file://$(find jetbot_description)/urdf/jetbot_soccer/wheel1_sub6_1.stl"/>
			</geometry>
			<material name="wheel1_sub6_1_material">
				<color rgba="0.768627 0.886275 0.952941 1.0"/>
			</material>
		</visual>
		<inertial>
			<origin xyz="3.67355e-05 -2.09868e-05 5.31199e-07" rpy="0 0 0"/>
			<mass value="9.9564e-05" />
			<inertia ixx="9.26988e-10" ixy="4.8503e-10"  ixz="2.09591e-13" iyy="1.48655e-09" iyz="-2.62533e-14" izz="1.76782e-09" />
		</inertial>
	</link>
	<joint name="wheel1_sub10" type="revolute">
		<origin xyz="0.0165 -8.32667e-17 0.0189056" rpy="-2.52436e-11 1.4584e-11 2.0944" />
		<parent link="horn4_2" />
		<child link="wheel1_sub6_1" />
		<axis xyz="-0.866025 0.5 0"/>
		<limit lower="-0.02" upper="0.10" effort="100" velocity="20" />
		<joint_properties friction="0.0"/>
	</joint>
	<link name="wheel1_sub5_1">
		<collision>
			<origin xyz="0.0534199 -0.0535157 0.032114" rpy="1.73039e-17 -3.36201e-17 3.55887e-17" />
			<geometry>
				<mesh filename="file://$(find jetbot_description)/urdf/jetbot_soccer/sub_wheel.stl"/>
			</geometry>
			<material name="sub_wheel_material">
				<color rgba="0.768627 0.886275 0.952941 1.0"/>
			</material>
		</collision>
		<visual>
			<origin xyz="0 0 0" rpy="0 -0 0" />
			<geometry>
				<mesh filename="file://$(find jetbot_description)/urdf/jetbot_soccer/wheel1_sub5_1.stl"/>
			</geometry>
			<material name="wheel1_sub5_1_material">
				<color rgba="0.768627 0.886275 0.952941 1.0"/>
			</material>
		</visual>
		<inertial>
			<origin xyz="3.67355e-05 -2.09868e-05 5.31199e-07" rpy="0 0 0"/>
			<mass value="9.9564e-05" />
			<inertia ixx="9.26988e-10" ixy="4.8503e-10"  ixz="2.09591e-13" iyy="1.48655e-09" iyz="-2.62533e-14" izz="1.76782e-09" />
		</inertial>
	</link>
	<joint name="wheel1_sub11" type="revolute">
		<origin xyz="0.0142894 -0.00825 0.0102056" rpy="-3.14159 6.52124e-09 0.523599" />
		<parent link="horn4_2" />
		<child link="wheel1_sub5_1" />
		<axis xyz="-0.866025 0.5 0"/>
		<limit lower="-0.02" upper="0.10" effort="100" velocity="20" />
		<joint_properties friction="0.0"/>
	</joint>
	<link name="wheel1_sub2_1">
		<collision>
			<origin xyz="0.0534199 -0.0535157 0.032114" rpy="1.90961e-17 -4.13764e-20 8.25728e-20" />
			<geometry>
				<mesh filename="file://$(find jetbot_description)/urdf/jetbot_soccer/sub_wheel.stl"/>
			</geometry>
			<material name="sub_wheel_material">
				<color rgba="0.768627 0.886275 0.952941 1.0"/>
			</material>
		</collision>
		<visual>
			<origin xyz="0 0 0" rpy="0 -0 0" />
			<geometry>
				<mesh filename="file://$(find jetbot_description)/urdf/jetbot_soccer/wheel1_sub2_1.stl"/>
			</geometry>
			<material name="wheel1_sub2_1_material">
				<color rgba="0.768627 0.886275 0.952941 1.0"/>
			</material>
		</visual>
		<inertial>
			<origin xyz="3.67355e-05 -2.09868e-05 5.31199e-07" rpy="0 0 0"/>
			<mass value="9.9564e-05" />
			<inertia ixx="9.26988e-10" ixy="4.8503e-10"  ixz="2.09591e-13" iyy="1.48655e-09" iyz="-2.62533e-14" izz="1.76782e-09" />
		</inertial>
	</link>
	<joint name="wheel1_sub12" type="revolute">
		<origin xyz="0.0142894 0.00825 0.0102056" rpy="-3.14159 6.54647e-09 -1.5708" />
		<parent link="horn4_2" />
		<child link="wheel1_sub2_1" />
		<axis xyz="-0.866025 0.5 0"/>
		<limit lower="-0.02" upper="0.10" effort="100" velocity="20" />
		<joint_properties friction="0.0"/>
	</joint>
	<joint name="wheel2" type="revolute">
		<origin xyz="-0.345274 -0.21712 -0.143861" rpy="1.5708 -0.00111608 -2.05776" />
		<parent link="body_1" />
		<child link="horn4_2" />
		<axis xyz="0 0 -1"/>
		<limit lower="-0.02" upper="0.10" effort="100" velocity="20" />
		<joint_properties friction="0.0"/>
	</joint>
	<link name="roller_stick_1">
		<collision>
			<origin xyz="-0.04445 -0.29536 -0.137105" rpy="2.90963e-22 -7.94868e-24 -4.68924e-18" />
			<geometry>
				<mesh filename="file://$(find jetbot_description)/urdf/jetbot_soccer/solenoid_stick.stl"/>
			</geometry>
			<material name="solenoid_stick_material">
				<color rgba="0.972549 0.529412 0.00392157 1.0"/>
			</material>
		</collision>
		<visual>
			<origin xyz="0 0 0" rpy="0 -0 0" />
			<geometry>
				<mesh filename="file://$(find jetbot_description)/urdf/jetbot_soccer/roller_stick_1.stl"/>
			</geometry>
			<material name="roller_stick_1_material">
				<color rgba="0.972549 0.529412 0.00392157 1.0"/>
			</material>
		</visual>
		<inertial>
			<origin xyz="-6.93889e-18 -2.08515e-19 -2.77556e-17" rpy="0 0 0"/>
			<mass value="0.0115774" />
			<inertia ixx="1.72634e-07" ixy="-3.47366e-23"  ixz="6.38012e-29" iyy="7.7112e-06" iyz="-2.15544e-27" izz="7.7112e-06" />
		</inertial>
	</link>
	<joint name="stick" type="prismatic">
		<origin xyz="-0.286122 -0.271696 -0.136153" rpy="-5.12956e-06 9.95073e-08 -1.534" />
		<parent link="body_1" />
		<child link="roller_stick_1" />
		<axis xyz="-1 0 0"/>
		<limit lower="-0.02" upper="0.10" effort="100" velocity="20" />
		<joint_properties friction="0.0"/>
	</joint>
	<link name="jetson_nano_board_1">
		<collision>
			<origin xyz="-0.251541 -0.295929 -0.0510866" rpy="3.14159 -9.45786e-08 -3.09132" />
			<geometry>
				<mesh filename="file://$(find jetbot_description)/urdf/jetbot_soccer/jetson_nano_board.stl"/>
			</geometry>
			<material name="jetson_nano_board_material">
				<color rgba="0.470588 0.470588 0.470588 1.0"/>
			</material>
		</collision>
		<visual>
			<origin xyz="0 0 0" rpy="0 -0 0" />
			<geometry>
				<mesh filename="file://$(find jetbot_description)/urdf/jetbot_soccer/jetson_nano_board_1.stl"/>
			</geometry>
			<material name="jetson_nano_board_1_material">
				<color rgba="0.470588 0.470588 0.470588 1.0"/>
			</material>
		</visual>
		<inertial>
			<origin xyz="-0.296144 -0.267738 -0.0602462" rpy="0 0 0"/>
			<mass value="0.313249" />
			<inertia ixx="0.000144213" ixy="9.11453e-06"  ixz="7.10396e-07" iyy="0.000199833" iyz="2.02698e-05" izz="0.000304634" />
		</inertial>
	</link>
	<joint name="28a6cca5-4289-4e64-b4d8-c50c4cd05862_fixing" type="fixed">
		<origin xyz="0 0 0" rpy="0 -0 0" />
		<parent link="body_1" />
		<child link="jetson_nano_board_1" />
		<axis xyz="0 0 1"/>
		<limit lower="-0.02" upper="0.10" effort="100" velocity="20" />
		<joint_properties friction="0.0"/>
	</joint>
	<link name="antenna_1">
		<collision>
			<origin xyz="-0.276459 -0.273576 -0.0485466" rpy="1.5708 -9.72302e-08 1.58414" />
			<geometry>
				<mesh filename="file://$(find jetbot_description)/urdf/jetbot_soccer/antenna_hub.step.stl"/>
			</geometry>
			<material name="antenna_hub.step_material">
				<color rgba="0.666667 0.694118 0.764706 1.0"/>
			</material>
		</collision>
		<collision>
			<origin xyz="-0.276919 -0.27358 -0.0485466" rpy="1.5708 -9.72302e-08 1.58414" />
			<geometry>
				<mesh filename="file://$(find jetbot_description)/urdf/jetbot_soccer/antennae.step.stl"/>
			</geometry>
			<material name="antennae.step_material">
				<color rgba="0.109804 0.109804 0.109804 1.0"/>
			</material>
		</collision>
		<visual>
			<origin xyz="0 0 0" rpy="0 -0 0" />
			<geometry>
				<mesh filename="file://$(find jetbot_description)/urdf/jetbot_soccer/antenna_1.stl"/>
			</geometry>
			<material name="antenna_1_material">
				<color rgba="0.231213 0.237197 0.252587 1.0"/>
			</material>
		</visual>
		<inertial>
			<origin xyz="-0.238595 -0.215152 0.0264879" rpy="0 0 0"/>
			<mass value="0.0230466" />
			<inertia ixx="2.4591e-05" ixy="-7.54169e-10"  ixz="-4.40646e-07" iyy="5.96118e-05" iyz="1.75881e-08" izz="3.54165e-05" />
		</inertial>
	</link>
	<joint name="5636c7c4-d6d9-48d4-ba43-82af95ef5ff5_fixing" type="fixed">
		<origin xyz="0 0 0" rpy="0 -0 0" />
		<parent link="body_1" />
		<child link="antenna_1" />
		<axis xyz="0 0 1"/>
		<limit lower="-0.02" upper="0.10" effort="100" velocity="20" />
		<joint_properties friction="0.0"/>
	</joint>
	<link name="antenna_2">
		<collision>
			<origin xyz="-0.374025 -0.274324 -0.0485466" rpy="1.5708 -9.72302e-08 1.58414" />
			<geometry>
				<mesh filename="file://$(find jetbot_description)/urdf/jetbot_soccer/antenna_hub.step.stl"/>
			</geometry>
			<material name="antenna_hub.step_material">
				<color rgba="0.666667 0.694118 0.764706 1.0"/>
			</material>
		</collision>
		<collision>
			<origin xyz="-0.374485 -0.274328 -0.0485466" rpy="1.5708 -9.72302e-08 1.58414" />
			<geometry>
				<mesh filename="file://$(find jetbot_description)/urdf/jetbot_soccer/antennae.step.stl"/>
			</geometry>
			<material name="antennae.step_material">
				<color rgba="0.109804 0.109804 0.109804 1.0"/>
			</material>
		</collision>
		<visual>
			<origin xyz="0 0 0" rpy="0 -0 0" />
			<geometry>
				<mesh filename="file://$(find jetbot_description)/urdf/jetbot_soccer/antenna_2.stl"/>
			</geometry>
			<material name="antenna_2_material">
				<color rgba="0.231213 0.237197 0.252587 1.0"/>
			</material>
		</visual>
		<inertial>
			<origin xyz="-0.336162 -0.2159 0.026488" rpy="0 0 0"/>
			<mass value="0.0230466" />
			<inertia ixx="2.4591e-05" ixy="-7.54169e-10"  ixz="-4.40646e-07" iyy="5.96118e-05" iyz="1.75881e-08" izz="3.54165e-05" />
		</inertial>
	</link>
	<joint name="b5fa963e-5c41-4bbc-bc2c-582118eb1811_fixing" type="fixed">
		<origin xyz="0 0 0" rpy="0 -0 0" />
		<parent link="body_1" />
		<child link="antenna_2" />
		<axis xyz="0 0 1"/>
		<limit lower="-0.02" upper="0.10" effort="100" velocity="20" />
		<joint_properties friction="0.0"/>
	</joint>
	<link name="jetbot_mainboard_1">
		<collision>
			<origin xyz="-0.286678 -0.27202 -0.0525466" rpy="1.5708 -9.50057e-08 -3.09557" />
			<geometry>
				<mesh filename="file://$(find jetbot_description)/urdf/jetbot_soccer/____.step.stl"/>
			</geometry>
			<material name="____.step_material">
				<color rgba="0.196078 0.207843 0.262745 1.0"/>
			</material>
		</collision>
		<collision>
			<origin xyz="-0.286678 -0.27202 -0.0525466" rpy="1.5708 -9.50057e-08 -3.09557" />
			<geometry>
				<mesh filename="file://$(find jetbot_description)/urdf/jetbot_soccer/____.step.stl"/>
			</geometry>
			<material name="____.step_material">
				<color rgba="0.788235 0.788235 0.788235 1.0"/>
			</material>
		</collision>
		<collision>
			<origin xyz="-0.286678 -0.27202 -0.0525466" rpy="1.5708 -9.50057e-08 -3.09557" />
			<geometry>
				<mesh filename="file://$(find jetbot_description)/urdf/jetbot_soccer/____.step.stl"/>
			</geometry>
			<material name="____.step_material">
				<color rgba="0.196078 0.207843 0.262745 1.0"/>
			</material>
		</collision>
		<collision>
			<origin xyz="-0.286678 -0.27202 -0.0525466" rpy="1.5708 -9.50057e-08 -3.09557" />
			<geometry>
				<mesh filename="file://$(find jetbot_description)/urdf/jetbot_soccer/____.step.stl"/>
			</geometry>
			<material name="____.step_material">
				<color rgba="0.788235 0.788235 0.788235 1.0"/>
			</material>
		</collision>
		<collision>
			<origin xyz="-0.286678 -0.27202 -0.0525466" rpy="1.5708 -9.50057e-08 -3.09557" />
			<geometry>
				<mesh filename="file://$(find jetbot_description)/urdf/jetbot_soccer/pcb.step.stl"/>
			</geometry>
			<material name="pcb.step_material">
				<color rgba="0.298039 0.298039 0.298039 1.0"/>
			</material>
		</collision>
		<collision>
			<origin xyz="-0.286678 -0.27202 -0.0525466" rpy="1.5708 -9.50057e-08 -3.09557" />
			<geometry>
				<mesh filename="file://$(find jetbot_description)/urdf/jetbot_soccer/____.step.stl"/>
			</geometry>
			<material name="____.step_material">
				<color rgba="0.788235 0.788235 0.788235 1.0"/>
			</material>
		</collision>
		<collision>
			<origin xyz="-0.286678 -0.27202 -0.0525466" rpy="1.5708 -9.50057e-08 -3.09557" />
			<geometry>
				<mesh filename="file://$(find jetbot_description)/urdf/jetbot_soccer/____.step.stl"/>
			</geometry>
			<material name="____.step_material">
				<color rgba="0.788235 0.788235 0.788235 1.0"/>
			</material>
		</collision>
		<collision>
			<origin xyz="-0.286678 -0.27202 -0.0525466" rpy="1.5708 -9.50057e-08 -3.09557" />
			<geometry>
				<mesh filename="file://$(find jetbot_description)/urdf/jetbot_soccer/pcb.step.stl"/>
			</geometry>
			<material name="pcb.step_material">
				<color rgba="0.792157 0.792157 0.792157 1.0"/>
			</material>
		</collision>
		<collision>
			<origin xyz="-0.286678 -0.27202 -0.0525466" rpy="1.5708 -9.50057e-08 -3.09557" />
			<geometry>
				<mesh filename="file://$(find jetbot_description)/urdf/jetbot_soccer/______.step.stl"/>
			</geometry>
			<material name="______.step_material">
				<color rgba="1 1 1 1.0"/>
			</material>
		</collision>
		<collision>
			<origin xyz="-0.286678 -0.27202 -0.0525466" rpy="1.5708 -9.50057e-08 -3.09557" />
			<geometry>
				<mesh filename="file://$(find jetbot_description)/urdf/jetbot_soccer/____.step.stl"/>
			</geometry>
			<material name="____.step_material">
				<color rgba="0.784314 0.784314 0.784314 1.0"/>
			</material>
		</collision>
		<collision>
			<origin xyz="-0.286678 -0.27202 -0.0525466" rpy="1.5708 -9.50057e-08 -3.09557" />
			<geometry>
				<mesh filename="file://$(find jetbot_description)/urdf/jetbot_soccer/____.step.stl"/>
			</geometry>
			<material name="____.step_material">
				<color rgba="0.788235 0.788235 0.788235 1.0"/>
			</material>
		</collision>
		<collision>
			<origin xyz="-0.286678 -0.27202 -0.0525466" rpy="1.5708 -9.50057e-08 -3.09557" />
			<geometry>
				<mesh filename="file://$(find jetbot_description)/urdf/jetbot_soccer/12v.step.stl"/>
			</geometry>
			<material name="12v.step_material">
				<color rgba="0.054902 0.054902 0.054902 1.0"/>
			</material>
		</collision>
		<collision>
			<origin xyz="-0.286678 -0.27202 -0.0525466" rpy="1.5708 -9.50057e-08 -3.09557" />
			<geometry>
				<mesh filename="file://$(find jetbot_description)/urdf/jetbot_soccer/pcb.step.stl"/>
			</geometry>
			<material name="pcb.step_material">
				<color rgba="0.792157 0.792157 0.792157 1.0"/>
			</material>
		</collision>
		<collision>
			<origin xyz="-0.286678 -0.27202 -0.0525466" rpy="1.5708 -9.50057e-08 -3.09557" />
			<geometry>
				<mesh filename="file://$(find jetbot_description)/urdf/jetbot_soccer/____.step.stl"/>
			</geometry>
			<material name="____.step_material">
				<color rgba="0.788235 0.788235 0.788235 1.0"/>
			</material>
		</collision>
		<collision>
			<origin xyz="-0.286678 -0.27202 -0.0525466" rpy="1.5708 -9.50057e-08 -3.09557" />
			<geometry>
				<mesh filename="file://$(find jetbot_description)/urdf/jetbot_soccer/1.14_tft_ips_-_13p_-_reverse_mount.step.stl"/>
			</geometry>
			<material name="1.14_tft_ips_-_13p_-_reverse_mount.step_material">
				<color rgba="1 1 1 1.0"/>
			</material>
		</collision>
		<visual>
			<origin xyz="0 0 0" rpy="0 -0 0" />
			<geometry>
				<mesh filename="file://$(find jetbot_description)/urdf/jetbot_soccer/jetbot_mainboard_1.stl"/>
			</geometry>
			<material name="jetbot_mainboard_1_material">
				<color rgba="0.662744 0.662751 0.662788 1.0"/>
			</material>
		</visual>
		<inertial>
			<origin xyz="-0.289045 -0.272693 -0.0446533" rpy="0 0 0"/>
			<mass value="0.050638" />
			<inertia ixx="3.13809e-05" ixy="-9.87308e-07"  ixz="-1.68428e-06" iyy="4.15679e-05" iyz="2.17178e-08" izz="7.02134e-05" />
		</inertial>
	</link>
	<joint name="1623da3d-7a3b-4284-aeff-267caa8f09d1_fixing" type="fixed">
		<origin xyz="0 0 0" rpy="0 -0 0" />
		<parent link="body_1" />
		<child link="jetbot_mainboard_1" />
		<axis xyz="0 0 1"/>
		<limit lower="-0.02" upper="0.10" effort="100" velocity="20" />
		<joint_properties friction="0.0"/>
	</joint>
	<link name="camera_holder_1">
		<collision>
			<origin xyz="-0.284452 0.00369129 -0.0485466" rpy="-9.45786e-08 1.00791e-07 -1.52052" />
			<geometry>
				<mesh filename="file://$(find jetbot_description)/urdf/jetbot_soccer/camera_holder.stl"/>
			</geometry>
			<material name="camera_holder_material">
				<color rgba="0.498039 0.498039 0.498039 1.0"/>
			</material>
		</collision>
		<visual>
			<origin xyz="0 0 0" rpy="0 -0 0" />
			<geometry>
				<mesh filename="file://$(find jetbot_description)/urdf/jetbot_soccer/camera_holder_1.stl"/>
			</geometry>
			<material name="camera_holder_1_material">
				<color rgba="0.498039 0.498039 0.498039 1.0"/>
			</material>
		</visual>
		<inertial>
			<origin xyz="-0.285689 -0.337991 -0.0422618" rpy="0 0 0"/>
			<mass value="0.00309401" />
			<inertia ixx="3.40706e-07" ixy="6.19345e-09"  ixz="-7.30947e-09" iyy="4.84187e-07" iyz="-1.23852e-07" izz="4.68613e-07" />
		</inertial>
	</link>
	<link name="rspcameramia_1">
		<collision>
			<origin xyz="-0.285512 -0.344894 -0.0370628" rpy="3.14159 -1.34625 -1.52052" />
			<geometry>
				<mesh filename="file://$(find jetbot_description)/urdf/jetbot_soccer/picamerapcb.stl"/>
			</geometry>
			<material name="picamerapcb_material">
				<color rgba="0 0.517647 0 1.0"/>
			</material>
		</collision>
		<collision>
			<origin xyz="-0.285078 -0.351283 -0.0358091" rpy="-1.5708 1.34625 1.62107" />
			<geometry>
				<mesh filename="file://$(find jetbot_description)/urdf/jetbot_soccer/ova5647_lens_fov.stl"/>
			</geometry>
			<material name="ova5647_lens_fov_material">
				<color rgba="0 0 0 1.0"/>
			</material>
		</collision>
		<collision>
			<origin xyz="-0.285327 -0.346451 -0.0347049" rpy="-1.5708 1.34625 1.62107" />
			<geometry>
				<mesh filename="file://$(find jetbot_description)/urdf/jetbot_soccer/ova5647_housing.stl"/>
			</geometry>
			<material name="ova5647_housing_material">
				<color rgba="0.74902 0.74902 0.74902 1.0"/>
			</material>
		</collision>
		<collision>
			<origin xyz="-0.285029 -0.346859 -0.0347267" rpy="-2.91705 9.45786e-08 0.0502736" />
			<geometry>
				<mesh filename="file://$(find jetbot_description)/urdf/jetbot_soccer/ribbon_cam.stl"/>
			</geometry>
			<material name="ribbon_cam_material">
				<color rgba="1 0.945098 0.694118 1.0"/>
			</material>
		</collision>
		<visual>
			<origin xyz="0 0 0" rpy="0 -0 0" />
			<geometry>
				<mesh filename="file://$(find jetbot_description)/urdf/jetbot_soccer/rspcameramia_1.stl"/>
			</geometry>
			<material name="rspcameramia_1_material">
				<color rgba="0.116168 0.499506 0.115092 1.0"/>
			</material>
		</visual>
		<inertial>
			<origin xyz="-0.285321 -0.346426 -0.036476" rpy="0 0 0"/>
			<mass value="0.00106392" />
			<inertia ixx="7.88407e-08" ixy="-1.1471e-10"  ixz="-8.40461e-09" iyy="4.18615e-08" iyz="1.07649e-09" izz="4.36329e-08" />
		</inertial>
	</link>
	<joint name="af31a009-280f-45a6-bd50-7597af53eaaa_fixing" type="fixed">
		<origin xyz="0 0 0" rpy="0 -0 0" />
		<parent link="camera_holder_1" />
		<child link="rspcameramia_1" />
		<axis xyz="0 0 1"/>
		<limit lower="-0.02" upper="0.10" effort="100" velocity="20" />
		<joint_properties friction="0.0"/>
	</joint>
	<joint name="1ba92857-bc40-4050-bedd-c0c48935edbe_fixing" type="fixed">
		<origin xyz="0 0 0" rpy="0 -0 0" />
		<parent link="body_1" />
		<child link="camera_holder_1" />
		<axis xyz="0 0 1"/>
		<limit lower="-0.02" upper="0.10" effort="100" velocity="20" />
		<joint_properties friction="0.0"/>
	</joint>
	<link name="ir_sensor_1">
		<collision>
			<origin xyz="-0.321974 -0.320317 -0.118627" rpy="-3.81895e-08 -1.32836e-07 2.65463" />
			<geometry>
				<mesh filename="file://$(find jetbot_description)/urdf/jetbot_soccer/part_1.stl"/>
			</geometry>
			<material name="part_1_material">
				<color rgba="0.792157 0.819608 0.933333 1.0"/>
			</material>
		</collision>
		<visual>
			<origin xyz="0 0 0" rpy="0 -0 0" />
			<geometry>
				<mesh filename="file://$(find jetbot_description)/urdf/jetbot_soccer/ir_sensor_1.stl"/>
			</geometry>
			<material name="ir_sensor_1_material">
				<color rgba="0.25098 0.25098 0.25098 1.0"/>
			</material>
		</visual>
		<inertial>
			<origin xyz="0 0 0" rpy="0 0 0"/>
			<mass value="0.001" />
			<inertia ixx="0" ixy="0"  ixz="0" iyy="0" iyz="0" izz="0" />
		</inertial>
	</link>
	<joint name="a981a5f9-1268-400b-8b22-48f8be010698_fixing" type="fixed">
		<origin xyz="0 0 0" rpy="0 -0 0" />
		<parent link="body_1" />
		<child link="ir_sensor_1" />
		<axis xyz="0 0 1"/>
		<limit lower="-0.02" upper="0.10" effort="100" velocity="20" />
		<joint_properties friction="0.0"/>
	</joint>
	<link name="lidar_frame_1">
		<collision>
			<origin xyz="-0.510243 -0.233537 -0.0836266" rpy="-9.70802e-08 9.83834e-08 -1.54564" />
			<geometry>
				<mesh filename="file://$(find jetbot_description)/urdf/jetbot_soccer/part_13.stl"/>
			</geometry>
			<material name="part_13_material">
				<color rgba="0.980392 0.713725 0.00392157 1.0"/>
			</material>
		</collision>
		<visual>
			<origin xyz="0 0 0" rpy="0 -0 0" />
			<geometry>
				<mesh filename="file://$(find jetbot_description)/urdf/jetbot_soccer/lidar_frame_1.stl"/>
			</geometry>
			<material name="lidar_frame_1_material">
				<color rgba="0.25098 0.25098 0.25098 1.0"/>
			</material>
		</visual>
		<inertial>
			<origin xyz="0 0 0" rpy="0 0 0"/>
			<mass value="0.001" />
			<inertia ixx="0" ixy="0"  ixz="0" iyy="0" iyz="0" izz="0" />
		</inertial>
	</link>
	<link name="lidar_sensor_1">
		<collision>
			<origin xyz="-0.284346 -0.34215 -0.0719386" rpy="3.14159 -9.70802e-08 -3.11644" />
			<geometry>
				<mesh filename="file://$(find jetbot_description)/urdf/jetbot_soccer/part_1.stl"/>
			</geometry>
			<material name="part_1_material">
				<color rgba="0.25098 0.25098 0.25098 1.0"/>
			</material>
		</collision>
		<visual>
			<origin xyz="0 0 0" rpy="0 -0 0" />
			<geometry>
				<mesh filename="file://$(find jetbot_description)/urdf/jetbot_soccer/lidar_sensor_1.stl"/>
			</geometry>
			<material name="lidar_sensor_1_material">
				<color rgba="0.25098 0.25098 0.25098 1.0"/>
			</material>
		</visual>
		<inertial>
			<origin xyz="0 0 0" rpy="0 0 0"/>
			<mass value="0.001" />
			<inertia ixx="0" ixy="0"  ixz="0" iyy="0" iyz="0" izz="0" />
		</inertial>
	</link>
	<joint name="63f7070b-6a81-4c88-b8bb-c1db0c9fc58f_fixing" type="fixed">
		<origin xyz="0 0 0" rpy="0 -0 0" />
		<parent link="lidar_frame_1" />
		<child link="lidar_sensor_1" />
		<axis xyz="0 0 1"/>
		<limit lower="-0.02" upper="0.10" effort="100" velocity="20" />
		<joint_properties friction="0.0"/>
	</joint>
	<joint name="e293418b-2a63-4571-a683-167c5e99a2ae_fixing" type="fixed">
		<origin xyz="0 0 0" rpy="0 -0 0" />
		<parent link="body_1" />
		<child link="lidar_frame_1" />
		<axis xyz="0 0 1"/>
		<limit lower="-0.02" upper="0.10" effort="100" velocity="20" />
		<joint_properties friction="0.0"/>
	</joint>
</robot>
