<?xml version="1.0"?>
<robot name="jetbot" xmlns:xacro="http://www.ros.org/wiki/xacro">
    <xacro:include filename="$(find jetbot_description)/urdf/jetbot.gazebo" />
    <xacro:property name="follow_wheel_radius" value="0.0135"/>
    <xacro:property name="follow_wheel_length" value="0.011"/>
    <xacro:property name="follow_wheel_mass" value="0.66"/>
    <xacro:macro name="cylinder_inertial" params="radius length mass *origin">
      <inertial>
        <mass value="${mass}" />
        <xacro:insert_block name="origin" />
        <inertia ixx="${0.0833333 * mass * (3 * radius * radius + length * length)}" ixy="0.0" ixz="0.0"
          iyy="${0.0833333 * mass * (3 * radius * radius + length * length)}" iyz="0.0"
          izz="${0.5 * mass * radius * radius}" />
      </inertial>
    </xacro:macro>
   

    <link name="chassis">
      <inertial>
        <origin rpy="1.57079632679 0.0 1.57079632679" xyz="0.0 0.0 0.086"/>
        <mass value="50"/>
        <inertia ixx="0"  ixy="0"  ixz="0" iyy="0" iyz="0" izz="0" />
      </inertial>

      <collision>
        <origin rpy="1.57079632679 0.0 1.57079632679" xyz="0.0 0.0 0.086"/>
        <geometry>
          <mesh filename="file://$(find jetbot_description)/urdf/jetbot/meshes/JetBot-v3-Chassis.dae" scale="0.002 0.002 0.002"/>
        </geometry>
      </collision>

      <visual>
        <origin rpy="1.57079632679 0.0 1.57079632679" xyz="0.0 0.0 0.086"/>
        <geometry>
          <mesh filename="file://$(find jetbot_description)/urdf/jetbot/meshes/JetBot-v3-Chassis.dae" scale="0.002 0.002 0.002"/>
        </geometry>
      </visual>
    </link>


    <link name="left_wheel">
      <inertial>
        <mass value="1"/>
        <origin rpy="0 0 0" xyz="0 0 0"/>
        <inertia ixx="0"  ixy="0"  ixz="0" iyy="0" iyz="0" izz="0" />
      </inertial>

      <collision>
        <origin rpy="0 0 0" xyz="0 0 0"/>
        <geometry>
          <mesh filename="file://$(find jetbot_description)/urdf/jetbot/meshes/JetBot-v3-Wheel.stl" scale="0.002 0.002 0.002"/>
        </geometry>
      </collision>

      <visual>
        <origin rpy="0 0 0" xyz="0 0 0"/>
          <geometry>
            <mesh filename="file://$(find jetbot_description)/urdf/jetbot/meshes/JetBot-v3-Wheel.stl" scale="0.002 0.002 0.002"/>
          </geometry>
      </visual>
    </link>


    <joint name='left_wheel_hinge' type='revolute'>
      <origin rpy="0.0 0.0 1.57079632679" xyz="0.06 0.1025 0.06"/>
      <child  link="left_wheel"/>
      <parent link="chassis"/>
      <axis rpy="0 0 0" xyz="1 0 0"/>
      <limit lower="-360" upper="360" effort="50" velocity="100"/>
    </joint>


    <link name="right_wheel">
      <inertial>
        <mass value="1"/>
        <origin rpy="0 0 0" xyz="0 0 0"/>
        <inertia ixx="0"  ixy="0"  ixz="0" iyy="0" iyz="0" izz="0" />
      </inertial>

      <collision>
        <origin rpy="0 0 0" xyz="0 0 0"/>
        <geometry>
          <mesh filename="file://$(find jetbot_description)/urdf/jetbot/meshes/JetBot-v3-Wheel.stl" scale="0.002 0.002 0.002"/>
        </geometry>
      </collision>

      <visual>
        <origin rpy="0 0 0" xyz="0 0 0"/>
        <geometry>
          <mesh filename="file://$(find jetbot_description)/urdf/jetbot/meshes/JetBot-v3-Wheel.stl" scale="0.002 0.002 0.002"/>
        </geometry>
      </visual>
    </link>


    <joint name='right_wheel_hinge' type='revolute'>
      <origin rpy="0.0 0.0 1.57079632679 " xyz="0.06 -0.119 0.06"/>
      <child  link="right_wheel"/>
      <parent link="chassis"/>
      <axis rpy="0 0 0" xyz="1 0 0"/>
      <limit lower="-360" upper="360" effort="50" velocity="100"/>
    </joint>


    <joint name="camera_joint" type="fixed">
      <origin rpy="0 0.25 0" xyz="0.11 0.0 0.1714"/>
      <child  link="camera_link"/>
      <parent link="chassis"/>
      <pose>0.0 0.0 0.0 0.0 0.0 0.0</pose>
      <axis>
        <xyz>0.1 0.0 0.0</xyz>
      </axis>
    </joint>


    <!-- Camera -->
    <link name="camera_link">
      <gravity>false</gravity>
      <inertial>
        <inertia ixx="0"  ixy="0"  ixz="0" iyy="0" iyz="0" izz="0" />
        <mass value="1"/>
      </inertial>
      <visual name="visual">
        <origin rpy="0 0 0" xyz="0 0.0 0"/>
        <geometry>
          <box size="0.002 0.002 0.002"/>
        </geometry>
      </visual>
    </link>


    <joint name="camera_optical_joint" type="fixed">
      <!-- these values have to be these values otherwise the gazebo camera image
          won't be aligned properly with the frame it is supposedly originating from -->
      <origin xyz="0 0 0" rpy="0 0 0"/>
      <parent link="camera_link"/>
      <child link="camera_link_optical"/>
    </joint>


    <link name="camera_link_optical">
    </link>


    <transmission name="tran1">
      <type>transmission_interface/SimpleTransmission</type>
      <joint name="left_wheel_hinge">
        <hardwareInterface>hardware_interface/EffortJointInterface</hardwareInterface>
      </joint>
      <actuator name="motor1">
        <hardwareInterface>hardware_interface/EffortJointInterface</hardwareInterface>
        <mechanicalReduction>1</mechanicalReduction>
      </actuator>
    </transmission>


    <transmission name="tran2">
      <type>transmission_interface/SimpleTransmission</type>
      <joint name="right_wheel_hinge">
        <hardwareInterface>hardware_interface/EffortJointInterface</hardwareInterface>
      </joint>
      <actuator name="motor2">
        <hardwareInterface>hardware_interface/EffortJointInterface</hardwareInterface>
        <mechanicalReduction>1</mechanicalReduction>
      </actuator>
    </transmission>
</robot>
